Workbook

Sheet Informasi Proyek
A1: INFORMASI PROYEK
A2: Rencana Anggaran Biaya (RAB) - Pembangunan Balai Pelatihan Vokasi dan Produktivitas Morowali Utara
A4: A. DATA PROYEK
A6: Satuan Kerja | B6: : | C6: Direktorat Jenderal Pembinaan Pelatihan Vokasi dan Prosuktivitas
A7: Pekerjaan | B7: : | C7: Pembangunan Balai Pelatihan Vokasi dan Produktivitas Morowali Utara
A8: Lokasi | B8: : | C8: Jl. Trans Sulawesi, Tompira, Petasia, Kabupaten Morowali Utara, Sulawesi Tengah
A9: Pagu Konstruksi (Rp) | B9: : | C9: 61132457000
A10: Tahun Anggaran | B10: : | C10: 2026
A11: Pelaksana (PT/CV) | B11: : | C11: ................................ (isi)
A12: Konsultan Pengawas / MK | B12: : | C12: ................................ (isi)
A13: Jenis Kontrak | B13: : | C13: Harga satuan / lump sum - sesuai dokumen kontrak (isi)
A14: Waktu Pelaksanaan (hari kalender) | B14: : | C14: 300 | D14: Asumsi: BoQ memuat sewa drone 10 bulan (item 8). Sesuaikan dgn dokumen kontrak.
A15: Jumlah Minggu Pelaksanaan | B15: : | C15: =ROUNDUP(C14/7,0) -> 43
A16: Tanggal Mulai (SPMK) - asumsi | B16: : | C16: =DATE(2026,11,2) -> 46328 | D16: Isi sesuai tanggal SPMK. Jadwal pada lembar Schedule mengikuti sel ini.
A17: Tanggal Selesai (rencana) | B17: : | C17: =C16+C14-1 -> 46627
A18: Masa Pemeliharaan | B18: : | C18: 180 hari kalender (asumsi - sesuaikan kontrak)
A19: B. PARAMETER BIAYA
A20: Overhead & Profit (%) | B20: : | C20: 0.1 | D20: Diterapkan pada seluruh analisa harga satuan (maks. 15% menurut pola AHSP Permen PUPR 8/2023).
A21: PPN (%) | B21: : | C21: 0.11 | D21: Tarif efektif konstruksi 11% (DPP 11/12 x 12%) - sesuaikan ketentuan perpajakan yang berlaku.
A23: C. RINGKASAN HASIL
A24: Real cost biaya konstruksi (Rp) | B24: : | C24: =Rekap!C69 -> 56359846641
A25: Total biaya konstruksi incl. PPN, dibulatkan (Rp) | B25: : | C25: =Rekap!C72 -> 62559430000
A26: Pagu konstruksi (Rp) | B26: : | C26: =C9 -> 61132457000
A27: Selisih pagu - total biaya (Rp) | B27: : | C27: =Rekap!C74 -> -1426973000
A28: Rasio total biaya terhadap pagu | B28: : | C28: =Rekap!C75 -> 1.0233423
A29: Jumlah item pekerjaan pada RAB | B29: : | C29: =COUNTIF(RAB!H:H,"Analisa*")+COUNTIF(RAB!H:H,"Survei*")+COUNTIF(RAB!H:H,"Lump*") -> 1398
A30: - harga dari analisa koefisien (AHSP) | B30: : | C30: =COUNTIF(RAB!H:H,"Analisa*") -> 651
A31: - harga survei pasar (estimasi) | B31: : | C31: =COUNTIF(RAB!H:H,"Survei*") -> 619
A32: - lump sum estimasi, perlu verifikasi gambar/vendor | B32: : | C32: =COUNTIF(RAB!H:H,"Lump*") -> 128
A34: D. SUSUNAN LEMBAR KERJA
A35: Informasi Proyek | C35: Data proyek, parameter O&P/PPN, ringkasan hasil, catatan
A36: Rekap | C36: Rekapitulasi biaya per bangunan/kelompok pekerjaan, PPN, perbandingan dgn pagu
A37: RAB | C37: Bill of Quantity lengkap: volume (dari BoQ), harga satuan (dari AHSP), jumlah harga
A38: Analisa Harga Satuan | C38: Bagian A: analisa koefisien; Bagian B: harga paket/peralatan/survei
A39: Harga Bahan dan Tenaga | C39: Harga dasar upah, bahan, dan peralatan (input biru)
A40: Schedule | C40: Jadwal mingguan (Gantt), bobot, dan Kurva S
A42: E. CATATAN & ASUMSI PENTING
A43: 1. VOLUME diambil apa adanya dari dokumen BoQ (RAB_1.pdf & RAB_2.pdf, 22 halaman). Gambar kerja belum diterima - volume belum diverifikasi terhadap gambar.
A44: 2. HARGA SATUAN DASAR (upah, bahan, alat) adalah ESTIMASI. Dokumen HSD/AHSP resmi Kabupaten Morowali Utara TA 2026 tidak ditemukan pada sumber publik. Ganti sel biru pada lembar "Harga Bahan dan Tenaga" dan "Analisa Harga Satuan" Bagian B dengan harga resmi - seluruh lembar terhitung otomatis.
A45: 3. Koefisien analisa mengacu pola SNI 7394:2008 dan Permen PUPR No. 8 Tahun 2023 (disederhanakan). Verifikasi dengan buku AHSP resmi sebelum dipakai untuk penawaran/kontrak.
...

Sheet Rekap
A1: REKAPITULASI BILL OF QUANTITY
A2: SATUAN KERJA | C2: ='Informasi Proyek'!C6 -> Direktorat Jenderal Pembinaan Pelatihan Vokasi dan Prosuktivitas
A3: PEKERJAAN | C3: ='Informasi Proyek'!C7 -> Pembangunan Balai Pelatihan Vokasi dan Produktivitas Morowali Utara
A4: LOKASI | C4: ='Informasi Proyek'!C8 -> Jl. Trans Sulawesi, Tompira, Petasia, Kabupaten Morowali Utara, Sulawesi Tengah
A5: TAHUN ANGGARAN | C5: ='Informasi Proyek'!C10 -> 2026
A6: PAGU KONSTRUKSI (Rp) | C6: ='Informasi Proyek'!$C$9 -> 61132457000
A8: No | B8: URAIAN PEKERJAAN | C8: JUMLAH HARGA (Rp) | D8: BOBOT (%)
B9: KONSTRUKSI GEDUNG
B10: PENDAHULUAN
A11: I | B11: PEKERJAAN PERSIAPAN | C11: =RAB!F69 -> 1070391300 | D11: =C11/$C$69 -> 0.01899209
B12: JUMLAH PENDAHULUAN | C12: =SUM(C11:C11) -> 1070391300 | D12: =C12/$C$69 -> 0.01899209
A13: A | B13: GEDUNG KANTOR
A14: II | B14: PEKERJAAN TANAH (KANTOR) | C14: =RAB!F84 -> 139193331 | D14: =C14/$C$69 -> 0.0024697252
A15: III | B15: PEKERJAAN STRUKTURAL (KANTOR) | C15: =RAB!F227 -> 4859770070 | D15: =C15/$C$69 -> 0.086227525
A16: IV | B16: PEKERJAAN ARSITEKTURAL (KANTOR) | C16: =RAB!F332 -> 4981319345 | D16: =C16/$C$69 -> 0.088384189
A17: V | B17: PEKERJAAN MEKANIKAL (KANTOR) | C17: =RAB!F427 -> 2323248400 | D17: =C17/$C$69 -> 0.041221695
A18: VI | B18: PEKERJAAN PLUMBING (KANTOR) | C18: =RAB!F515 -> 375664025 | D18: =C18/$C$69 -> 0.0066654551
A19: VII | B19: PEKERJAAN ELEKTRIKAL (KANTOR) | C19: =RAB!F660 -> 816963895 | D19: =C19/$C$69 -> 0.014495495
B20: JUMLAH GEDUNG KANTOR | C20: =SUM(C14:C19) -> 13496159066 | D20: =C20/$C$69 -> 0.23946408
A21: B | B21: WORKSHOP BERAT (LAS)
A22: II | B22: PEKERJAAN TANAH (WORKSHOP LAS) | C22: =RAB!F673 -> 170661767 | D22: =C22/$C$69 -> 0.0030280737
A23: III | B23: PEKERJAAN STRUKTURAL (WORKSHOP LAS) | C23: =RAB!F766 -> 2376992884 | D23: =C23/$C$69 -> 0.04217529
A24: IV | B24: PEKERJAAN ARSITEKTURAL (WORKSHOP LAS) | C24: =RAB!F838 -> 2669851369 | D24: =C24/$C$69 -> 0.047371516
A25: V | B25: PEKERJAAN MEKANIKAL (WORKSHOP LAS) | C25: =RAB!F849 -> 78897500 | D25: =C25/$C$69 -> 0.0013998885
A26: VI | B26: PEKERJAAN PLUMBING (WORKSHOP LAS) | C26: =RAB!F895 -> 188814450 | D26: =C26/$C$69 -> 0.003350159
A27: VII | B27: PEKERJAAN ELEKTRIKAL (WORKSHOP LAS) | C27: =RAB!F942 -> 197810415 | D27: =C27/$C$69 -> 0.0035097756
B28: JUMLAH WORKSHOP BERAT (LAS) | C28: =SUM(C22:C27) -> 5683028385 | D28: =C28/$C$69 -> 0.1008347
A29: C | B29: WORKSHOP BERAT (MEKANIK)
A30: II | B30: PEKERJAAN TANAH (WORKSHOP MEKANIK) | C30: =RAB!F955 -> 170661767 | D30: =C30/$C$69 -> 0.0030280737
A31: III | B31: PEKERJAAN STRUKTURAL (WORKSHOP MEKANIK) | C31: =RAB!F1053 -> 3275711654 | D31: =C31/$C$69 -> 0.058121373
A32: IV | B32: PEKERJAAN ARSITEKTURAL (WORKSHOP MEKANIK) | C32: =RAB!F1125 -> 2659482782 | D32: =C32/$C$69 -> 0.047187545
A33: V | B33: PEKERJAAN MEKANIKAL (WORKSHOP MEKANIK) | C33: =RAB!F1136 -> 78897500 | D33: =C33/$C$69 -> 0.0013998885
A34: VI | B34: PEKERJAAN PLUMBING (WORKSHOP MEKANIK) | C34: =RAB!F1182 -> 181600815 | D34: =C34/$C$69 -> 0.0032221666
A35: VII | B35: PEKERJAAN ELEKTRIKAL (WORKSHOP MEKANIK) | C35: =RAB!F1229 -> 202212395 | D35: =C35/$C$69 -> 0.0035878805
B36: JUMLAH WORKSHOP BERAT (MEKANIK) | C36: =SUM(C30:C35) -> 6568566913 | D36: =C36/$C$69 -> 0.11654693
A37: D | B37: WORKSHOP RINGAN (TEKNIK INFORMATIKA DAN KOMPUTER / TIK)
A38: II | B38: PEKERJAAN TANAH (WORKSHOP RINGAN TEKNIK INFORMATIKA DAN KOMPUTER (TIK)) | C38: =RAB!F1242 -> 174234748 | D38: =C38/$C$69 -> 0.0030914695
A39: III | B39: PEKERJAAN STRUKTURAL (WORKSHOP RINGAN TEKNIK INFORMATIKA DAN KOMPUTER (TIK)) | C39: =RAB!F1320 -> 1756129526 | D39: =C39/$C$69 -> 0.031159232
A40: IV | B40: PEKERJAAN ARSITEKTURAL (WORKSHOP RINGAN TEKNIK INFORMATIKA DAN KOMPUTER (TIK)) | C40: =RAB!F1383 -> 2241920775 | D40: =C40/$C$69 -> 0.039778688
A41: V | B41: PEKERJAAN MEKANIKAL PLUMBING (WORKSHOP TEKNIK INFORMATIKA DAN KOMPUTER (TIK)) | C41: =RAB!F1442 -> 360555525 | D41: =C41/$C$69 -> 0.006397383
...

Sheet RAB
A1: BILL OF QUANTITY / RENCANA ANGGARAN BIAYA (RAB)
A2: SATUAN KERJA | C2: ='Informasi Proyek'!C6 -> Direktorat Jenderal Pembinaan Pelatihan Vokasi dan Prosuktivitas
A3: PEKERJAAN | C3: ='Informasi Proyek'!C7 -> Pembangunan Balai Pelatihan Vokasi dan Produktivitas Morowali Utara
A4: LOKASI | C4: ='Informasi Proyek'!C8 -> Jl. Trans Sulawesi, Tompira, Petasia, Kabupaten Morowali Utara, Sulawesi Tengah
A5: TAHUN ANGGARAN | C5: ='Informasi Proyek'!C10 -> 2026
A6: PAGU KONSTRUKSI (Rp) | C6: ='Informasi Proyek'!$C$9 -> 61132457000
A8: No | B8: URAIAN PEKERJAAN | C8: SATUAN | D8: VOLUME | E8: HARGA SATUAN (Rp) | F8: JUMLAH HARGA (Rp) | G8: KODE AHSP | H8: DASAR HARGA
A9: a | B9: d | C9: e | D9: f | E9: g | F9: h = f x g
B10: PENDAHULUAN - DIVISI 1: PERSIAPAN
A11: I | B11: PEKERJAAN PERSIAPAN
A12: 1 | B12: Pek. Pembuatan Papan Proyek (1 m2) | C12: Ls | D12: 6 | E12: ='Analisa Harga Satuan'!$H$803 -> 1320000 | F12: =ROUND(D12*E12,0) -> 7920000 | G12: B.001 | H12: Survei pasar (estimasi)
A13: 2 | B13: Pek. Pembuatan Barak Pekerja Minimal 36 m2 | C13: Set | D13: 1 | E13: ='Analisa Harga Satuan'!$H$804 -> 59400000 | F13: =ROUND(D13*E13,0) -> 59400000 | G13: B.002 | H13: Survei pasar (estimasi)
A14: 3 | B14: Pek. Direksi Keet luas 16 m2 | C14: Set | D14: 1 | E14: ='Analisa Harga Satuan'!$H$805 -> 38720000 | F14: =ROUND(D14*E14,0) -> 38720000 | G14: B.003 | H14: Survei pasar (estimasi)
A15: 4 | B15: Pek. Pengukuran Dan Pemasangan Bowplank | C15: Ls | D15: 1 | E15: ='Analisa Harga Satuan'!$H$806 -> 19800000 | F15: =ROUND(D15*E15,0) -> 19800000 | G15: B.004 | H15: Lump sum estimasi - verifikasi gambar
A16: 5 | B16: Biaya PDA Test 3 Titik | C16: titik | D16: 12 | E16: ='Analisa Harga Satuan'!$H$807 -> 9350000 | F16: =ROUND(D16*E16,0) -> 112200000 | G16: B.005 | H16: Survei pasar (estimasi)
A17: 6 | B17: Biaya Mobilisasi dan Demobilisasi Alat Pancang include Personil | C17: Ls | D17: 1 | E17: ='Analisa Harga Satuan'!$H$808 -> 313500000 | F17: =ROUND(D17*E17,0) -> 313500000 | G17: B.006 | H17: Lump sum estimasi - verifikasi gambar
B18: 7 Pek. Kontrol Daya Dukung Pondasi
A19: - | B19: Boring Test | C19: titik | D19: 1 | E19: ='Analisa Harga Satuan'!$H$809 -> 16500000 | F19: =ROUND(D19*E19,0) -> 16500000 | G19: B.007 | H19: Survei pasar (estimasi)
A20: - | B20: Sondir | C20: titik | D20: 4 | E20: ='Analisa Harga Satuan'!$H$810 -> 3850000 | F20: =ROUND(D20*E20,0) -> 15400000 | G20: B.008 | H20: Survei pasar (estimasi)
B21: 8 Pek. Pengendalian Progres Pekerjaan (Via Multimedia)
A22: - | B22: Sewa Drone | C22: Bulan | D22: 10 | E22: ='Analisa Harga Satuan'!$H$811 -> 2750000 | F22: =ROUND(D22*E22,0) -> 27500000 | G22: B.009 | H22: Survei pasar (estimasi)
A23: - | B23: Pengadaan CCTV Outdoor Wifi | C23: Bh | D23: 3 | E23: ='Analisa Harga Satuan'!$H$812 -> 3850000 | F23: =ROUND(D23*E23,0) -> 11550000 | G23: B.010 | H23: Survei pasar (estimasi)
A24: 9 | B24: Biaya Pemantauan dan Pengujian Lingkungan sebanyak 2x (Progres 30% dan 80%) | C24: Set | D24: 1 | E24: ='Analisa Harga Satuan'!$H$813 -> 93500000 | F24: =ROUND(D24*E24,0) -> 93500000 | G24: B.011 | H24: Lump sum estimasi - verifikasi gambar
B25: a) Pemantauan Tingkat Getaran
B26: b) Pemantauan Tingkat Kebisingan
B27: c) Pemantauan Kualitas Air Permukaan
B28: d) Pemantauan Kualitas Udara
B29: e) Operasional dan Sewa Alat
B30: f) Honorarium Tenaga Lapangan
A31: 10 | B31: Biaya Pembongkaran Bangunan Eksisting | C31: m2 | D31: 405 | E31: ='Analisa Harga Satuan'!$H$814 -> 93500 | F31: =ROUND(D31*E31,0) -> 37867500 | G31: B.012 | H31: Survei pasar (estimasi)
A32: 11 | B32: Biaya Pengukuran Topografi | C32: Ls | D32: 1 | E32: ='Analisa Harga Satuan'!$H$815 -> 71500000 | F32: =ROUND(D32*E32,0) -> 71500000 | G32: B.013 | H32: Lump sum estimasi - verifikasi gambar
B33: 12 Komponen Biaya Keselamatan Konstruksi
B34: 1.Penyiapan dokumen RKK, RKPPL,RMLLP,RMPK:
A35: a) | B35: Pembuatan dokumen RKK, RKPPL, RMLLP, RMPK | C35: Set | D35: 1 | E35: ='Analisa Harga Satuan'!$H$816 -> 13200000 | F35: =ROUND(D35*E35,0) -> 13200000 | G35: B.014 | H35: Lump sum estimasi - verifikasi gambar
A36: b) | B36: Pembuatan prosedur dan instruksi kerja | C36: Set | D36: 1 | E36: ='Analisa Harga Satuan'!$H$817 -> 6600000 | F36: =ROUND(D36*E36,0) -> 6600000 | G36: B.015 | H36: Lump sum estimasi - verifikasi gambar
A37: c) | B37: Penyusunan pelaporan penerapan SMKK | C37: Set | D37: 1 | E37: ='Analisa Harga Satuan'!$H$818 -> 8800000 | F37: =ROUND(D37*E37,0) -> 8800000 | G37: B.016 | H37: Lump sum estimasi - verifikasi gambar
B38: 2. Sosialisasi, promosi dan pelatihan:
A39: a) | B39: Induksi Keselamatan Konstruksi (Safety Induction) | C39: OB | D39: 6 | E39: ='Analisa Harga Satuan'!$H$819 -> 1375000 | F39: =ROUND(D39*E39,0) -> 8250000 | G39: B.017 | H39: Survei pasar (estimasi)
A40: b) | B40: Pengarahan Keselamatan Konstruksi (Safety Briefing) | C40: OB | D40: 6 | E40: ='Analisa Harga Satuan'!$H$820 -> 825000 | F40: =ROUND(D40*E40,0) -> 4950000 | G40: B.018 | H40: Survei pasar (estimasi)
A41: d) | B41: Patroli keselamatan konstruksi | C41: durasi | D41: 6 | E41: ='Analisa Harga Satuan'!$H$821 -> 1650000 | F41: =ROUND(D41*E41,0) -> 9900000 | G41: B.019 | H41: Survei pasar (estimasi)
...

Sheet Analisa Harga Satuan
A1: ANALISA HARGA SATUAN PEKERJAAN (AHSP)
A2: Pembangunan Balai Pelatihan Vokasi dan Produktivitas Morowali Utara - Kab. Morowali Utara, TA 2026
A3: Koefisien mengacu pola SNI / Permen PUPR No. 8 Tahun 2023 (disederhanakan & disesuaikan). Harga dasar dari lembar "Harga Bahan dan Tenaga" (estimasi). Overhead & profit dari lembar Informasi Proyek.
A4: Overhead & Profit (%) | C4: ='Informasi Proyek'!$C$20 -> 0.1
A5: BAGIAN A - ANALISA BERBASIS KOEFISIEN (TENAGA - BAHAN - PERALATAN)
A6: A.01 | B6: Galian tanah biasa (excavator + perapihan manual) | C6: m3 | G6: Permen PUPR 8/2023 (disesuaikan, mekanis)
A7: No | B7: Uraian komponen | C7: Satuan | D7: Koefisien | E7: Harga Satuan (Rp) | F7: Jumlah (Rp)
B8: A. TENAGA KERJA
A9: 1 | B9: Pekerja [L01] | C9: OH | D9: 0.3 | E9: ='Harga Bahan dan Tenaga'!$D$7 -> 135000 | F9: =D9*E9 -> 40500
A10: 2 | B10: Mandor [L09] | C10: OH | D10: 0.015 | E10: ='Harga Bahan dan Tenaga'!$D$15 -> 200000 | F10: =D10*E10 -> 3000
B11: Jumlah Tenaga Kerja | F11: =SUM(F9:F10) -> 43500
B12: C. PERALATAN
A13: 1 | B13: Excavator PC-200 (incl. operator & BBM) [E01] | C13: jam | D13: 0.08 | E13: ='Harga Bahan dan Tenaga'!$D$63 -> 650000 | F13: =D13*E13 -> 52000
B14: Jumlah Peralatan | F14: =SUM(F13:F13) -> 52000
B15: D. JUMLAH (A+B+C) | F15: =F11+F14 -> 95500
B16: E. Overhead & Profit | D16: ='Informasi Proyek'!$C$20 -> 0.1 | F16: =F15*D16 -> 9550
B17: F. HARGA SATUAN PEKERJAAN per m3 (D+E, dibulatkan) | F17: =ROUND(F15+F16,0) -> 105050
A19: A.02 | B19: Buangan bekas galian (angkut dump truck jarak +/- 3 km) | C19: m3 | G19: AHSP alat berat, disesuaikan
A20: No | B20: Uraian komponen | C20: Satuan | D20: Koefisien | E20: Harga Satuan (Rp) | F20: Jumlah (Rp)
B21: A. TENAGA KERJA
A22: 1 | B22: Pekerja [L01] | C22: OH | D22: 0.05 | E22: ='Harga Bahan dan Tenaga'!$D$7 -> 135000 | F22: =D22*E22 -> 6750
A23: 2 | B23: Mandor [L09] | C23: OH | D23: 0.003 | E23: ='Harga Bahan dan Tenaga'!$D$15 -> 200000 | F23: =D23*E23 -> 600
B24: Jumlah Tenaga Kerja | F24: =SUM(F22:F23) -> 7350
B25: C. PERALATAN
A26: 1 | B26: Excavator PC-200 (incl. operator & BBM) [E01] | C26: jam | D26: 0.05 | E26: ='Harga Bahan dan Tenaga'!$D$63 -> 650000 | F26: =D26*E26 -> 32500
A27: 2 | B27: Dump truck 10 ton (incl. operator & BBM) [E02] | C27: jam | D27: 0.14 | E27: ='Harga Bahan dan Tenaga'!$D$64 -> 450000 | F27: =D27*E27 -> 63000
B28: Jumlah Peralatan | F28: =SUM(F26:F27) -> 95500
B29: D. JUMLAH (A+B+C) | F29: =F24+F28 -> 102850
B30: E. Overhead & Profit | D30: ='Informasi Proyek'!$C$20 -> 0.1 | F30: =F29*D30 -> 10285
B31: F. HARGA SATUAN PEKERJAAN per m3 (D+E, dibulatkan) | F31: =ROUND(F29+F30,0) -> 113135
A33: A.03 | B33: Urugan kembali bekas galian + pemadatan | C33: m3 | G33: Permen PUPR 8/2023
A34: No | B34: Uraian komponen | C34: Satuan | D34: Koefisien | E34: Harga Satuan (Rp) | F34: Jumlah (Rp)
B35: A. TENAGA KERJA
A36: 1 | B36: Pekerja [L01] | C36: OH | D36: 0.35 | E36: ='Harga Bahan dan Tenaga'!$D$7 -> 135000 | F36: =D36*E36 -> 47250
A37: 2 | B37: Mandor [L09] | C37: OH | D37: 0.0175 | E37: ='Harga Bahan dan Tenaga'!$D$15 -> 200000 | F37: =D37*E37 -> 3500
B38: Jumlah Tenaga Kerja | F38: =SUM(F36:F37) -> 50750
B39: C. PERALATAN
A40: 1 | B40: Stamper / plate compactor [E08] | C40: jam | D40: 0.1 | E40: ='Harga Bahan dan Tenaga'!$D$70 -> 85000 | F40: =D40*E40 -> 8500
B41: Jumlah Peralatan | F41: =SUM(F40:F40) -> 8500
B42: D. JUMLAH (A+B+C) | F42: =F38+F41 -> 59250
...

Sheet Harga Bahan dan Tenaga
A1: DAFTAR HARGA SATUAN DASAR: TENAGA KERJA, BAHAN DAN PERALATAN
A2: Kabupaten Morowali Utara, Provinsi Sulawesi Tengah - Tahun Anggaran 2026
A3: CATATAN: seluruh harga pada lembar ini adalah ESTIMASI PERENCANA (dokumen HSD/AHSP resmi Kab. Morowali Utara TA 2026 belum tersedia saat penyusunan). Ganti sel biru dengan harga resmi; seluruh analisa, RAB, rekap, dan kurva S akan terhitung ulang otomatis.
A5: Kode | B5: Uraian | C5: Satuan | D5: Harga Satuan (Rp) | E5: Keterangan / Dasar
A6: A. UPAH TENAGA KERJA (per Orang-Hari)
A7: L01 | B7: Pekerja | C7: OH | D7: 135000 | E7: Estimasi - ganti dgn HSD Upah Kab. Morowali Utara 2026
A8: L02 | B8: Tukang Batu / Tukang Plester | C8: OH | D8: 170000 | E8: Estimasi - ganti dgn HSD Upah Kab. Morowali Utara 2026
A9: L03 | B9: Tukang Kayu / Bekisting | C9: OH | D9: 170000 | E9: Estimasi - ganti dgn HSD Upah Kab. Morowali Utara 2026
A10: L04 | B10: Tukang Besi / Pembesian | C10: OH | D10: 170000 | E10: Estimasi - ganti dgn HSD Upah Kab. Morowali Utara 2026
A11: L05 | B11: Tukang Cat | C11: OH | D11: 165000 | E11: Estimasi - ganti dgn HSD Upah Kab. Morowali Utara 2026
A12: L06 | B12: Tukang Las | C12: OH | D12: 190000 | E12: Estimasi - ganti dgn HSD Upah Kab. Morowali Utara 2026
A13: L07 | B13: Tukang Keramik / Finishing | C13: OH | D13: 170000 | E13: Estimasi - ganti dgn HSD Upah Kab. Morowali Utara 2026
A14: L08 | B14: Kepala Tukang | C14: OH | D14: 190000 | E14: Estimasi - ganti dgn HSD Upah Kab. Morowali Utara 2026
A15: L09 | B15: Mandor | C15: OH | D15: 200000 | E15: Estimasi - ganti dgn HSD Upah Kab. Morowali Utara 2026
A16: B. BAHAN
A17: M01 | B17: Semen Portland (PC) | C17: kg | D17: 1760 | E17: Estimasi harga di lokasi (delivered) - ganti dgn HSD Bahan 2026
A18: M02 | B18: Pasir pasang | C18: m3 | D18: 380000 | E18: Estimasi harga di lokasi (delivered) - ganti dgn HSD Bahan 2026
A19: M03 | B19: Pasir urug | C19: m3 | D19: 320000 | E19: Estimasi harga di lokasi (delivered) - ganti dgn HSD Bahan 2026
A20: M04 | B20: Kerikil / split beton | C20: m3 | D20: 480000 | E20: Estimasi harga di lokasi (delivered) - ganti dgn HSD Bahan 2026
A21: M05 | B21: Batu kali | C21: m3 | D21: 400000 | E21: Estimasi harga di lokasi (delivered) - ganti dgn HSD Bahan 2026
A22: M06 | B22: Batu kosong (aanstamping) | C22: m3 | D22: 380000 | E22: Estimasi harga di lokasi (delivered) - ganti dgn HSD Bahan 2026
A23: M07 | B23: Air kerja | C23: m3 | D23: 35000 | E23: Estimasi harga di lokasi (delivered) - ganti dgn HSD Bahan 2026
A24: M08 | B24: Besi beton polos / ulir | C24: kg | D24: 17500 | E24: Estimasi harga di lokasi (delivered) - ganti dgn HSD Bahan 2026
A25: M09 | B25: Kawat beton (bendrat) | C25: kg | D25: 24000 | E25: Estimasi harga di lokasi (delivered) - ganti dgn HSD Bahan 2026
A26: M10 | B26: Kayu balok kelas II/III | C26: m3 | D26: 5200000 | E26: Estimasi harga di lokasi (delivered) - ganti dgn HSD Bahan 2026
A27: M11 | B27: Papan kayu bekisting | C27: m3 | D27: 4800000 | E27: Estimasi harga di lokasi (delivered) - ganti dgn HSD Bahan 2026
A28: M12 | B28: Plywood 12 mm | C28: lbr | D28: 235000 | E28: Estimasi harga di lokasi (delivered) - ganti dgn HSD Bahan 2026
... A61: M45 | B61: Primer bitumen | C61: kg | D61: 45000 | E61: Estimasi harga di lokasi (delivered) - ganti dgn HSD Bahan 2026
A62: C. PERALATAN (sewa per jam, incl. operator & BBM)
A63: E01 | B63: Excavator PC-200 (incl. operator & BBM) | C63: jam | D63: 650000 | E63: Estimasi - ganti dgn HSD Alat 2026
A64: E02 | B64: Dump truck 10 ton (incl. operator & BBM) | C64: jam | D64: 450000 | E64: Estimasi - ganti dgn HSD Alat 2026
A65: E03 | B65: Bulldozer D6 (incl. operator & BBM) | C65: jam | D65: 750000 | E65: Estimasi - ganti dgn HSD Alat 2026
A66: E04 | B66: Vibro roller (incl. operator & BBM) | C66: jam | D66: 420000 | E66: Estimasi - ganti dgn HSD Alat 2026
A67: E05 | B67: Motor grader (incl. operator & BBM) | C67: jam | D67: 600000 | E67: Estimasi - ganti dgn HSD Alat 2026
A68: E06 | B68: Concrete mixer 0.35 m3 | C68: jam | D68: 125000 | E68: Estimasi - ganti dgn HSD Alat 2026
A69: E07 | B69: Concrete vibrator | C69: jam | D69: 60000 | E69: Estimasi - ganti dgn HSD Alat 2026
A70: E08 | B70: Stamper / plate compactor | C70: jam | D70: 85000 | E70: Estimasi - ganti dgn HSD Alat 2026
A71: E09 | B71: Mobile crane 25 ton (incl. operator) | C71: jam | D71: 850000 | E71: Estimasi - ganti dgn HSD Alat 2026
A72: E10 | B72: Mesin las / genset las | C72: jam | D72: 95000 | E72: Estimasi - ganti dgn HSD Alat 2026

Sheet Schedule
A1: SCHEDULE PELAKSANAAN (BAR CHART / GANTT) DAN KURVA S
A2: ="Pekerjaan: "&'Informasi Proyek'!C7 -> Pekerjaan: Pembangunan Balai Pelatihan Vokasi dan Produktivitas Morowali Utara
A3: ="Mulai: "&TEXT('Informasi Proyek'!C16,"dd-mmm-yyyy")&" | Selesai: "&TEXT('Informasi Proyek'!C17,"dd-mmm-yyyy")&" | Durasi: "&'Informasi Proyek'!C14&" hari kalender ("&'Informasi Proyek'!C15&" minggu)" -> Mulai: 02-Nov-2026 | Selesai: 28-Aug-2027 | Durasi: 300 hari kalender (43 minggu)
A4: Sel BIRU (Mulai & Durasi, dalam minggu) dapat diubah. Progres mingguan = bobot / durasi (distribusi seragam per kegiatan).
A6: No | B6: URAIAN KEGIATAN | C6: BOBOT (%) | D6: MULAI (mgg) | E6: DURASI (mgg) | F6: SELESAI (mgg) | G6: 1 | H6: 2 | I6: 3 | J6: 4 | K6: 5 | L6: 6 | M6: 7 | N6: 8 | O6: 9 | P6: 10 | Q6: 11 | R6: 12 | S6: 13 | T6: 14 | U6: 15 | V6: 16 | W6: 17 | X6: 18 | Y6: 19 | Z6: 20 | AA6: 21 | AB6: 22 | AC6: 23 | AD6: 24 | AE6: 25 | AF6: 26 | AG6: 27 | AH6: 28 | AI6: 29 | AJ6: 30 | AK6: 31 | AL6: 32 | AM6: 33 | AN6: 34 | AO6: 35 | AP6: 36 | AQ6: 37 | AR6: 38 | AS6: 39 | AT6: 40 | AU6: 41 | AV6: 42 | AW6: 43
B7: Tanggal awal minggu | G7: ='Informasi Proyek'!$C$16+7*(G$6-1) -> 46328 | H7: ='Informasi Proyek'!$C$16+7*(H$6-1) -> 46335 | I7: ='Informasi Proyek'!$C$16+7*(I$6-1) -> 46342 | J7: ='Informasi Proyek'!$C$16+7*(J$6-1) -> 46349 | K7: ='Informasi Proyek'!$C$16+7*(K$6-1) -> 46356 | L7: ='Informasi Proyek'!$C$16+7*(L$6-1) -> 46363 | M7: ='Informasi Proyek'!$C$16+7*(M$6-1) -> 46370 | N7: ='Informasi Proyek'!$C$16+7*(N$6-1) -> 46377 | ... AW7: ='Informasi Proyek'!$C$16+7*(AW$6-1) -> 46622
A8: 1 | B8: ="PENDAHULUAN - "&Rekap!B11 -> PENDAHULUAN - PEKERJAAN PERSIAPAN | C8: =Rekap!C11/Rekap!$C$69 -> 0.01899209 | D8: 1 | E8: 43 | F8: =D8+E8-1 -> 43 | G8: =IF(AND(G$6>=$D8,G$6<=$F8),$C8/$E8,0) -> 0.00044167652 | H8: =IF(AND(H$6>=$D8,H$6<=$F8),$C8/$E8,0) -> 0.00044167652 | I8: =IF(AND(I$6>=$D8,I$6<=$F8),$C8/$E8,0) -> 0.00044167652 | J8: =IF(AND(J$6>=$D8,J$6<=$F8),$C8/$E8,0) -> 0.00044167652 | K8: =IF(AND(K$6>=$D8,K$6<=$F8),$C8/$E8,0) -> 0.00044167652 | L8: =IF(AND(L$6>=$D8,L$6<=$F8),$C8/$E8,0) -> 0.00044167652 | M8: =IF(AND(M$6>=$D8,M$6<=$F8),$C8/$E8,0) -> 0.00044167652 | N8: =IF(AND(N$6>=$D8,N$6<=$F8),$C8/$E8,0) -> 0.00044167652 | ... AW8: =IF(AND(AW$6>=$D8,AW$6<=$F8),$C8/$E8,0) -> 0.00044167652
A9: 2 | B9: ="KANTOR - "&Rekap!B14 -> KANTOR - PEKERJAAN TANAH (KANTOR) | C9: =Rekap!C14/Rekap!$C$69 -> 0.0024697252 | D9: 6 | E9: 5 | F9: =D9+E9-1 -> 10 | G9: =IF(AND(G$6>=$D9,G$6<=$F9),$C9/$E9,0) -> 0 | H9: =IF(AND(H$6>=$D9,H$6<=$F9),$C9/$E9,0) -> 0 | I9: =IF(AND(I$6>=$D9,I$6<=$F9),$C9/$E9,0) -> 0 | J9: =IF(AND(J$6>=$D9,J$6<=$F9),$C9/$E9,0) -> 0 | K9: =IF(AND(K$6>=$D9,K$6<=$F9),$C9/$E9,0) -> 0 | L9: =IF(AND(L$6>=$D9,L$6<=$F9),$C9/$E9,0) -> 0.00049394503 | M9: =IF(AND(M$6>=$D9,M$6<=$F9),$C9/$E9,0) -> 0.00049394503 | N9: =IF(AND(N$6>=$D9,N$6<=$F9),$C9/$E9,0) -> 0.00049394503 | ... AW9: =IF(AND(AW$6>=$D9,AW$6<=$F9),$C9/$E9,0) -> 0
A10: 3 | B10: ="KANTOR - "&Rekap!B15 -> KANTOR - PEKERJAAN STRUKTURAL (KANTOR) | C10: =Rekap!C15/Rekap!$C$69 -> 0.086227525 | D10: 9 | E10: 19 | F10: =D10+E10-1 -> 27 | G10: =IF(AND(G$6>=$D10,G$6<=$F10),$C10/$E10,0) -> 0 | H10: =IF(AND(H$6>=$D10,H$6<=$F10),$C10/$E10,0) -> 0 | I10: =IF(AND(I$6>=$D10,I$6<=$F10),$C10/$E10,0) -> 0 | J10: =IF(AND(J$6>=$D10,J$6<=$F10),$C10/$E10,0) -> 0 | K10: =IF(AND(K$6>=$D10,K$6<=$F10),$C10/$E10,0) -> 0 | L10: =IF(AND(L$6>=$D10,L$6<=$F10),$C10/$E10,0) -> 0 | M10: =IF(AND(M$6>=$D10,M$6<=$F10),$C10/$E10,0) -> 0 | N10: =IF(AND(N$6>=$D10,N$6<=$F10),$C10/$E10,0) -> 0 | ... AW10: =IF(AND(AW$6>=$D10,AW$6<=$F10),$C10/$E10,0) -> 0
A11: 4 | B11: ="KANTOR - "&Rekap!B16 -> KANTOR - PEKERJAAN ARSITEKTURAL (KANTOR) | C11: =Rekap!C16/Rekap!$C$69 -> 0.088384189 | D11: 21 | E11: 18 | F11: =D11+E11-1 -> 38 | G11: =IF(AND(G$6>=$D11,G$6<=$F11),$C11/$E11,0) -> 0 | H11: =IF(AND(H$6>=$D11,H$6<=$F11),$C11/$E11,0) -> 0 | I11: =IF(AND(I$6>=$D11,I$6<=$F11),$C11/$E11,0) -> 0 | J11: =IF(AND(J$6>=$D11,J$6<=$F11),$C11/$E11,0) -> 0 | K11: =IF(AND(K$6>=$D11,K$6<=$F11),$C11/$E11,0) -> 0 | L11: =IF(AND(L$6>=$D11,L$6<=$F11),$C11/$E11,0) -> 0 | M11: =IF(AND(M$6>=$D11,M$6<=$F11),$C11/$E11,0) -> 0 | N11: =IF(AND(N$6>=$D11,N$6<=$F11),$C11/$E11,0) -> 0 | ... AW11: =IF(AND(AW$6>=$D11,AW$6<=$F11),$C11/$E11,0) -> 0
A12: 5 | B12: ="KANTOR - "&Rekap!B17 -> KANTOR - PEKERJAAN MEKANIKAL (KANTOR) | C12: =Rekap!C17/Rekap!$C$69 -> 0.041221695 | D12: 28 | E12: 13 | F12: =D12+E12-1 -> 40 | G12: =IF(AND(G$6>=$D12,G$6<=$F12),$C12/$E12,0) -> 0 | H12: =IF(AND(H$6>=$D12,H$6<=$F12),$C12/$E12,0) -> 0 | I12: =IF(AND(I$6>=$D12,I$6<=$F12),$C12/$E12,0) -> 0 | J12: =IF(AND(J$6>=$D12,J$6<=$F12),$C12/$E12,0) -> 0 | K12: =IF(AND(K$6>=$D12,K$6<=$F12),$C12/$E12,0) -> 0 | L12: =IF(AND(L$6>=$D12,L$6<=$F12),$C12/$E12,0) -> 0 | M12: =IF(AND(M$6>=$D12,M$6<=$F12),$C12/$E12,0) -> 0 | N12: =IF(AND(N$6>=$D12,N$6<=$F12),$C12/$E12,0) -> 0 | ... AW12: =IF(AND(AW$6>=$D12,AW$6<=$F12),$C12/$E12,0) -> 0
A13: 6 | B13: ="KANTOR - "&Rekap!B18 -> KANTOR - PEKERJAAN PLUMBING (KANTOR) | C13: =Rekap!C18/Rekap!$C$69 -> 0.0066654551 | D13: 22 | E13: 17 | F13: =D13+E13-1 -> 38 | G13: =IF(AND(G$6>=$D13,G$6<=$F13),$C13/$E13,0) -> 0 | H13: =IF(AND(H$6>=$D13,H$6<=$F13),$C13/$E13,0) -> 0 | I13: =IF(AND(I$6>=$D13,I$6<=$F13),$C13/$E13,0) -> 0 | J13: =IF(AND(J$6>=$D13,J$6<=$F13),$C13/$E13,0) -> 0 | K13: =IF(AND(K$6>=$D13,K$6<=$F13),$C13/$E13,0) -> 0 | L13: =IF(AND(L$6>=$D13,L$6<=$F13),$C13/$E13,0) -> 0 | M13: =IF(AND(M$6>=$D13,M$6<=$F13),$C13/$E13,0) -> 0 | N13: =IF(AND(N$6>=$D13,N$6<=$F13),$C13/$E13,0) -> 0 | ... AW13: =IF(AND(AW$6>=$D13,AW$6<=$F13),$C13/$E13,0) -> 0
A14: 7 | B14: ="KANTOR - "&Rekap!B19 -> KANTOR - PEKERJAAN ELEKTRIKAL (KANTOR) | C14: =Rekap!C19/Rekap!$C$69 -> 0.014495495 | D14: 24 | E14: 16 | F14: =D14+E14-1 -> 39 | G14: =IF(AND(G$6>=$D14,G$6<=$F14),$C14/$E14,0) -> 0 | H14: =IF(AND(H$6>=$D14,H$6<=$F14),$C14/$E14,0) -> 0 | I14: =IF(AND(I$6>=$D14,I$6<=$F14),$C14/$E14,0) -> 0 | J14: =IF(AND(J$6>=$D14,J$6<=$F14),$C14/$E14,0) -> 0 | K14: =IF(AND(K$6>=$D14,K$6<=$F14),$C14/$E14,0) -> 0 | L14: =IF(AND(L$6>=$D14,L$6<=$F14),$C14/$E14,0) -> 0 | M14: =IF(AND(M$6>=$D14,M$6<=$F14),$C14/$E14,0) -> 0 | N14: =IF(AND(N$6>=$D14,N$6<=$F14),$C14/$E14,0) -> 0 | ... AW14: =IF(AND(AW$6>=$D14,AW$6<=$F14),$C14/$E14,0) -> 0
A15: 8 | B15: ="WORKSHOP LAS - "&Rekap!B22 -> WORKSHOP LAS - PEKERJAAN TANAH (WORKSHOP LAS) | C15: =Rekap!C22/Rekap!$C$69 -> 0.0030280737 | D15: 8 | E15: 4 | F15: =D15+E15-1 -> 11 | G15: =IF(AND(G$6>=$D15,G$6<=$F15),$C15/$E15,0) -> 0 | H15: =IF(AND(H$6>=$D15,H$6<=$F15),$C15/$E15,0) -> 0 | I15: =IF(AND(I$6>=$D15,I$6<=$F15),$C15/$E15,0) -> 0 | J15: =IF(AND(J$6>=$D15,J$6<=$F15),$C15/$E15,0) -> 0 | K15: =IF(AND(K$6>=$D15,K$6<=$F15),$C15/$E15,0) -> 0 | L15: =IF(AND(L$6>=$D15,L$6<=$F15),$C15/$E15,0) -> 0 | M15: =IF(AND(M$6>=$D15,M$6<=$F15),$C15/$E15,0) -> 0 | N15: =IF(AND(N$6>=$D15,N$6<=$F15),$C15/$E15,0) -> 0.00075701841 | ... AW15: =IF(AND(AW$6>=$D15,AW$6<=$F15),$C15/$E15,0) -> 0
A16: 9 | B16: ="WORKSHOP LAS - "&Rekap!B23 -> WORKSHOP LAS - PEKERJAAN STRUKTURAL (WORKSHOP LAS) | C16: =Rekap!C23/Rekap!$C$69 -> 0.04217529 | D16: 11 | E16: 15 | F16: =D16+E16-1 -> 25 | G16: =IF(AND(G$6>=$D16,G$6<=$F16),$C16/$E16,0) -> 0 | H16: =IF(AND(H$6>=$D16,H$6<=$F16),$C16/$E16,0) -> 0 | I16: =IF(AND(I$6>=$D16,I$6<=$F16),$C16/$E16,0) -> 0 | J16: =IF(AND(J$6>=$D16,J$6<=$F16),$C16/$E16,0) -> 0 | K16: =IF(AND(K$6>=$D16,K$6<=$F16),$C16/$E16,0) -> 0 | L16: =IF(AND(L$6>=$D16,L$6<=$F16),$C16/$E16,0) -> 0 | M16: =IF(AND(M$6>=$D16,M$6<=$F16),$C16/$E16,0) -> 0 | N16: =IF(AND(N$6>=$D16,N$6<=$F16),$C16/$E16,0) -> 0 | ... AW16: =IF(AND(AW$6>=$D16,AW$6<=$F16),$C16/$E16,0) -> 0
A17: 10 | B17: ="WORKSHOP LAS - "&Rekap!B24 -> WORKSHOP LAS - PEKERJAAN ARSITEKTURAL (WORKSHOP LAS) | C17: =Rekap!C24/Rekap!$C$69 -> 0.047371516 | D17: 22 | E17: 12 | F17: =D17+E17-1 -> 33 | G17: =IF(AND(G$6>=$D17,G$6<=$F17),$C17/$E17,0) -> 0 | H17: =IF(AND(H$6>=$D17,H$6<=$F17),$C17/$E17,0) -> 0 | I17: =IF(AND(I$6>=$D17,I$6<=$F17),$C17/$E17,0) -> 0 | J17: =IF(AND(J$6>=$D17,J$6<=$F17),$C17/$E17,0) -> 0 | K17: =IF(AND(K$6>=$D17,K$6<=$F17),$C17/$E17,0) -> 0 | L17: =IF(AND(L$6>=$D17,L$6<=$F17),$C17/$E17,0) -> 0 | M17: =IF(AND(M$6>=$D17,M$6<=$F17),$C17/$E17,0) -> 0 | N17: =IF(AND(N$6>=$D17,N$6<=$F17),$C17/$E17,0) -> 0 | ... AW17: =IF(AND(AW$6>=$D17,AW$6<=$F17),$C17/$E17,0) -> 0
A18: 11 | B18: ="WORKSHOP LAS - "&Rekap!B25 -> WORKSHOP LAS - PEKERJAAN MEKANIKAL (WORKSHOP LAS) | C18: =Rekap!C25/Rekap!$C$69 -> 0.0013998885 | D18: 30 | E18: 6 | F18: =D18+E18-1 -> 35 | G18: =IF(AND(G$6>=$D18,G$6<=$F18),$C18/$E18,0) -> 0 | H18: =IF(AND(H$6>=$D18,H$6<=$F18),$C18/$E18,0) -> 0 | I18: =IF(AND(I$6>=$D18,I$6<=$F18),$C18/$E18,0) -> 0 | J18: =IF(AND(J$6>=$D18,J$6<=$F18),$C18/$E18,0) -> 0 | K18: =IF(AND(K$6>=$D18,K$6<=$F18),$C18/$E18,0) -> 0 | L18: =IF(AND(L$6>=$D18,L$6<=$F18),$C18/$E18,0) -> 0 | M18: =IF(AND(M$6>=$D18,M$6<=$F18),$C18/$E18,0) -> 0 | N18: =IF(AND(N$6>=$D18,N$6<=$F18),$C18/$E18,0) -> 0 | ... AW18: =IF(AND(AW$6>=$D18,AW$6<=$F18),$C18/$E18,0) -> 0
A19: 12 | B19: ="WORKSHOP LAS - "&Rekap!B26 -> WORKSHOP LAS - PEKERJAAN PLUMBING (WORKSHOP LAS) | C19: =Rekap!C26/Rekap!$C$69 -> 0.003350159 | D19: 27 | E19: 9 | F19: =D19+E19-1 -> 35 | G19: =IF(AND(G$6>=$D19,G$6<=$F19),$C19/$E19,0) -> 0 | H19: =IF(AND(H$6>=$D19,H$6<=$F19),$C19/$E19,0) -> 0 | I19: =IF(AND(I$6>=$D19,I$6<=$F19),$C19/$E19,0) -> 0 | J19: =IF(AND(J$6>=$D19,J$6<=$F19),$C19/$E19,0) -> 0 | K19: =IF(AND(K$6>=$D19,K$6<=$F19),$C19/$E19,0) -> 0 | L19: =IF(AND(L$6>=$D19,L$6<=$F19),$C19/$E19,0) -> 0 | M19: =IF(AND(M$6>=$D19,M$6<=$F19),$C19/$E19,0) -> 0 | N19: =IF(AND(N$6>=$D19,N$6<=$F19),$C19/$E19,0) -> 0 | ... AW19: =IF(AND(AW$6>=$D19,AW$6<=$F19),$C19/$E19,0) -> 0
A20: 13 | B20: ="WORKSHOP LAS - "&Rekap!B27 -> WORKSHOP LAS - PEKERJAAN ELEKTRIKAL (WORKSHOP LAS) | C20: =Rekap!C27/Rekap!$C$69 -> 0.0035097756 | D20: 29 | E20: 10 | F20: =D20+E20-1 -> 38 | G20: =IF(AND(G$6>=$D20,G$6<=$F20),$C20/$E20,0) -> 0 | H20: =IF(AND(H$6>=$D20,H$6<=$F20),$C20/$E20,0) -> 0 | I20: =IF(AND(I$6>=$D20,I$6<=$F20),$C20/$E20,0) -> 0 | J20: =IF(AND(J$6>=$D20,J$6<=$F20),$C20/$E20,0) -> 0 | K20: =IF(AND(K$6>=$D20,K$6<=$F20),$C20/$E20,0) -> 0 | L20: =IF(AND(L$6>=$D20,L$6<=$F20),$C20/$E20,0) -> 0 | M20: =IF(AND(M$6>=$D20,M$6<=$F20),$C20/$E20,0) -> 0 | N20: =IF(AND(N$6>=$D20,N$6<=$F20),$C20/$E20,0) -> 0 | ... AW20: =IF(AND(AW$6>=$D20,AW$6<=$F20),$C20/$E20,0) -> 0
A21: 14 | B21: ="WORKSHOP MEKANIK - "&Rekap!B30 -> WORKSHOP MEKANIK - PEKERJAAN TANAH (WORKSHOP MEKANIK) | C21: =Rekap!C30/Rekap!$C$69 -> 0.0030280737 | D21: 9 | E21: 4 | F21: =D21+E21-1 -> 12 | G21: =IF(AND(G$6>=$D21,G$6<=$F21),$C21/$E21,0) -> 0 | H21: =IF(AND(H$6>=$D21,H$6<=$F21),$C21/$E21,0) -> 0 | I21: =IF(AND(I$6>=$D21,I$6<=$F21),$C21/$E21,0) -> 0 | J21: =IF(AND(J$6>=$D21,J$6<=$F21),$C21/$E21,0) -> 0 | K21: =IF(AND(K$6>=$D21,K$6<=$F21),$C21/$E21,0) -> 0 | L21: =IF(AND(L$6>=$D21,L$6<=$F21),$C21/$E21,0) -> 0 | M21: =IF(AND(M$6>=$D21,M$6<=$F21),$C21/$E21,0) -> 0 | N21: =IF(AND(N$6>=$D21,N$6<=$F21),$C21/$E21,0) -> 0 | ... AW21: =IF(AND(AW$6>=$D21,AW$6<=$F21),$C21/$E21,0) -> 0
A22: 15 | B22: ="WORKSHOP MEKANIK - "&Rekap!B31 -> WORKSHOP MEKANIK - PEKERJAAN STRUKTURAL (WORKSHOP MEKANIK) | C22: =Rekap!C31/Rekap!$C$69 -> 0.058121373 | D22: 12 | E22: 15 | F22: =D22+E22-1 -> 26 | G22: =IF(AND(G$6>=$D22,G$6<=$F22),$C22/$E22,0) -> 0 | H22: =IF(AND(H$6>=$D22,H$6<=$F22),$C22/$E22,0) -> 0 | I22: =IF(AND(I$6>=$D22,I$6<=$F22),$C22/$E22,0) -> 0 | J22: =IF(AND(J$6>=$D22,J$6<=$F22),$C22/$E22,0) -> 0 | K22: =IF(AND(K$6>=$D22,K$6<=$F22),$C22/$E22,0) -> 0 | L22: =IF(AND(L$6>=$D22,L$6<=$F22),$C22/$E22,0) -> 0 | M22: =IF(AND(M$6>=$D22,M$6<=$F22),$C22/$E22,0) -> 0 | N22: =IF(AND(N$6>=$D22,N$6<=$F22),$C22/$E22,0) -> 0 | ... AW22: =IF(AND(AW$6>=$D22,AW$6<=$F22),$C22/$E22,0) -> 0
A23: 16 | B23: ="WORKSHOP MEKANIK - "&Rekap!B32 -> WORKSHOP MEKANIK - PEKERJAAN ARSITEKTURAL (WORKSHOP MEKANIK) | C23: =Rekap!C32/Rekap!$C$69 -> 0.047187545 | D23: 23 | E23: 12 | F23: =D23+E23-1 -> 34 | G23: =IF(AND(G$6>=$D23,G$6<=$F23),$C23/$E23,0) -> 0 | H23: =IF(AND(H$6>=$D23,H$6<=$F23),$C23/$E23,0) -> 0 | I23: =IF(AND(I$6>=$D23,I$6<=$F23),$C23/$E23,0) -> 0 | J23: =IF(AND(J$6>=$D23,J$6<=$F23),$C23/$E23,0) -> 0 | K23: =IF(AND(K$6>=$D23,K$6<=$F23),$C23/$E23,0) -> 0 | L23: =IF(AND(L$6>=$D23,L$6<=$F23),$C23/$E23,0) -> 0 | M23: =IF(AND(M$6>=$D23,M$6<=$F23),$C23/$E23,0) -> 0 | N23: =IF(AND(N$6>=$D23,N$6<=$F23),$C23/$E23,0) -> 0 | ... AW23: =IF(AND(AW$6>=$D23,AW$6<=$F23),$C23/$E23,0) -> 0
A24: 17 | B24: ="WORKSHOP MEKANIK - "&Rekap!B33 -> WORKSHOP MEKANIK - PEKERJAAN MEKANIKAL (WORKSHOP MEKANIK) | C24: =Rekap!C33/Rekap!$C$69 -> 0.0013998885 | D24: 31 | E24: 6 | F24: =D24+E24-1 -> 36 | G24: =IF(AND(G$6>=$D24,G$6<=$F24),$C24/$E24,0) -> 0 | H24: =IF(AND(H$6>=$D24,H$6<=$F24),$C24/$E24,0) -> 0 | I24: =IF(AND(I$6>=$D24,I$6<=$F24),$C24/$E24,0) -> 0 | J24: =IF(AND(J$6>=$D24,J$6<=$F24),$C24/$E24,0) -> 0 | K24: =IF(AND(K$6>=$D24,K$6<=$F24),$C24/$E24,0) -> 0 | L24: =IF(AND(L$6>=$D24,L$6<=$F24),$C24/$E24,0) -> 0 | M24: =IF(AND(M$6>=$D24,M$6<=$F24),$C24/$E24,0) -> 0 | N24: =IF(AND(N$6>=$D24,N$6<=$F24),$C24/$E24,0) -> 0 | ... AW24: =IF(AND(AW$6>=$D24,AW$6<=$F24),$C24/$E24,0) -> 0
A25: 18 | B25: ="WORKSHOP MEKANIK - "&Rekap!B34 -> WORKSHOP MEKANIK - PEKERJAAN PLUMBING (WORKSHOP MEKANIK) | C25: =Rekap!C34/Rekap!$C$69 -> 0.0032221666 | D25: 28 | E25: 9 | F25: =D25+E25-1 -> 36 | G25: =IF(AND(G$6>=$D25,G$6<=$F25),$C25/$E25,0) -> 0 | H25: =IF(AND(H$6>=$D25,H$6<=$F25),$C25/$E25,0) -> 0 | I25: =IF(AND(I$6>=$D25,I$6<=$F25),$C25/$E25,0) -> 0 | J25: =IF(AND(J$6>=$D25,J$6<=$F25),$C25/$E25,0) -> 0 | K25: =IF(AND(K$6>=$D25,K$6<=$F25),$C25/$E25,0) -> 0 | L25: =IF(AND(L$6>=$D25,L$6<=$F25),$C25/$E25,0) -> 0 | M25: =IF(AND(M$6>=$D25,M$6<=$F25),$C25/$E25,0) -> 0 | N25: =IF(AND(N$6>=$D25,N$6<=$F25),$C25/$E25,0) -> 0 | ... AW25: =IF(AND(AW$6>=$D25,AW$6<=$F25),$C25/$E25,0) -> 0
A26: 19 | B26: ="WORKSHOP MEKANIK - "&Rekap!B35 -> WORKSHOP MEKANIK - PEKERJAAN ELEKTRIKAL (WORKSHOP MEKANIK) | C26: =Rekap!C35/Rekap!$C$69 -> 0.0035878805 | D26: 30 | E26: 10 | F26: =D26+E26-1 -> 39 | G26: =IF(AND(G$6>=$D26,G$6<=$F26),$C26/$E26,0) -> 0 | H26: =IF(AND(H$6>=$D26,H$6<=$F26),$C26/$E26,0) -> 0 | I26: =IF(AND(I$6>=$D26,I$6<=$F26),$C26/$E26,0) -> 0 | J26: =IF(AND(J$6>=$D26,J$6<=$F26),$C26/$E26,0) -> 0 | K26: =IF(AND(K$6>=$D26,K$6<=$F26),$C26/$E26,0) -> 0 | L26: =IF(AND(L$6>=$D26,L$6<=$F26),$C26/$E26,0) -> 0 | M26: =IF(AND(M$6>=$D26,M$6<=$F26),$C26/$E26,0) -> 0 | N26: =IF(AND(N$6>=$D26,N$6<=$F26),$C26/$E26,0) -> 0 | ... AW26: =IF(AND(AW$6>=$D26,AW$6<=$F26),$C26/$E26,0) -> 0
A27: 20 | B27: ="WORKSHOP TIK - "&Rekap!B38 -> WORKSHOP TIK - PEKERJAAN TANAH (WORKSHOP RINGAN TEKNIK INFORMATIKA DAN KOMPUTER (TIK)) | C27: =Rekap!C38/Rekap!$C$69 -> 0.0030914695 | D27: 10 | E27: 4 | F27: =D27+E27-1 -> 13 | G27: =IF(AND(G$6>=$D27,G$6<=$F27),$C27/$E27,0) -> 0 | H27: =IF(AND(H$6>=$D27,H$6<=$F27),$C27/$E27,0) -> 0 | I27: =IF(AND(I$6>=$D27,I$6<=$F27),$C27/$E27,0) -> 0 | J27: =IF(AND(J$6>=$D27,J$6<=$F27),$C27/$E27,0) -> 0 | K27: =IF(AND(K$6>=$D27,K$6<=$F27),$C27/$E27,0) -> 0 | L27: =IF(AND(L$6>=$D27,L$6<=$F27),$C27/$E27,0) -> 0 | M27: =IF(AND(M$6>=$D27,M$6<=$F27),$C27/$E27,0) -> 0 | N27: =IF(AND(N$6>=$D27,N$6<=$F27),$C27/$E27,0) -> 0 | ... AW27: =IF(AND(AW$6>=$D27,AW$6<=$F27),$C27/$E27,0) -> 0
A28: 21 | B28: ="WORKSHOP TIK - "&Rekap!B39 -> WORKSHOP TIK - PEKERJAAN STRUKTURAL (WORKSHOP RINGAN TEKNIK INFORMATIKA DAN KOMPUTER (TIK)) | C28: =Rekap!C39/Rekap!$C$69 -> 0.031159232 | D28: 13 | E28: 14 | F28: =D28+E28-1 -> 26 | G28: =IF(AND(G$6>=$D28,G$6<=$F28),$C28/$E28,0) -> 0 | H28: =IF(AND(H$6>=$D28,H$6<=$F28),$C28/$E28,0) -> 0 | I28: =IF(AND(I$6>=$D28,I$6<=$F28),$C28/$E28,0) -> 0 | J28: =IF(AND(J$6>=$D28,J$6<=$F28),$C28/$E28,0) -> 0 | K28: =IF(AND(K$6>=$D28,K$6<=$F28),$C28/$E28,0) -> 0 | L28: =IF(AND(L$6>=$D28,L$6<=$F28),$C28/$E28,0) -> 0 | M28: =IF(AND(M$6>=$D28,M$6<=$F28),$C28/$E28,0) -> 0 | N28: =IF(AND(N$6>=$D28,N$6<=$F28),$C28/$E28,0) -> 0 | ... AW28: =IF(AND(AW$6>=$D28,AW$6<=$F28),$C28/$E28,0) -> 0
A29: 22 | B29: ="WORKSHOP TIK - "&Rekap!B40 -> WORKSHOP TIK - PEKERJAAN ARSITEKTURAL (WORKSHOP RINGAN TEKNIK INFORMATIKA DAN KOMPUTER (TIK)) | C29: =Rekap!C40/Rekap!$C$69 -> 0.039778688 | D29: 24 | E29: 12 | F29: =D29+E29-1 -> 35 | G29: =IF(AND(G$6>=$D29,G$6<=$F29),$C29/$E29,0) -> 0 | H29: =IF(AND(H$6>=$D29,H$6<=$F29),$C29/$E29,0) -> 0 | I29: =IF(AND(I$6>=$D29,I$6<=$F29),$C29/$E29,0) -> 0 | J29: =IF(AND(J$6>=$D29,J$6<=$F29),$C29/$E29,0) -> 0 | K29: =IF(AND(K$6>=$D29,K$6<=$F29),$C29/$E29,0) -> 0 | L29: =IF(AND(L$6>=$D29,L$6<=$F29),$C29/$E29,0) -> 0 | M29: =IF(AND(M$6>=$D29,M$6<=$F29),$C29/$E29,0) -> 0 | N29: =IF(AND(N$6>=$D29,N$6<=$F29),$C29/$E29,0) -> 0 | ... AW29: =IF(AND(AW$6>=$D29,AW$6<=$F29),$C29/$E29,0) -> 0
A30: 23 | B30: ="WORKSHOP TIK - "&Rekap!B41 -> WORKSHOP TIK - PEKERJAAN MEKANIKAL PLUMBING (WORKSHOP TEKNIK INFORMATIKA DAN KOMPUTER (TIK)) | C30: =Rekap!C41/Rekap!$C$69 -> 0.006397383 | D30: 28 | E30: 10 | F30: =D30+E30-1 -> 37 | G30: =IF(AND(G$6>=$D30,G$6<=$F30),$C30/$E30,0) -> 0 | H30: =IF(AND(H$6>=$D30,H$6<=$F30),$C30/$E30,0) -> 0 | I30: =IF(AND(I$6>=$D30,I$6<=$F30),$C30/$E30,0) -> 0 | J30: =IF(AND(J$6>=$D30,J$6<=$F30),$C30/$E30,0) -> 0 | K30: =IF(AND(K$6>=$D30,K$6<=$F30),$C30/$E30,0) -> 0 | L30: =IF(AND(L$6>=$D30,L$6<=$F30),$C30/$E30,0) -> 0 | M30: =IF(AND(M$6>=$D30,M$6<=$F30),$C30/$E30,0) -> 0 | N30: =IF(AND(N$6>=$D30,N$6<=$F30),$C30/$E30,0) -> 0 | ... AW30: =IF(AND(AW$6>=$D30,AW$6<=$F30),$C30/$E30,0) -> 0
A31: 24 | B31: ="WORKSHOP TIK - "&Rekap!B42 -> WORKSHOP TIK - PEKERJAAN ELEKTRIKAL (WORKSHOP TEKNIK INFORMATIKA DAN KOMPUTER (TIK)) | C31: =Rekap!C42/Rekap!$C$69 -> 0.0041105127 | D31: 30 | E31: 10 | F31: =D31+E31-1 -> 39 | G31: =IF(AND(G$6>=$D31,G$6<=$F31),$C31/$E31,0) -> 0 | H31: =IF(AND(H$6>=$D31,H$6<=$F31),$C31/$E31,0) -> 0 | I31: =IF(AND(I$6>=$D31,I$6<=$F31),$C31/$E31,0) -> 0 | J31: =IF(AND(J$6>=$D31,J$6<=$F31),$C31/$E31,0) -> 0 | K31: =IF(AND(K$6>=$D31,K$6<=$F31),$C31/$E31,0) -> 0 | L31: =IF(AND(L$6>=$D31,L$6<=$F31),$C31/$E31,0) -> 0 | M31: =IF(AND(M$6>=$D31,M$6<=$F31),$C31/$E31,0) -> 0 | N31: =IF(AND(N$6>=$D31,N$6<=$F31),$C31/$E31,0) -> 0 | ... AW31: =IF(AND(AW$6>=$D31,AW$6<=$F31),$C31/$E31,0) -> 0
A32: 25 | B32: ="GARDU PLN & POWER HOUSE - "&Rekap!B45 -> GARDU PLN & POWER HOUSE - PEKERJAAN TANAH (PLN) | C32: =Rekap!C45/Rekap!$C$69 -> 0.0037479395 | D32: 10 | E32: 3 | F32: =D32+E32-1 -> 12 | G32: =IF(AND(G$6>=$D32,G$6<=$F32),$C32/$E32,0) -> 0 | H32: =IF(AND(H$6>=$D32,H$6<=$F32),$C32/$E32,0) -> 0 | I32: =IF(AND(I$6>=$D32,I$6<=$F32),$C32/$E32,0) -> 0 | J32: =IF(AND(J$6>=$D32,J$6<=$F32),$C32/$E32,0) -> 0 | K32: =IF(AND(K$6>=$D32,K$6<=$F32),$C32/$E32,0) -> 0 | L32: =IF(AND(L$6>=$D32,L$6<=$F32),$C32/$E32,0) -> 0 | M32: =IF(AND(M$6>=$D32,M$6<=$F32),$C32/$E32,0) -> 0 | N32: =IF(AND(N$6>=$D32,N$6<=$F32),$C32/$E32,0) -> 0 | ... AW32: =IF(AND(AW$6>=$D32,AW$6<=$F32),$C32/$E32,0) -> 0
A33: 26 | B33: ="GARDU PLN & POWER HOUSE - "&Rekap!B46 -> GARDU PLN & POWER HOUSE - PEKERJAAN STRUKTURAL (PLN) | C33: =Rekap!C46/Rekap!$C$69 -> 0.036538327 | D33: 13 | E33: 9 | F33: =D33+E33-1 -> 21 | G33: =IF(AND(G$6>=$D33,G$6<=$F33),$C33/$E33,0) -> 0 | H33: =IF(AND(H$6>=$D33,H$6<=$F33),$C33/$E33,0) -> 0 | I33: =IF(AND(I$6>=$D33,I$6<=$F33),$C33/$E33,0) -> 0 | J33: =IF(AND(J$6>=$D33,J$6<=$F33),$C33/$E33,0) -> 0 | K33: =IF(AND(K$6>=$D33,K$6<=$F33),$C33/$E33,0) -> 0 | L33: =IF(AND(L$6>=$D33,L$6<=$F33),$C33/$E33,0) -> 0 | M33: =IF(AND(M$6>=$D33,M$6<=$F33),$C33/$E33,0) -> 0 | N33: =IF(AND(N$6>=$D33,N$6<=$F33),$C33/$E33,0) -> 0 | ... AW33: =IF(AND(AW$6>=$D33,AW$6<=$F33),$C33/$E33,0) -> 0
A34: 27 | B34: ="GARDU PLN & POWER HOUSE - "&Rekap!B47 -> GARDU PLN & POWER HOUSE - PEKERJAAN ARSITEKTURAL (PLN) | C34: =Rekap!C47/Rekap!$C$69 -> 0.011080081 | D34: 20 | E34: 9 | F34: =D34+E34-1 -> 28 | G34: =IF(AND(G$6>=$D34,G$6<=$F34),$C34/$E34,0) -> 0 | H34: =IF(AND(H$6>=$D34,H$6<=$F34),$C34/$E34,0) -> 0 | I34: =IF(AND(I$6>=$D34,I$6<=$F34),$C34/$E34,0) -> 0 | J34: =IF(AND(J$6>=$D34,J$6<=$F34),$C34/$E34,0) -> 0 | K34: =IF(AND(K$6>=$D34,K$6<=$F34),$C34/$E34,0) -> 0 | L34: =IF(AND(L$6>=$D34,L$6<=$F34),$C34/$E34,0) -> 0 | M34: =IF(AND(M$6>=$D34,M$6<=$F34),$C34/$E34,0) -> 0 | N34: =IF(AND(N$6>=$D34,N$6<=$F34),$C34/$E34,0) -> 0 | ... AW34: =IF(AND(AW$6>=$D34,AW$6<=$F34),$C34/$E34,0) -> 0
A35: 28 | B35: ="GARDU PLN & POWER HOUSE - "&Rekap!B48 -> GARDU PLN & POWER HOUSE - PEKERJAAN MEKANIKAL (PLN) | C35: =Rekap!C48/Rekap!$C$69 -> 0.00031551115 | D35: 30 | E35: 3 | F35: =D35+E35-1 -> 32 | G35: =IF(AND(G$6>=$D35,G$6<=$F35),$C35/$E35,0) -> 0 | H35: =IF(AND(H$6>=$D35,H$6<=$F35),$C35/$E35,0) -> 0 | I35: =IF(AND(I$6>=$D35,I$6<=$F35),$C35/$E35,0) -> 0 | J35: =IF(AND(J$6>=$D35,J$6<=$F35),$C35/$E35,0) -> 0 | K35: =IF(AND(K$6>=$D35,K$6<=$F35),$C35/$E35,0) -> 0 | L35: =IF(AND(L$6>=$D35,L$6<=$F35),$C35/$E35,0) -> 0 | M35: =IF(AND(M$6>=$D35,M$6<=$F35),$C35/$E35,0) -> 0 | N35: =IF(AND(N$6>=$D35,N$6<=$F35),$C35/$E35,0) -> 0 | ... AW35: =IF(AND(AW$6>=$D35,AW$6<=$F35),$C35/$E35,0) -> 0
A36: 29 | B36: ="GARDU PLN & POWER HOUSE - "&Rekap!B49 -> GARDU PLN & POWER HOUSE - PEKERJAAN ELEKTRIKAL (PLN) | C36: =Rekap!C49/Rekap!$C$69 -> 0.056837492 | D36: 27 | E36: 14 | F36: =D36+E36-1 -> 40 | G36: =IF(AND(G$6>=$D36,G$6<=$F36),$C36/$E36,0) -> 0 | H36: =IF(AND(H$6>=$D36,H$6<=$F36),$C36/$E36,0) -> 0 | I36: =IF(AND(I$6>=$D36,I$6<=$F36),$C36/$E36,0) -> 0 | J36: =IF(AND(J$6>=$D36,J$6<=$F36),$C36/$E36,0) -> 0 | K36: =IF(AND(K$6>=$D36,K$6<=$F36),$C36/$E36,0) -> 0 | L36: =IF(AND(L$6>=$D36,L$6<=$F36),$C36/$E36,0) -> 0 | M36: =IF(AND(M$6>=$D36,M$6<=$F36),$C36/$E36,0) -> 0 | N36: =IF(AND(N$6>=$D36,N$6<=$F36),$C36/$E36,0) -> 0 | ... AW36: =IF(AND(AW$6>=$D36,AW$6<=$F36),$C36/$E36,0) -> 0
A37: 30 | B37: ="PUMP HOUSE - "&Rekap!B52 -> PUMP HOUSE - PEKERJAAN TANAH (PUMP HOUSE) | C37: =Rekap!C52/Rekap!$C$69 -> 0.0019992443 | D37: 11 | E37: 3 | F37: =D37+E37-1 -> 13 | G37: =IF(AND(G$6>=$D37,G$6<=$F37),$C37/$E37,0) -> 0 | H37: =IF(AND(H$6>=$D37,H$6<=$F37),$C37/$E37,0) -> 0 | I37: =IF(AND(I$6>=$D37,I$6<=$F37),$C37/$E37,0) -> 0 | J37: =IF(AND(J$6>=$D37,J$6<=$F37),$C37/$E37,0) -> 0 | K37: =IF(AND(K$6>=$D37,K$6<=$F37),$C37/$E37,0) -> 0 | L37: =IF(AND(L$6>=$D37,L$6<=$F37),$C37/$E37,0) -> 0 | M37: =IF(AND(M$6>=$D37,M$6<=$F37),$C37/$E37,0) -> 0 | N37: =IF(AND(N$6>=$D37,N$6<=$F37),$C37/$E37,0) -> 0 | ... AW37: =IF(AND(AW$6>=$D37,AW$6<=$F37),$C37/$E37,0) -> 0
A38: 31 | B38: ="PUMP HOUSE - "&Rekap!B53 -> PUMP HOUSE - PEKERJAAN STRUKTURAL (PUMP HOUSE) | C38: =Rekap!C53/Rekap!$C$69 -> 0.012863343 | D38: 14 | E38: 8 | F38: =D38+E38-1 -> 21 | G38: =IF(AND(G$6>=$D38,G$6<=$F38),$C38/$E38,0) -> 0 | H38: =IF(AND(H$6>=$D38,H$6<=$F38),$C38/$E38,0) -> 0 | I38: =IF(AND(I$6>=$D38,I$6<=$F38),$C38/$E38,0) -> 0 | J38: =IF(AND(J$6>=$D38,J$6<=$F38),$C38/$E38,0) -> 0 | K38: =IF(AND(K$6>=$D38,K$6<=$F38),$C38/$E38,0) -> 0 | L38: =IF(AND(L$6>=$D38,L$6<=$F38),$C38/$E38,0) -> 0 | M38: =IF(AND(M$6>=$D38,M$6<=$F38),$C38/$E38,0) -> 0 | N38: =IF(AND(N$6>=$D38,N$6<=$F38),$C38/$E38,0) -> 0 | ... AW38: =IF(AND(AW$6>=$D38,AW$6<=$F38),$C38/$E38,0) -> 0
A39: 32 | B39: ="PUMP HOUSE - "&Rekap!B54 -> PUMP HOUSE - PEKERJAAN ARSITEKTURAL (PUMP HOUSE) | C39: =Rekap!C54/Rekap!$C$69 -> 0.0056135153 | D39: 20 | E39: 8 | F39: =D39+E39-1 -> 27 | G39: =IF(AND(G$6>=$D39,G$6<=$F39),$C39/$E39,0) -> 0 | H39: =IF(AND(H$6>=$D39,H$6<=$F39),$C39/$E39,0) -> 0 | I39: =IF(AND(I$6>=$D39,I$6<=$F39),$C39/$E39,0) -> 0 | J39: =IF(AND(J$6>=$D39,J$6<=$F39),$C39/$E39,0) -> 0 | K39: =IF(AND(K$6>=$D39,K$6<=$F39),$C39/$E39,0) -> 0 | L39: =IF(AND(L$6>=$D39,L$6<=$F39),$C39/$E39,0) -> 0 | M39: =IF(AND(M$6>=$D39,M$6<=$F39),$C39/$E39,0) -> 0 | N39: =IF(AND(N$6>=$D39,N$6<=$F39),$C39/$E39,0) -> 0 | ... AW39: =IF(AND(AW$6>=$D39,AW$6<=$F39),$C39/$E39,0) -> 0
A40: 33 | B40: ="PUMP HOUSE - "&Rekap!B55 -> PUMP HOUSE - PEKERJAAN MEKANIKAL (PUMP HOUSE) | C40: =Rekap!C55/Rekap!$C$69 -> 0.015273374 | D40: 28 | E40: 6 | F40: =D40+E40-1 -> 33 | G40: =IF(AND(G$6>=$D40,G$6<=$F40),$C40/$E40,0) -> 0 | H40: =IF(AND(H$6>=$D40,H$6<=$F40),$C40/$E40,0) -> 0 | I40: =IF(AND(I$6>=$D40,I$6<=$F40),$C40/$E40,0) -> 0 | J40: =IF(AND(J$6>=$D40,J$6<=$F40),$C40/$E40,0) -> 0 | K40: =IF(AND(K$6>=$D40,K$6<=$F40),$C40/$E40,0) -> 0 | L40: =IF(AND(L$6>=$D40,L$6<=$F40),$C40/$E40,0) -> 0 | M40: =IF(AND(M$6>=$D40,M$6<=$F40),$C40/$E40,0) -> 0 | N40: =IF(AND(N$6>=$D40,N$6<=$F40),$C40/$E40,0) -> 0 | ... AW40: =IF(AND(AW$6>=$D40,AW$6<=$F40),$C40/$E40,0) -> 0
A41: 34 | B41: ="PUMP HOUSE - "&Rekap!B56 -> PUMP HOUSE - PEKERJAAN PLUMBING (PUMP HOUSE) | C41: =Rekap!C56/Rekap!$C$69 -> 0.0045628421 | D41: 28 | E41: 6 | F41: =D41+E41-1 -> 33 | G41: =IF(AND(G$6>=$D41,G$6<=$F41),$C41/$E41,0) -> 0 | H41: =IF(AND(H$6>=$D41,H$6<=$F41),$C41/$E41,0) -> 0 | I41: =IF(AND(I$6>=$D41,I$6<=$F41),$C41/$E41,0) -> 0 | J41: =IF(AND(J$6>=$D41,J$6<=$F41),$C41/$E41,0) -> 0 | K41: =IF(AND(K$6>=$D41,K$6<=$F41),$C41/$E41,0) -> 0 | L41: =IF(AND(L$6>=$D41,L$6<=$F41),$C41/$E41,0) -> 0 | M41: =IF(AND(M$6>=$D41,M$6<=$F41),$C41/$E41,0) -> 0 | N41: =IF(AND(N$6>=$D41,N$6<=$F41),$C41/$E41,0) -> 0 | ... AW41: =IF(AND(AW$6>=$D41,AW$6<=$F41),$C41/$E41,0) -> 0
...
