Workbook

Sheet Informasi Project
A1: RENCANA ANGGARAN BIAYA (RAB)
A2: Sel BIRU = input pengguna; hitam = rumus; hijau = tautan antar sheet; kuning = asumsi kunci. Data di bawah adalah CONTOH sampai gambar kerja dilampirkan.
A4: Nama Pekerjaan | B4: Pembangunan Gedung Kantor 1 Lantai (CONTOH - sesuaikan dengan gambar)
A5: Lokasi Pekerjaan | B5: Kabupaten Morowali Utara, Provinsi Sulawesi Tengah
A6: Pemilik / PPK | B6: (isi nama instansi / PPK)
A7: Project Manager | B7: (isi nama PM)
A8: Konsultan Perencana / Pengawas | B8: (isi)
A9: Kontraktor Pelaksana | B9: (isi)
A10: Jenis Pekerjaan | B10: Konstruksi Bangunan Gedung (Cipta Karya)
A11: Tahun Anggaran | B11: 2026
A12: Acuan Harga Satuan | B12: HSPK/Analisis Standar Biaya & HSD Kab. Morowali Utara TA 2026 (isi nomor Perbup)
A13: Status Harga | B13: ASUMSI INDIKATIF - belum diverifikasi ke Perbup/survei; WAJIB diganti
A14: Luas Bangunan (m²) | B14: 120
A15: Waktu Pelaksanaan (hari kalender) | B15: 150
A16: Waktu Pelaksanaan (minggu) | B16: =CEILING(B15/7,1) -> 22
A17: Overhead & Profit (%) | B17: 0.15
A18: PPN (%) | B18: 0.11
A19: Pembulatan ke kelipatan (Rp) | B19: 1000
A20: Tanggal Mulai (rencana) | B20: 46027
A21: Sumber Dana | B21: APBD Kab. Morowali Utara TA 2026 (sesuaikan)
A24: CATATAN & ASUMSI
A25: 1. Harga bahan & upah adalah ESTIMASI INDIKATIF level Kab. Morowali Utara (daerah dengan biaya angkut tinggi). Data resmi Perbup HSPK/HSD Morowali Utara TA 2026 tidak dapat saya akses; ganti seluruh sel biru di sheet Harga Bahan & Harga Upah dengan angka Perbup / survei pasar.
A26: 2. Koefisien AHSP mengacu pola SNI/Permen PUPR (Analisis Harga Satuan Pekerjaan) - bersifat indikatif; sesuaikan dengan spesifikasi teknis.
A27: 3. Volume pada sheet RAB adalah volume CONTOH untuk gedung 1 lantai +/-120 m² (kolom Keterangan menjelaskan dasar hitungnya). Ganti dengan quantity take-off dari gambar kerja.
A28: 4. Pekerjaan Lump Sum (LS) memakai harga input langsung (biru) pada sheet RAB.
A29: 5. Alur: Harga Bahan & Harga Upah -> Analisa Harga Satuan -> RAB -> Rekap RAB -> Schedule (bobot & kurva S).
A30: 6. Tarif PPN 11% adalah input; ubah di B18 bila ketentuan perpajakan berbeda.

Sheet Rekap RAB
A1: REKAPITULASI RENCANA ANGGARAN BIAYA
A2: ="Pekerjaan: "&'Informasi Project'!B4 -> Pekerjaan: Pembangunan Gedung Kantor 1 Lantai (CONTOH - sesuaikan dengan gambar)
A3: ="Lokasi: "&'Informasi Project'!B5 -> Lokasi: Kabupaten Morowali Utara, Provinsi Sulawesi Tengah
A4: ="Tahun Anggaran: "&'Informasi Project'!B11 -> Tahun Anggaran: 2026
A6: No | B6: Uraian Pekerjaan | C6: Jumlah Harga (Rp) | D6: Bobot (%)
A7: I | B7: PEKERJAAN PERSIAPAN | C7: =RAB!G15 -> 37880934 | D7: =IF($C$18=0,0,C7/$C$18) -> 0.059091738
A8: II | B8: PEKERJAAN TANAH & PONDASI | C8: =RAB!G25 -> 68993990 | D8: =IF($C$18=0,0,C8/$C$18) -> 0.10762604
A9: III | B9: PEKERJAAN STRUKTUR BETON | C9: =RAB!G33 -> 1.2842809e+08 | D9: =IF($C$18=0,0,C9/$C$18) -> 0.20033929
A10: IV | B10: PEKERJAAN DINDING | C10: =RAB!G39 -> 1.2206304e+08 | D10: =IF($C$18=0,0,C10/$C$18) -> 0.19041022
A11: V | B11: PEKERJAAN ATAP & PLAFON | C11: =RAB!G45 -> 125467760 | D11: =IF($C$18=0,0,C11/$C$18) -> 0.19572136
A12: VI | B12: PEKERJAAN LANTAI & KERAMIK | C12: =RAB!G50 -> 54110778 | D12: =IF($C$18=0,0,C12/$C$18) -> 0.084409215
A13: VII | B13: PEKERJAAN KUSEN, PINTU & JENDELA | C13: =RAB!G55 -> 38170110 | D13: =IF($C$18=0,0,C13/$C$18) -> 0.059542834
A14: VIII | B14: PEKERJAAN FINISHING | C14: =RAB!G60 -> 24990420 | D14: =IF($C$18=0,0,C14/$C$18) -> 0.038983394
A15: IX | B15: PEKERJAAN SANITASI & AIR | C15: =RAB!G68 -> 22296390 | D15: =IF($C$18=0,0,C15/$C$18) -> 0.034780886
A16: X | B16: PEKERJAAN INSTALASI LISTRIK | C16: =RAB!G74 -> 17260670 | D16: =IF($C$18=0,0,C16/$C$18) -> 0.026925498
A17: XI | B17: PEKERJAAN AKHIR | C17: =RAB!G78 -> 1390781.2 | D17: =IF($C$18=0,0,C17/$C$18) -> 0.0021695263
B18: JUMLAH | C18: =SUM(C7:C17) -> 6.4105296e+08 | D18: =SUM(D7:D17) -> 1
B19: PPN | C19: =C18*'Informasi Project'!$B$18 -> 70515826
B20: JUMLAH TOTAL (termasuk PPN) | C20: =C18+C19 -> 7.1156879e+08
B21: DIBULATKAN | C21: =IF('Informasi Project'!$B$19>0,CEILING(C20,'Informasi Project'!$B$19),C20) -> 711569000
B22: Biaya per m² bangunan (dibulatkan) | C22: =IF('Informasi Project'!$B$14>0,C21/'Informasi Project'!$B$14,0) -> 5929741.7
B25: Disusun oleh, | C25: Disetujui oleh,
B29: ( Project Manager ) | C29: ( PPK / Pemilik )

Sheet RAB
A1: RENCANA ANGGARAN BIAYA (RAB)
A2: ="Pekerjaan: "&'Informasi Project'!B4 -> Pekerjaan: Pembangunan Gedung Kantor 1 Lantai (CONTOH - sesuaikan dengan gambar)
A3: ="Lokasi: "&'Informasi Project'!B5 -> Lokasi: Kabupaten Morowali Utara, Provinsi Sulawesi Tengah
A4: Kode AHSP & Volume (biru) = input. Volume contoh - ganti dari gambar kerja. Baris 'LS' = lump sum, harga input langsung.
A6: No | B6: Uraian Pekerjaan | C6: Kode AHSP | D6: Satuan | E6: Volume | F6: Harga Satuan (Rp) | G6: Jumlah Harga (Rp) | H6: Dasar Volume (contoh)
A7: I | B7: PEKERJAAN PERSIAPAN
A8: 1 | B8: Mobilisasi & demobilisasi peralatan/personel | C8: - | D8: LS | E8: 1 | F8: 7500000 | G8: =E8*F8 -> 7500000 | H8: Lump sum, biaya angkut ke Morowali Utara
A9: 2 | B9: Direksi keet, gudang & fasilitas sementara | C9: - | D9: LS | E9: 1 | F9: 9000000 | G9: =E9*F9 -> 9000000 | H9: Lump sum
A10: 3 | B10: Papan nama proyek | C10: - | D10: LS | E10: 1 | F10: 750000 | G10: =E10*F10 -> 750000 | H10: Lump sum
A11: 4 | B11: Keselamatan & kesehatan kerja (SMKK) | C11: - | D11: LS | E11: 1 | F11: 6500000 | G11: =E11*F11 -> 6500000 | H11: Lump sum - APD, rambu, P3K
A12: 5 | B12: Dokumentasi, pelaporan & gambar as built drawing | C12: - | D12: LS | E12: 1 | F12: 3500000 | G12: =E12*F12 -> 3500000 | H12: Lump sum
A13: 6 | B13: =INDEX('Analisa Harga Satuan'!$B$5:$B$372,MATCH(C13,'Analisa Harga Satuan'!$A$5:$A$372,0)) -> Pembersihan lahan & perataan | C13: P.2 | D13: =INDEX('Analisa Harga Satuan'!$C$5:$C$372,MATCH(C13,'Analisa Harga Satuan'!$A$5:$A$372,0)) -> m² | E13: 220 | F13: =INDEX('Analisa Harga Satuan'!$F$5:$F$372,MATCH(C13,'Analisa Harga Satuan'!$A$5:$A$372,0)) -> 9271.875 | G13: =E13*F13 -> 2039812.5 | H13: Luas lahan kerja = bangunan + 100 m²
A14: 7 | B14: =INDEX('Analisa Harga Satuan'!$B$5:$B$372,MATCH(C14,'Analisa Harga Satuan'!$A$5:$A$372,0)) -> Pengukuran & pemasangan bouwplank | C14: P.1 | D14: =INDEX('Analisa Harga Satuan'!$C$5:$C$372,MATCH(C14,'Analisa Harga Satuan'!$A$5:$A$372,0)) -> m' | E14: 44 | F14: =INDEX('Analisa Harga Satuan'!$F$5:$F$372,MATCH(C14,'Analisa Harga Satuan'!$A$5:$A$372,0)) -> 195252.75 | G14: =E14*F14 -> 8591121 | H14: Keliling 2x(10+12) m
B15: Sub Total I | G15: =SUM(G8:G14) -> 37880934
A17: II | B17: PEKERJAAN TANAH & PONDASI
A18: 1 | B18: =INDEX('Analisa Harga Satuan'!$B$5:$B$372,MATCH(C18,'Analisa Harga Satuan'!$A$5:$A$372,0)) -> Galian tanah biasa kedalaman s.d. 1 m | C18: T.1 | D18: =INDEX('Analisa Harga Satuan'!$C$5:$C$372,MATCH(C18,'Analisa Harga Satuan'!$A$5:$A$372,0)) -> m³ | E18: 38.4 | F18: =INDEX('Analisa Harga Satuan'!$F$5:$F$372,MATCH(C18,'Analisa Harga Satuan'!$A$5:$A$372,0)) -> 135843.75 | G18: =E18*F18 -> 5216400 | H18: 80 m' x 0,6 m x 0,8 m
A19: 2 | B19: =INDEX('Analisa Harga Satuan'!$B$5:$B$372,MATCH(C19,'Analisa Harga Satuan'!$A$5:$A$372,0)) -> Urugan pasir bawah pondasi / lantai | C19: T.2 | D19: =INDEX('Analisa Harga Satuan'!$C$5:$C$372,MATCH(C19,'Analisa Harga Satuan'!$A$5:$A$372,0)) -> m³ | E19: 4.8 | F19: =INDEX('Analisa Harga Satuan'!$F$5:$F$372,MATCH(C19,'Analisa Harga Satuan'!$A$5:$A$372,0)) -> 468337.5 | G19: =E19*F19 -> 2248020 | H19: 80 m' x 0,6 m x 0,1 m
A20: 3 | B20: =INDEX('Analisa Harga Satuan'!$B$5:$B$372,MATCH(C20,'Analisa Harga Satuan'!$A$5:$A$372,0)) -> Pasangan batu kosong (aanstamping) | C20: T.3 | D20: =INDEX('Analisa Harga Satuan'!$C$5:$C$372,MATCH(C20,'Analisa Harga Satuan'!$A$5:$A$372,0)) -> m³ | E20: 9.6 | F20: =INDEX('Analisa Harga Satuan'!$F$5:$F$372,MATCH(C20,'Analisa Harga Satuan'!$A$5:$A$372,0)) -> 843714.75 | G20: =E20*F20 -> 8099661.6 | H20: 80 m' x 0,6 m x 0,2 m
A21: 4 | B21: =INDEX('Analisa Harga Satuan'!$B$5:$B$372,MATCH(C21,'Analisa Harga Satuan'!$A$5:$A$372,0)) -> Pondasi batu kali campuran 1 PC : 5 PS | C21: T.4 | D21: =INDEX('Analisa Harga Satuan'!$C$5:$C$372,MATCH(C21,'Analisa Harga Satuan'!$A$5:$A$372,0)) -> m³ | E21: 25.2 | F21: =INDEX('Analisa Harga Satuan'!$F$5:$F$372,MATCH(C21,'Analisa Harga Satuan'!$A$5:$A$372,0)) -> 1478698.8 | G21: =E21*F21 -> 37263208 | H21: 80 m' x 0,45 m x 0,7 m
A22: 5 | B22: =INDEX('Analisa Harga Satuan'!$B$5:$B$372,MATCH(C22,'Analisa Harga Satuan'!$A$5:$A$372,0)) -> Urugan tanah kembali (galian setempat) | C22: T.5 | D22: =INDEX('Analisa Harga Satuan'!$C$5:$C$372,MATCH(C22,'Analisa Harga Satuan'!$A$5:$A$372,0)) -> m³ | E22: 12 | F22: =INDEX('Analisa Harga Satuan'!$F$5:$F$372,MATCH(C22,'Analisa Harga Satuan'!$A$5:$A$372,0)) -> 54337.5 | G22: =E22*F22 -> 652050 | H22: Sisa galian setelah pondasi
A23: 6 | B23: =INDEX('Analisa Harga Satuan'!$B$5:$B$372,MATCH(C23,'Analisa Harga Satuan'!$A$5:$A$372,0)) -> Urugan tanah peninggi lantai (didatangkan) | C23: T.6 | D23: =INDEX('Analisa Harga Satuan'!$C$5:$C$372,MATCH(C23,'Analisa Harga Satuan'!$A$5:$A$372,0)) -> m³ | E23: 48 | F23: =INDEX('Analisa Harga Satuan'!$F$5:$F$372,MATCH(C23,'Analisa Harga Satuan'!$A$5:$A$372,0)) -> 206137.5 | G23: =E23*F23 -> 9894600 | H23: 120 m² x 0,4 m peninggian lantai
A24: 7 | B24: =INDEX('Analisa Harga Satuan'!$B$5:$B$372,MATCH(C24,'Analisa Harga Satuan'!$A$5:$A$372,0)) -> Urugan pasir bawah pondasi / lantai | C24: T.2 | D24: =INDEX('Analisa Harga Satuan'!$C$5:$C$372,MATCH(C24,'Analisa Harga Satuan'!$A$5:$A$372,0)) -> m³ | E24: 12 | F24: =INDEX('Analisa Harga Satuan'!$F$5:$F$372,MATCH(C24,'Analisa Harga Satuan'!$A$5:$A$372,0)) -> 468337.5 | G24: =E24*F24 -> 5620050 | H24: 120 m² x 0,1 m (pasir bawah lantai)
B25: Sub Total II | G25: =SUM(G18:G24) -> 68993990
A27: III | B27: PEKERJAAN STRUKTUR BETON
A28: 1 | B28: =INDEX('Analisa Harga Satuan'!$B$5:$B$372,MATCH(C28,'Analisa Harga Satuan'!$A$5:$A$372,0)) -> Beton K-125 (lantai kerja) | C28: S.1 | D28: =INDEX('Analisa Harga Satuan'!$C$5:$C$372,MATCH(C28,'Analisa Harga Satuan'!$A$5:$A$372,0)) -> m³ | E28: 6 | F28: =INDEX('Analisa Harga Satuan'!$F$5:$F$372,MATCH(C28,'Analisa Harga Satuan'!$A$5:$A$372,0)) -> 1828781.8 | G28: =E28*F28 -> 10972690 | H28: 120 m² x 0,05 m lantai kerja
A29: 2 | B29: =INDEX('Analisa Harga Satuan'!$B$5:$B$372,MATCH(C29,'Analisa Harga Satuan'!$A$5:$A$372,0)) -> Beton K-225 (kolom, sloof, balok, ring balk) | C29: S.2 | D29: =INDEX('Analisa Harga Satuan'!$C$5:$C$372,MATCH(C29,'Analisa Harga Satuan'!$A$5:$A$372,0)) -> m³ | E29: 9.5 | F29: =INDEX('Analisa Harga Satuan'!$F$5:$F$372,MATCH(C29,'Analisa Harga Satuan'!$A$5:$A$372,0)) -> 2005134.2 | G29: =E29*F29 -> 19048775 | H29: Kolom 3,65 + sloof 2,4 + ring balk 2,4 + lain-lain
A30: 3 | B30: =INDEX('Analisa Harga Satuan'!$B$5:$B$372,MATCH(C30,'Analisa Harga Satuan'!$A$5:$A$372,0)) -> Pembesian dengan besi beton | C30: S.3 | D30: =INDEX('Analisa Harga Satuan'!$C$5:$C$372,MATCH(C30,'Analisa Harga Satuan'!$A$5:$A$372,0)) -> kg | E30: 1450 | F30: =INDEX('Analisa Harga Satuan'!$F$5:$F$372,MATCH(C30,'Analisa Harga Satuan'!$A$5:$A$372,0)) -> 24623.8 | G30: =E30*F30 -> 35704510 | H30: +/-150 kg/m³ beton
A31: 4 | B31: =INDEX('Analisa Harga Satuan'!$B$5:$B$372,MATCH(C31,'Analisa Harga Satuan'!$A$5:$A$372,0)) -> Bekisting kolom (plywood) | C31: S.4 | D31: =INDEX('Analisa Harga Satuan'!$C$5:$C$372,MATCH(C31,'Analisa Harga Satuan'!$A$5:$A$372,0)) -> m² | E31: 73 | F31: =INDEX('Analisa Harga Satuan'!$F$5:$F$372,MATCH(C31,'Analisa Harga Satuan'!$A$5:$A$372,0)) -> 391184 | G31: =E31*F31 -> 28556432 | H31: 24 kolom x 0,8 m x 3,8 m
A32: 5 | B32: =INDEX('Analisa Harga Satuan'!$B$5:$B$372,MATCH(C32,'Analisa Harga Satuan'!$A$5:$A$372,0)) -> Bekisting sloof / balok (papan kayu) | C32: S.5 | D32: =INDEX('Analisa Harga Satuan'!$C$5:$C$372,MATCH(C32,'Analisa Harga Satuan'!$A$5:$A$372,0)) -> m² | E32: 90 | F32: =INDEX('Analisa Harga Satuan'!$F$5:$F$372,MATCH(C32,'Analisa Harga Satuan'!$A$5:$A$372,0)) -> 379396.5 | G32: =E32*F32 -> 34145685 | H32: 160 m' sloof+balok x 0,55 m
B33: Sub Total III | G33: =SUM(G28:G32) -> 1.2842809e+08
A35: IV | B35: PEKERJAAN DINDING
A36: 1 | B36: =INDEX('Analisa Harga Satuan'!$B$5:$B$372,MATCH(C36,'Analisa Harga Satuan'!$A$5:$A$372,0)) -> Pasangan dinding bata merah 1 PC : 4 PS | C36: D.1 | D36: =INDEX('Analisa Harga Satuan'!$C$5:$C$372,MATCH(C36,'Analisa Harga Satuan'!$A$5:$A$372,0)) -> m² | E36: 210 | F36: =INDEX('Analisa Harga Satuan'!$F$5:$F$372,MATCH(C36,'Analisa Harga Satuan'!$A$5:$A$372,0)) -> 216458.75 | G36: =E36*F36 -> 45456338 | H36: (74 m' x 3,2 m) - bukaan
A37: 2 | B37: =INDEX('Analisa Harga Satuan'!$B$5:$B$372,MATCH(C37,'Analisa Harga Satuan'!$A$5:$A$372,0)) -> Plesteran 1 PC : 4 PS tebal 15 mm | C37: D.2 | D37: =INDEX('Analisa Harga Satuan'!$C$5:$C$372,MATCH(C37,'Analisa Harga Satuan'!$A$5:$A$372,0)) -> m² | E37: 420 | F37: =INDEX('Analisa Harga Satuan'!$F$5:$F$372,MATCH(C37,'Analisa Harga Satuan'!$A$5:$A$372,0)) -> 113943.15 | G37: =E37*F37 -> 47856123 | H37: Dua sisi dinding
A38: 3 | B38: =INDEX('Analisa Harga Satuan'!$B$5:$B$372,MATCH(C38,'Analisa Harga Satuan'!$A$5:$A$372,0)) -> Acian | C38: D.3 | D38: =INDEX('Analisa Harga Satuan'!$C$5:$C$372,MATCH(C38,'Analisa Harga Satuan'!$A$5:$A$372,0)) -> m² | E38: 420 | F38: =INDEX('Analisa Harga Satuan'!$F$5:$F$372,MATCH(C38,'Analisa Harga Satuan'!$A$5:$A$372,0)) -> 68453.75 | G38: =E38*F38 -> 28750575 | H38: Dua sisi dinding
B39: Sub Total IV | G39: =SUM(G36:G38) -> 1.2206304e+08
A41: V | B41: PEKERJAAN ATAP & PLAFON
A42: 1 | B42: =INDEX('Analisa Harga Satuan'!$B$5:$B$372,MATCH(C42,'Analisa Harga Satuan'!$A$5:$A$372,0)) -> Rangka atap baja ringan + penutup spandek | C42: A.1 | D42: =INDEX('Analisa Harga Satuan'!$C$5:$C$372,MATCH(C42,'Analisa Harga Satuan'!$A$5:$A$372,0)) -> m² | E42: 190 | F42: =INDEX('Analisa Harga Satuan'!$F$5:$F$372,MATCH(C42,'Analisa Harga Satuan'!$A$5:$A$372,0)) -> 523422.5 | G42: =E42*F42 -> 99450275 | H42: Luas atap miring + overstek
A43: 2 | B43: =INDEX('Analisa Harga Satuan'!$B$5:$B$372,MATCH(C43,'Analisa Harga Satuan'!$A$5:$A$372,0)) -> Nok / bubungan zincalume | C43: A.2 | D43: =INDEX('Analisa Harga Satuan'!$C$5:$C$372,MATCH(C43,'Analisa Harga Satuan'!$A$5:$A$372,0)) -> m' | E43: 36 | F43: =INDEX('Analisa Harga Satuan'!$F$5:$F$372,MATCH(C43,'Analisa Harga Satuan'!$A$5:$A$372,0)) -> 120031.25 | G43: =E43*F43 -> 4321125 | H43: Nok 12 m' + rusuk 24 m'
A44: 3 | B44: =INDEX('Analisa Harga Satuan'!$B$5:$B$372,MATCH(C44,'Analisa Harga Satuan'!$A$5:$A$372,0)) -> Plafon gypsum rangka hollow | C44: A.3 | D44: =INDEX('Analisa Harga Satuan'!$C$5:$C$372,MATCH(C44,'Analisa Harga Satuan'!$A$5:$A$372,0)) -> m² | E44: 140 | F44: =INDEX('Analisa Harga Satuan'!$F$5:$F$372,MATCH(C44,'Analisa Harga Satuan'!$A$5:$A$372,0)) -> 154974 | G44: =E44*F44 -> 21696360 | H44: Plafon ruang + teras
B45: Sub Total V | G45: =SUM(G42:G44) -> 125467760
...

Sheet Analisa Harga Satuan
A1: ANALISA HARGA SATUAN PEKERJAAN (AHSP)
A2: Koefisien (biru) mengacu pola SNI/Permen PUPR - indikatif. Uraian, satuan & harga komponen otomatis dari sheet Harga Bahan/Harga Upah. Overhead & profit dari Informasi Project.
A4: Kode | B4: Uraian | C4: Satuan | D4: Koefisien | E4: Harga Satuan (Rp) | F4: Jumlah Harga (Rp) | G4: Kategori
A5: P.1 | B5: Pengukuran & pemasangan bouwplank | C5: m' | E5: Harga satuan: | F5: =F16 -> 195252.75
A6: B-11 | B6: =IF(LEFT($A6,1)="B",INDEX('Harga Bahan'!$B$5:$B$200,MATCH($A6,'Harga Bahan'!$A$5:$A$200,0)),INDEX('Harga Upah'!$B$5:$B$200,MATCH($A6,'Harga Upah'!$A$5:$A$200,0))) -> Kayu kelas III (papan bekisting/bouwplank) | C6: =IF(LEFT($A6,1)="B",INDEX('Harga Bahan'!$C$5:$C$200,MATCH($A6,'Harga Bahan'!$A$5:$A$200,0)),INDEX('Harga Upah'!$C$5:$C$200,MATCH($A6,'Harga Upah'!$A$5:$A$200,0))) -> m³ | D6: 0.012 | E6: =IF(LEFT($A6,1)="B",INDEX('Harga Bahan'!$D$5:$D$200,MATCH($A6,'Harga Bahan'!$A$5:$A$200,0)),INDEX('Harga Upah'!$D$5:$D$200,MATCH($A6,'Harga Upah'!$A$5:$A$200,0))) -> 4500000 | F6: =D6*E6 -> 54000 | G6: Bahan
A7: B-10 | B7: =IF(LEFT($A7,1)="B",INDEX('Harga Bahan'!$B$5:$B$200,MATCH($A7,'Harga Bahan'!$A$5:$A$200,0)),INDEX('Harga Upah'!$B$5:$B$200,MATCH($A7,'Harga Upah'!$A$5:$A$200,0))) -> Kayu kelas II (balok/usuk/kusen) | C7: =IF(LEFT($A7,1)="B",INDEX('Harga Bahan'!$C$5:$C$200,MATCH($A7,'Harga Bahan'!$A$5:$A$200,0)),INDEX('Harga Upah'!$C$5:$C$200,MATCH($A7,'Harga Upah'!$A$5:$A$200,0))) -> m³ | D7: 0.012 | E7: =IF(LEFT($A7,1)="B",INDEX('Harga Bahan'!$D$5:$D$200,MATCH($A7,'Harga Bahan'!$A$5:$A$200,0)),INDEX('Harga Upah'!$D$5:$D$200,MATCH($A7,'Harga Upah'!$A$5:$A$200,0))) -> 6500000 | F7: =D7*E7 -> 78000 | G7: Bahan
A8: B-13 | B8: =IF(LEFT($A8,1)="B",INDEX('Harga Bahan'!$B$5:$B$200,MATCH($A8,'Harga Bahan'!$A$5:$A$200,0)),INDEX('Harga Upah'!$B$5:$B$200,MATCH($A8,'Harga Upah'!$A$5:$A$200,0))) -> Paku campuran | C8: =IF(LEFT($A8,1)="B",INDEX('Harga Bahan'!$C$5:$C$200,MATCH($A8,'Harga Bahan'!$A$5:$A$200,0)),INDEX('Harga Upah'!$C$5:$C$200,MATCH($A8,'Harga Upah'!$A$5:$A$200,0))) -> kg | D8: 0.02 | E8: =IF(LEFT($A8,1)="B",INDEX('Harga Bahan'!$D$5:$D$200,MATCH($A8,'Harga Bahan'!$A$5:$A$200,0)),INDEX('Harga Upah'!$D$5:$D$200,MATCH($A8,'Harga Upah'!$A$5:$A$200,0))) -> 28000 | F8: =D8*E8 -> 560 | G8: Bahan
A9: U-01 | B9: =IF(LEFT($A9,1)="B",INDEX('Harga Bahan'!$B$5:$B$200,MATCH($A9,'Harga Bahan'!$A$5:$A$200,0)),INDEX('Harga Upah'!$B$5:$B$200,MATCH($A9,'Harga Upah'!$A$5:$A$200,0))) -> Pekerja | C9: =IF(LEFT($A9,1)="B",INDEX('Harga Bahan'!$C$5:$C$200,MATCH($A9,'Harga Bahan'!$A$5:$A$200,0)),INDEX('Harga Upah'!$C$5:$C$200,MATCH($A9,'Harga Upah'!$A$5:$A$200,0))) -> OH | D9: 0.1 | E9: =IF(LEFT($A9,1)="B",INDEX('Harga Bahan'!$D$5:$D$200,MATCH($A9,'Harga Bahan'!$A$5:$A$200,0)),INDEX('Harga Upah'!$D$5:$D$200,MATCH($A9,'Harga Upah'!$A$5:$A$200,0))) -> 150000 | F9: =D9*E9 -> 15000 | G9: Upah
A10: U-03 | B10: =IF(LEFT($A10,1)="B",INDEX('Harga Bahan'!$B$5:$B$200,MATCH($A10,'Harga Bahan'!$A$5:$A$200,0)),INDEX('Harga Upah'!$B$5:$B$200,MATCH($A10,'Harga Upah'!$A$5:$A$200,0))) -> Tukang kayu | C10: =IF(LEFT($A10,1)="B",INDEX('Harga Bahan'!$C$5:$C$200,MATCH($A10,'Harga Bahan'!$A$5:$A$200,0)),INDEX('Harga Upah'!$C$5:$C$200,MATCH($A10,'Harga Upah'!$A$5:$A$200,0))) -> OH | D10: 0.1 | E10: =IF(LEFT($A10,1)="B",INDEX('Harga Bahan'!$D$5:$D$200,MATCH($A10,'Harga Bahan'!$A$5:$A$200,0)),INDEX('Harga Upah'!$D$5:$D$200,MATCH($A10,'Harga Upah'!$A$5:$A$200,0))) -> 190000 | F10: =D10*E10 -> 19000 | G10: Upah
A11: U-08 | B11: =IF(LEFT($A11,1)="B",INDEX('Harga Bahan'!$B$5:$B$200,MATCH($A11,'Harga Bahan'!$A$5:$A$200,0)),INDEX('Harga Upah'!$B$5:$B$200,MATCH($A11,'Harga Upah'!$A$5:$A$200,0))) -> Kepala tukang | C11: =IF(LEFT($A11,1)="B",INDEX('Harga Bahan'!$C$5:$C$200,MATCH($A11,'Harga Bahan'!$A$5:$A$200,0)),INDEX('Harga Upah'!$C$5:$C$200,MATCH($A11,'Harga Upah'!$A$5:$A$200,0))) -> OH | D11: 0.01 | E11: =IF(LEFT($A11,1)="B",INDEX('Harga Bahan'!$D$5:$D$200,MATCH($A11,'Harga Bahan'!$A$5:$A$200,0)),INDEX('Harga Upah'!$D$5:$D$200,MATCH($A11,'Harga Upah'!$A$5:$A$200,0))) -> 210000 | F11: =D11*E11 -> 2100 | G11: Upah
A12: U-09 | B12: =IF(LEFT($A12,1)="B",INDEX('Harga Bahan'!$B$5:$B$200,MATCH($A12,'Harga Bahan'!$A$5:$A$200,0)),INDEX('Harga Upah'!$B$5:$B$200,MATCH($A12,'Harga Upah'!$A$5:$A$200,0))) -> Mandor | C12: =IF(LEFT($A12,1)="B",INDEX('Harga Bahan'!$C$5:$C$200,MATCH($A12,'Harga Bahan'!$A$5:$A$200,0)),INDEX('Harga Upah'!$C$5:$C$200,MATCH($A12,'Harga Upah'!$A$5:$A$200,0))) -> OH | D12: 0.005 | E12: =IF(LEFT($A12,1)="B",INDEX('Harga Bahan'!$D$5:$D$200,MATCH($A12,'Harga Bahan'!$A$5:$A$200,0)),INDEX('Harga Upah'!$D$5:$D$200,MATCH($A12,'Harga Upah'!$A$5:$A$200,0))) -> 225000 | F12: =D12*E12 -> 1125 | G12: Upah
B13: Jumlah harga bahan | F13: =SUMIF(G6:G12,"Bahan",F6:F12) -> 132560
B14: Jumlah harga upah | F14: =SUMIF(G6:G12,"Upah",F6:F12) -> 37225
B15: ="Overhead & profit ("&TEXT('Informasi Project'!$B$17,"0.0%")&")" -> Overhead & profit (15.0%) | F15: =(F13+F14)*'Informasi Project'!$B$17 -> 25467.75
B16: HARGA SATUAN PEKERJAAN | F16: =F13+F14+F15 -> 195252.75
A18: P.2 | B18: Pembersihan lahan & perataan | C18: m² | E18: Harga satuan: | F18: =F24 -> 9271.875
A19: U-01 | B19: =IF(LEFT($A19,1)="B",INDEX('Harga Bahan'!$B$5:$B$200,MATCH($A19,'Harga Bahan'!$A$5:$A$200,0)),INDEX('Harga Upah'!$B$5:$B$200,MATCH($A19,'Harga Upah'!$A$5:$A$200,0))) -> Pekerja | C19: =IF(LEFT($A19,1)="B",INDEX('Harga Bahan'!$C$5:$C$200,MATCH($A19,'Harga Bahan'!$A$5:$A$200,0)),INDEX('Harga Upah'!$C$5:$C$200,MATCH($A19,'Harga Upah'!$A$5:$A$200,0))) -> OH | D19: 0.05 | E19: =IF(LEFT($A19,1)="B",INDEX('Harga Bahan'!$D$5:$D$200,MATCH($A19,'Harga Bahan'!$A$5:$A$200,0)),INDEX('Harga Upah'!$D$5:$D$200,MATCH($A19,'Harga Upah'!$A$5:$A$200,0))) -> 150000 | F19: =D19*E19 -> 7500 | G19: Upah
A20: U-09 | B20: =IF(LEFT($A20,1)="B",INDEX('Harga Bahan'!$B$5:$B$200,MATCH($A20,'Harga Bahan'!$A$5:$A$200,0)),INDEX('Harga Upah'!$B$5:$B$200,MATCH($A20,'Harga Upah'!$A$5:$A$200,0))) -> Mandor | C20: =IF(LEFT($A20,1)="B",INDEX('Harga Bahan'!$C$5:$C$200,MATCH($A20,'Harga Bahan'!$A$5:$A$200,0)),INDEX('Harga Upah'!$C$5:$C$200,MATCH($A20,'Harga Upah'!$A$5:$A$200,0))) -> OH | D20: 0.0025 | E20: =IF(LEFT($A20,1)="B",INDEX('Harga Bahan'!$D$5:$D$200,MATCH($A20,'Harga Bahan'!$A$5:$A$200,0)),INDEX('Harga Upah'!$D$5:$D$200,MATCH($A20,'Harga Upah'!$A$5:$A$200,0))) -> 225000 | F20: =D20*E20 -> 562.5 | G20: Upah
B21: Jumlah harga bahan | F21: =SUMIF(G19:G20,"Bahan",F19:F20) -> 0
B22: Jumlah harga upah | F22: =SUMIF(G19:G20,"Upah",F19:F20) -> 8062.5
B23: ="Overhead & profit ("&TEXT('Informasi Project'!$B$17,"0.0%")&")" -> Overhead & profit (15.0%) | F23: =(F21+F22)*'Informasi Project'!$B$17 -> 1209.375
B24: HARGA SATUAN PEKERJAAN | F24: =F21+F22+F23 -> 9271.875
A26: T.1 | B26: Galian tanah biasa kedalaman s.d. 1 m | C26: m³ | E26: Harga satuan: | F26: =F32 -> 135843.75
A27: U-01 | B27: =IF(LEFT($A27,1)="B",INDEX('Harga Bahan'!$B$5:$B$200,MATCH($A27,'Harga Bahan'!$A$5:$A$200,0)),INDEX('Harga Upah'!$B$5:$B$200,MATCH($A27,'Harga Upah'!$A$5:$A$200,0))) -> Pekerja | C27: =IF(LEFT($A27,1)="B",INDEX('Harga Bahan'!$C$5:$C$200,MATCH($A27,'Harga Bahan'!$A$5:$A$200,0)),INDEX('Harga Upah'!$C$5:$C$200,MATCH($A27,'Harga Upah'!$A$5:$A$200,0))) -> OH | D27: 0.75 | E27: =IF(LEFT($A27,1)="B",INDEX('Harga Bahan'!$D$5:$D$200,MATCH($A27,'Harga Bahan'!$A$5:$A$200,0)),INDEX('Harga Upah'!$D$5:$D$200,MATCH($A27,'Harga Upah'!$A$5:$A$200,0))) -> 150000 | F27: =D27*E27 -> 112500 | G27: Upah
A28: U-09 | B28: =IF(LEFT($A28,1)="B",INDEX('Harga Bahan'!$B$5:$B$200,MATCH($A28,'Harga Bahan'!$A$5:$A$200,0)),INDEX('Harga Upah'!$B$5:$B$200,MATCH($A28,'Harga Upah'!$A$5:$A$200,0))) -> Mandor | C28: =IF(LEFT($A28,1)="B",INDEX('Harga Bahan'!$C$5:$C$200,MATCH($A28,'Harga Bahan'!$A$5:$A$200,0)),INDEX('Harga Upah'!$C$5:$C$200,MATCH($A28,'Harga Upah'!$A$5:$A$200,0))) -> OH | D28: 0.025 | E28: =IF(LEFT($A28,1)="B",INDEX('Harga Bahan'!$D$5:$D$200,MATCH($A28,'Harga Bahan'!$A$5:$A$200,0)),INDEX('Harga Upah'!$D$5:$D$200,MATCH($A28,'Harga Upah'!$A$5:$A$200,0))) -> 225000 | F28: =D28*E28 -> 5625 | G28: Upah
B29: Jumlah harga bahan | F29: =SUMIF(G27:G28,"Bahan",F27:F28) -> 0
B30: Jumlah harga upah | F30: =SUMIF(G27:G28,"Upah",F27:F28) -> 118125
B31: ="Overhead & profit ("&TEXT('Informasi Project'!$B$17,"0.0%")&")" -> Overhead & profit (15.0%) | F31: =(F29+F30)*'Informasi Project'!$B$17 -> 17718.75
B32: HARGA SATUAN PEKERJAAN | F32: =F29+F30+F31 -> 135843.75
A34: T.2 | B34: Urugan pasir bawah pondasi / lantai | C34: m³ | E34: Harga satuan: | F34: =F41 -> 468337.5
A35: B-02 | B35: =IF(LEFT($A35,1)="B",INDEX('Harga Bahan'!$B$5:$B$200,MATCH($A35,'Harga Bahan'!$A$5:$A$200,0)),INDEX('Harga Upah'!$B$5:$B$200,MATCH($A35,'Harga Upah'!$A$5:$A$200,0))) -> Pasir pasang | C35: =IF(LEFT($A35,1)="B",INDEX('Harga Bahan'!$C$5:$C$200,MATCH($A35,'Harga Bahan'!$A$5:$A$200,0)),INDEX('Harga Upah'!$C$5:$C$200,MATCH($A35,'Harga Upah'!$A$5:$A$200,0))) -> m³ | D35: 1.2 | E35: =IF(LEFT($A35,1)="B",INDEX('Harga Bahan'!$D$5:$D$200,MATCH($A35,'Harga Bahan'!$A$5:$A$200,0)),INDEX('Harga Upah'!$D$5:$D$200,MATCH($A35,'Harga Upah'!$A$5:$A$200,0))) -> 300000 | F35: =D35*E35 -> 360000 | G35: Bahan
A36: U-01 | B36: =IF(LEFT($A36,1)="B",INDEX('Harga Bahan'!$B$5:$B$200,MATCH($A36,'Harga Bahan'!$A$5:$A$200,0)),INDEX('Harga Upah'!$B$5:$B$200,MATCH($A36,'Harga Upah'!$A$5:$A$200,0))) -> Pekerja | C36: =IF(LEFT($A36,1)="B",INDEX('Harga Bahan'!$C$5:$C$200,MATCH($A36,'Harga Bahan'!$A$5:$A$200,0)),INDEX('Harga Upah'!$C$5:$C$200,MATCH($A36,'Harga Upah'!$A$5:$A$200,0))) -> OH | D36: 0.3 | E36: =IF(LEFT($A36,1)="B",INDEX('Harga Bahan'!$D$5:$D$200,MATCH($A36,'Harga Bahan'!$A$5:$A$200,0)),INDEX('Harga Upah'!$D$5:$D$200,MATCH($A36,'Harga Upah'!$A$5:$A$200,0))) -> 150000 | F36: =D36*E36 -> 45000 | G36: Upah
A37: U-09 | B37: =IF(LEFT($A37,1)="B",INDEX('Harga Bahan'!$B$5:$B$200,MATCH($A37,'Harga Bahan'!$A$5:$A$200,0)),INDEX('Harga Upah'!$B$5:$B$200,MATCH($A37,'Harga Upah'!$A$5:$A$200,0))) -> Mandor | C37: =IF(LEFT($A37,1)="B",INDEX('Harga Bahan'!$C$5:$C$200,MATCH($A37,'Harga Bahan'!$A$5:$A$200,0)),INDEX('Harga Upah'!$C$5:$C$200,MATCH($A37,'Harga Upah'!$A$5:$A$200,0))) -> OH | D37: 0.01 | E37: =IF(LEFT($A37,1)="B",INDEX('Harga Bahan'!$D$5:$D$200,MATCH($A37,'Harga Bahan'!$A$5:$A$200,0)),INDEX('Harga Upah'!$D$5:$D$200,MATCH($A37,'Harga Upah'!$A$5:$A$200,0))) -> 225000 | F37: =D37*E37 -> 2250 | G37: Upah
B38: Jumlah harga bahan | F38: =SUMIF(G35:G37,"Bahan",F35:F37) -> 360000
B39: Jumlah harga upah | F39: =SUMIF(G35:G37,"Upah",F35:F37) -> 47250
B40: ="Overhead & profit ("&TEXT('Informasi Project'!$B$17,"0.0%")&")" -> Overhead & profit (15.0%) | F40: =(F38+F39)*'Informasi Project'!$B$17 -> 61087.5
B41: HARGA SATUAN PEKERJAAN | F41: =F38+F39+F40 -> 468337.5
A43: T.3 | B43: Pasangan batu kosong (aanstamping) | C43: m³ | E43: Harga satuan: | F43: =F53 -> 843714.75
A44: B-06 | B44: =IF(LEFT($A44,1)="B",INDEX('Harga Bahan'!$B$5:$B$200,MATCH($A44,'Harga Bahan'!$A$5:$A$200,0)),INDEX('Harga Upah'!$B$5:$B$200,MATCH($A44,'Harga Upah'!$A$5:$A$200,0))) -> Batu kosong (aanstamping) | C44: =IF(LEFT($A44,1)="B",INDEX('Harga Bahan'!$C$5:$C$200,MATCH($A44,'Harga Bahan'!$A$5:$A$200,0)),INDEX('Harga Upah'!$C$5:$C$200,MATCH($A44,'Harga Upah'!$A$5:$A$200,0))) -> m³ | D44: 1.2 | E44: =IF(LEFT($A44,1)="B",INDEX('Harga Bahan'!$D$5:$D$200,MATCH($A44,'Harga Bahan'!$A$5:$A$200,0)),INDEX('Harga Upah'!$D$5:$D$200,MATCH($A44,'Harga Upah'!$A$5:$A$200,0))) -> 330000 | F44: =D44*E44 -> 396000 | G44: Bahan
A45: B-02 | B45: =IF(LEFT($A45,1)="B",INDEX('Harga Bahan'!$B$5:$B$200,MATCH($A45,'Harga Bahan'!$A$5:$A$200,0)),INDEX('Harga Upah'!$B$5:$B$200,MATCH($A45,'Harga Upah'!$A$5:$A$200,0))) -> Pasir pasang | C45: =IF(LEFT($A45,1)="B",INDEX('Harga Bahan'!$C$5:$C$200,MATCH($A45,'Harga Bahan'!$A$5:$A$200,0)),INDEX('Harga Upah'!$C$5:$C$200,MATCH($A45,'Harga Upah'!$A$5:$A$200,0))) -> m³ | D45: 0.432 | E45: =IF(LEFT($A45,1)="B",INDEX('Harga Bahan'!$D$5:$D$200,MATCH($A45,'Harga Bahan'!$A$5:$A$200,0)),INDEX('Harga Upah'!$D$5:$D$200,MATCH($A45,'Harga Upah'!$A$5:$A$200,0))) -> 300000 | F45: =D45*E45 -> 129600 | G45: Bahan
...

Sheet Harga Bahan
A1: DAFTAR HARGA SATUAN BAHAN - KAB. MOROWALI UTARA TA 2026
A2: Sel biru = harga input. ASUMSI INDIKATIF (bukan data resmi) - ganti dengan harga Perbup HSPK/HSD Kab. Morowali Utara TA 2026 atau survei. Boleh tambah baris (lookup sampai baris 200).
A4: Kode | B4: Uraian | C4: Satuan | D4: Harga Satuan (Rp)
A5: B-01 | B5: Semen Portland (PC) | C5: kg | D5: 1900
A6: B-02 | B6: Pasir pasang | C6: m³ | D6: 300000
A7: B-03 | B7: Pasir beton | C7: m³ | D7: 330000
A8: B-04 | B8: Batu split / kerikil 2/3 | C8: m³ | D8: 450000
A9: B-05 | B9: Batu kali belah | C9: m³ | D9: 350000
A10: B-06 | B10: Batu kosong (aanstamping) | C10: m³ | D10: 330000
A11: B-07 | B11: Batu bata merah | C11: bh | D11: 1200
A12: B-08 | B12: Besi beton polos/ulir | C12: kg | D12: 17500
A13: B-09 | B13: Kawat beton (bendrat) | C13: kg | D13: 28000
A14: B-10 | B14: Kayu kelas II (balok/usuk/kusen) | C14: m³ | D14: 6500000
A15: B-11 | B15: Kayu kelas III (papan bekisting/bouwplank) | C15: m³ | D15: 4500000
A16: B-12 | B16: Plywood 12 mm | C16: lembar | D16: 285000
... A40: B-36 | B40: Pipa conduit | C40: m' | D40: 6500

Sheet Harga Upah
A1: DAFTAR HARGA SATUAN UPAH TENAGA KERJA - KAB. MOROWALI UTARA TA 2026
A2: Sel biru = harga input. ASUMSI INDIKATIF (bukan data resmi) - ganti dengan harga Perbup HSPK/HSD Kab. Morowali Utara TA 2026 atau survei. Boleh tambah baris (lookup sampai baris 200).
A4: Kode | B4: Uraian | C4: Satuan | D4: Harga Satuan (Rp)
A5: U-01 | B5: Pekerja | C5: OH | D5: 150000
A6: U-02 | B6: Tukang batu | C6: OH | D6: 190000
A7: U-03 | B7: Tukang kayu | C7: OH | D7: 190000
A8: U-04 | B8: Tukang besi | C8: OH | D8: 190000
A9: U-05 | B9: Tukang cat | C9: OH | D9: 190000
A10: U-06 | B10: Tukang listrik | C10: OH | D10: 200000
A11: U-07 | B11: Tukang pipa | C11: OH | D11: 190000
A12: U-08 | B12: Kepala tukang | C12: OH | D12: 210000
A13: U-09 | B13: Mandor | C13: OH | D13: 225000
A14: U-10 | B14: Tukang pasang atap / rangka baja ringan | C14: OH | D14: 200000

Sheet Schedule
A1: JADWAL PELAKSANAAN & KURVA S
A2: Mulai & Selesai (minggu ke-, biru) = input. Bobot mingguan = bobot divisi dibagi rata pada minggu aktif. Bobot dari Rekap RAB.
A4: No | B4: Uraian Pekerjaan | C4: Bobot (%) | D4: Mulai (Mgg) | E4: Selesai (Mgg) | F4: Durasi (Mgg) | G4: M1 | H4: M2 | I4: M3 | J4: M4 | K4: M5 | L4: M6 | M4: M7 | N4: M8 | O4: M9 | P4: M10 | Q4: M11 | R4: M12 | S4: M13 | T4: M14 | U4: M15 | V4: M16 | W4: M17 | X4: M18 | Y4: M19 | Z4: M20 | AA4: M21 | AB4: M22 | AC4: M23 | AD4: M24
A5: I | B5: PEKERJAAN PERSIAPAN | C5: ='Rekap RAB'!D7 -> 0.059091738 | D5: 1 | E5: 2 | F5: =E5-D5+1 -> 2 | G5: =IF(AND(1>=$D5,1<=$E5),$C5/$F5,0) -> 0.029545869 | H5: =IF(AND(2>=$D5,2<=$E5),$C5/$F5,0) -> 0.029545869 | I5: =IF(AND(3>=$D5,3<=$E5),$C5/$F5,0) -> 0 | J5: =IF(AND(4>=$D5,4<=$E5),$C5/$F5,0) -> 0 | K5: =IF(AND(5>=$D5,5<=$E5),$C5/$F5,0) -> 0 | L5: =IF(AND(6>=$D5,6<=$E5),$C5/$F5,0) -> 0 | M5: =IF(AND(7>=$D5,7<=$E5),$C5/$F5,0) -> 0 | N5: =IF(AND(8>=$D5,8<=$E5),$C5/$F5,0) -> 0 | O5: =IF(AND(9>=$D5,9<=$E5),$C5/$F5,0) -> 0 | P5: =IF(AND(10>=$D5,10<=$E5),$C5/$F5,0) -> 0 | Q5: =IF(AND(11>=$D5,11<=$E5),$C5/$F5,0) -> 0 | R5: =IF(AND(12>=$D5,12<=$E5),$C5/$F5,0) -> 0 | S5: =IF(AND(13>=$D5,13<=$E5),$C5/$F5,0) -> 0 | T5: =IF(AND(14>=$D5,14<=$E5),$C5/$F5,0) -> 0 | U5: =IF(AND(15>=$D5,15<=$E5),$C5/$F5,0) -> 0 | V5: =IF(AND(16>=$D5,16<=$E5),$C5/$F5,0) -> 0 | W5: =IF(AND(17>=$D5,17<=$E5),$C5/$F5,0) -> 0 | X5: =IF(AND(18>=$D5,18<=$E5),$C5/$F5,0) -> 0 | Y5: =IF(AND(19>=$D5,19<=$E5),$C5/$F5,0) -> 0 | Z5: =IF(AND(20>=$D5,20<=$E5),$C5/$F5,0) -> 0 | AA5: =IF(AND(21>=$D5,21<=$E5),$C5/$F5,0) -> 0 | AB5: =IF(AND(22>=$D5,22<=$E5),$C5/$F5,0) -> 0 | AC5: =IF(AND(23>=$D5,23<=$E5),$C5/$F5,0) -> 0 | AD5: =IF(AND(24>=$D5,24<=$E5),$C5/$F5,0) -> 0
A6: II | B6: PEKERJAAN TANAH & PONDASI | C6: ='Rekap RAB'!D8 -> 0.10762604 | D6: 2 | E6: 5 | F6: =E6-D6+1 -> 4 | G6: =IF(AND(1>=$D6,1<=$E6),$C6/$F6,0) -> 0 | H6: =IF(AND(2>=$D6,2<=$E6),$C6/$F6,0) -> 0.026906509 | I6: =IF(AND(3>=$D6,3<=$E6),$C6/$F6,0) -> 0.026906509 | J6: =IF(AND(4>=$D6,4<=$E6),$C6/$F6,0) -> 0.026906509 | K6: =IF(AND(5>=$D6,5<=$E6),$C6/$F6,0) -> 0.026906509 | L6: =IF(AND(6>=$D6,6<=$E6),$C6/$F6,0) -> 0 | M6: =IF(AND(7>=$D6,7<=$E6),$C6/$F6,0) -> 0 | N6: =IF(AND(8>=$D6,8<=$E6),$C6/$F6,0) -> 0 | O6: =IF(AND(9>=$D6,9<=$E6),$C6/$F6,0) -> 0 | P6: =IF(AND(10>=$D6,10<=$E6),$C6/$F6,0) -> 0 | Q6: =IF(AND(11>=$D6,11<=$E6),$C6/$F6,0) -> 0 | R6: =IF(AND(12>=$D6,12<=$E6),$C6/$F6,0) -> 0 | S6: =IF(AND(13>=$D6,13<=$E6),$C6/$F6,0) -> 0 | T6: =IF(AND(14>=$D6,14<=$E6),$C6/$F6,0) -> 0 | U6: =IF(AND(15>=$D6,15<=$E6),$C6/$F6,0) -> 0 | V6: =IF(AND(16>=$D6,16<=$E6),$C6/$F6,0) -> 0 | W6: =IF(AND(17>=$D6,17<=$E6),$C6/$F6,0) -> 0 | X6: =IF(AND(18>=$D6,18<=$E6),$C6/$F6,0) -> 0 | Y6: =IF(AND(19>=$D6,19<=$E6),$C6/$F6,0) -> 0 | Z6: =IF(AND(20>=$D6,20<=$E6),$C6/$F6,0) -> 0 | AA6: =IF(AND(21>=$D6,21<=$E6),$C6/$F6,0) -> 0 | AB6: =IF(AND(22>=$D6,22<=$E6),$C6/$F6,0) -> 0 | AC6: =IF(AND(23>=$D6,23<=$E6),$C6/$F6,0) -> 0 | AD6: =IF(AND(24>=$D6,24<=$E6),$C6/$F6,0) -> 0
A7: III | B7: PEKERJAAN STRUKTUR BETON | C7: ='Rekap RAB'!D9 -> 0.20033929 | D7: 4 | E7: 10 | F7: =E7-D7+1 -> 7 | G7: =IF(AND(1>=$D7,1<=$E7),$C7/$F7,0) -> 0 | H7: =IF(AND(2>=$D7,2<=$E7),$C7/$F7,0) -> 0 | I7: =IF(AND(3>=$D7,3<=$E7),$C7/$F7,0) -> 0 | J7: =IF(AND(4>=$D7,4<=$E7),$C7/$F7,0) -> 0.028619898 | K7: =IF(AND(5>=$D7,5<=$E7),$C7/$F7,0) -> 0.028619898 | L7: =IF(AND(6>=$D7,6<=$E7),$C7/$F7,0) -> 0.028619898 | M7: =IF(AND(7>=$D7,7<=$E7),$C7/$F7,0) -> 0.028619898 | N7: =IF(AND(8>=$D7,8<=$E7),$C7/$F7,0) -> 0.028619898 | O7: =IF(AND(9>=$D7,9<=$E7),$C7/$F7,0) -> 0.028619898 | P7: =IF(AND(10>=$D7,10<=$E7),$C7/$F7,0) -> 0.028619898 | Q7: =IF(AND(11>=$D7,11<=$E7),$C7/$F7,0) -> 0 | R7: =IF(AND(12>=$D7,12<=$E7),$C7/$F7,0) -> 0 | S7: =IF(AND(13>=$D7,13<=$E7),$C7/$F7,0) -> 0 | T7: =IF(AND(14>=$D7,14<=$E7),$C7/$F7,0) -> 0 | U7: =IF(AND(15>=$D7,15<=$E7),$C7/$F7,0) -> 0 | V7: =IF(AND(16>=$D7,16<=$E7),$C7/$F7,0) -> 0 | W7: =IF(AND(17>=$D7,17<=$E7),$C7/$F7,0) -> 0 | X7: =IF(AND(18>=$D7,18<=$E7),$C7/$F7,0) -> 0 | Y7: =IF(AND(19>=$D7,19<=$E7),$C7/$F7,0) -> 0 | Z7: =IF(AND(20>=$D7,20<=$E7),$C7/$F7,0) -> 0 | AA7: =IF(AND(21>=$D7,21<=$E7),$C7/$F7,0) -> 0 | AB7: =IF(AND(22>=$D7,22<=$E7),$C7/$F7,0) -> 0 | AC7: =IF(AND(23>=$D7,23<=$E7),$C7/$F7,0) -> 0 | AD7: =IF(AND(24>=$D7,24<=$E7),$C7/$F7,0) -> 0
A8: IV | B8: PEKERJAAN DINDING | C8: ='Rekap RAB'!D10 -> 0.19041022 | D8: 9 | E8: 14 | F8: =E8-D8+1 -> 6 | G8: =IF(AND(1>=$D8,1<=$E8),$C8/$F8,0) -> 0 | H8: =IF(AND(2>=$D8,2<=$E8),$C8/$F8,0) -> 0 | I8: =IF(AND(3>=$D8,3<=$E8),$C8/$F8,0) -> 0 | J8: =IF(AND(4>=$D8,4<=$E8),$C8/$F8,0) -> 0 | K8: =IF(AND(5>=$D8,5<=$E8),$C8/$F8,0) -> 0 | L8: =IF(AND(6>=$D8,6<=$E8),$C8/$F8,0) -> 0 | M8: =IF(AND(7>=$D8,7<=$E8),$C8/$F8,0) -> 0 | N8: =IF(AND(8>=$D8,8<=$E8),$C8/$F8,0) -> 0 | O8: =IF(AND(9>=$D8,9<=$E8),$C8/$F8,0) -> 0.031735037 | P8: =IF(AND(10>=$D8,10<=$E8),$C8/$F8,0) -> 0.031735037 | Q8: =IF(AND(11>=$D8,11<=$E8),$C8/$F8,0) -> 0.031735037 | R8: =IF(AND(12>=$D8,12<=$E8),$C8/$F8,0) -> 0.031735037 | S8: =IF(AND(13>=$D8,13<=$E8),$C8/$F8,0) -> 0.031735037 | T8: =IF(AND(14>=$D8,14<=$E8),$C8/$F8,0) -> 0.031735037 | U8: =IF(AND(15>=$D8,15<=$E8),$C8/$F8,0) -> 0 | V8: =IF(AND(16>=$D8,16<=$E8),$C8/$F8,0) -> 0 | W8: =IF(AND(17>=$D8,17<=$E8),$C8/$F8,0) -> 0 | X8: =IF(AND(18>=$D8,18<=$E8),$C8/$F8,0) -> 0 | Y8: =IF(AND(19>=$D8,19<=$E8),$C8/$F8,0) -> 0 | Z8: =IF(AND(20>=$D8,20<=$E8),$C8/$F8,0) -> 0 | AA8: =IF(AND(21>=$D8,21<=$E8),$C8/$F8,0) -> 0 | AB8: =IF(AND(22>=$D8,22<=$E8),$C8/$F8,0) -> 0 | AC8: =IF(AND(23>=$D8,23<=$E8),$C8/$F8,0) -> 0 | AD8: =IF(AND(24>=$D8,24<=$E8),$C8/$F8,0) -> 0
A9: V | B9: PEKERJAAN ATAP & PLAFON | C9: ='Rekap RAB'!D11 -> 0.19572136 | D9: 12 | E9: 18 | F9: =E9-D9+1 -> 7 | G9: =IF(AND(1>=$D9,1<=$E9),$C9/$F9,0) -> 0 | H9: =IF(AND(2>=$D9,2<=$E9),$C9/$F9,0) -> 0 | I9: =IF(AND(3>=$D9,3<=$E9),$C9/$F9,0) -> 0 | J9: =IF(AND(4>=$D9,4<=$E9),$C9/$F9,0) -> 0 | K9: =IF(AND(5>=$D9,5<=$E9),$C9/$F9,0) -> 0 | L9: =IF(AND(6>=$D9,6<=$E9),$C9/$F9,0) -> 0 | M9: =IF(AND(7>=$D9,7<=$E9),$C9/$F9,0) -> 0 | N9: =IF(AND(8>=$D9,8<=$E9),$C9/$F9,0) -> 0 | O9: =IF(AND(9>=$D9,9<=$E9),$C9/$F9,0) -> 0 | P9: =IF(AND(10>=$D9,10<=$E9),$C9/$F9,0) -> 0 | Q9: =IF(AND(11>=$D9,11<=$E9),$C9/$F9,0) -> 0 | R9: =IF(AND(12>=$D9,12<=$E9),$C9/$F9,0) -> 0.027960195 | S9: =IF(AND(13>=$D9,13<=$E9),$C9/$F9,0) -> 0.027960195 | T9: =IF(AND(14>=$D9,14<=$E9),$C9/$F9,0) -> 0.027960195 | U9: =IF(AND(15>=$D9,15<=$E9),$C9/$F9,0) -> 0.027960195 | V9: =IF(AND(16>=$D9,16<=$E9),$C9/$F9,0) -> 0.027960195 | W9: =IF(AND(17>=$D9,17<=$E9),$C9/$F9,0) -> 0.027960195 | X9: =IF(AND(18>=$D9,18<=$E9),$C9/$F9,0) -> 0.027960195 | Y9: =IF(AND(19>=$D9,19<=$E9),$C9/$F9,0) -> 0 | Z9: =IF(AND(20>=$D9,20<=$E9),$C9/$F9,0) -> 0 | AA9: =IF(AND(21>=$D9,21<=$E9),$C9/$F9,0) -> 0 | AB9: =IF(AND(22>=$D9,22<=$E9),$C9/$F9,0) -> 0 | AC9: =IF(AND(23>=$D9,23<=$E9),$C9/$F9,0) -> 0 | AD9: =IF(AND(24>=$D9,24<=$E9),$C9/$F9,0) -> 0
A10: VI | B10: PEKERJAAN LANTAI & KERAMIK | C10: ='Rekap RAB'!D12 -> 0.084409215 | D10: 15 | E10: 19 | F10: =E10-D10+1 -> 5 | G10: =IF(AND(1>=$D10,1<=$E10),$C10/$F10,0) -> 0 | H10: =IF(AND(2>=$D10,2<=$E10),$C10/$F10,0) -> 0 | I10: =IF(AND(3>=$D10,3<=$E10),$C10/$F10,0) -> 0 | J10: =IF(AND(4>=$D10,4<=$E10),$C10/$F10,0) -> 0 | K10: =IF(AND(5>=$D10,5<=$E10),$C10/$F10,0) -> 0 | L10: =IF(AND(6>=$D10,6<=$E10),$C10/$F10,0) -> 0 | M10: =IF(AND(7>=$D10,7<=$E10),$C10/$F10,0) -> 0 | N10: =IF(AND(8>=$D10,8<=$E10),$C10/$F10,0) -> 0 | O10: =IF(AND(9>=$D10,9<=$E10),$C10/$F10,0) -> 0 | P10: =IF(AND(10>=$D10,10<=$E10),$C10/$F10,0) -> 0 | Q10: =IF(AND(11>=$D10,11<=$E10),$C10/$F10,0) -> 0 | R10: =IF(AND(12>=$D10,12<=$E10),$C10/$F10,0) -> 0 | S10: =IF(AND(13>=$D10,13<=$E10),$C10/$F10,0) -> 0 | T10: =IF(AND(14>=$D10,14<=$E10),$C10/$F10,0) -> 0 | U10: =IF(AND(15>=$D10,15<=$E10),$C10/$F10,0) -> 0.016881843 | V10: =IF(AND(16>=$D10,16<=$E10),$C10/$F10,0) -> 0.016881843 | W10: =IF(AND(17>=$D10,17<=$E10),$C10/$F10,0) -> 0.016881843 | X10: =IF(AND(18>=$D10,18<=$E10),$C10/$F10,0) -> 0.016881843 | Y10: =IF(AND(19>=$D10,19<=$E10),$C10/$F10,0) -> 0.016881843 | Z10: =IF(AND(20>=$D10,20<=$E10),$C10/$F10,0) -> 0 | AA10: =IF(AND(21>=$D10,21<=$E10),$C10/$F10,0) -> 0 | AB10: =IF(AND(22>=$D10,22<=$E10),$C10/$F10,0) -> 0 | AC10: =IF(AND(23>=$D10,23<=$E10),$C10/$F10,0) -> 0 | AD10: =IF(AND(24>=$D10,24<=$E10),$C10/$F10,0) -> 0
A11: VII | B11: PEKERJAAN KUSEN, PINTU & JENDELA | C11: ='Rekap RAB'!D13 -> 0.059542834 | D11: 13 | E11: 17 | F11: =E11-D11+1 -> 5 | G11: =IF(AND(1>=$D11,1<=$E11),$C11/$F11,0) -> 0 | H11: =IF(AND(2>=$D11,2<=$E11),$C11/$F11,0) -> 0 | I11: =IF(AND(3>=$D11,3<=$E11),$C11/$F11,0) -> 0 | J11: =IF(AND(4>=$D11,4<=$E11),$C11/$F11,0) -> 0 | K11: =IF(AND(5>=$D11,5<=$E11),$C11/$F11,0) -> 0 | L11: =IF(AND(6>=$D11,6<=$E11),$C11/$F11,0) -> 0 | M11: =IF(AND(7>=$D11,7<=$E11),$C11/$F11,0) -> 0 | N11: =IF(AND(8>=$D11,8<=$E11),$C11/$F11,0) -> 0 | O11: =IF(AND(9>=$D11,9<=$E11),$C11/$F11,0) -> 0 | P11: =IF(AND(10>=$D11,10<=$E11),$C11/$F11,0) -> 0 | Q11: =IF(AND(11>=$D11,11<=$E11),$C11/$F11,0) -> 0 | R11: =IF(AND(12>=$D11,12<=$E11),$C11/$F11,0) -> 0 | S11: =IF(AND(13>=$D11,13<=$E11),$C11/$F11,0) -> 0.011908567 | T11: =IF(AND(14>=$D11,14<=$E11),$C11/$F11,0) -> 0.011908567 | U11: =IF(AND(15>=$D11,15<=$E11),$C11/$F11,0) -> 0.011908567 | V11: =IF(AND(16>=$D11,16<=$E11),$C11/$F11,0) -> 0.011908567 | W11: =IF(AND(17>=$D11,17<=$E11),$C11/$F11,0) -> 0.011908567 | X11: =IF(AND(18>=$D11,18<=$E11),$C11/$F11,0) -> 0 | Y11: =IF(AND(19>=$D11,19<=$E11),$C11/$F11,0) -> 0 | Z11: =IF(AND(20>=$D11,20<=$E11),$C11/$F11,0) -> 0 | AA11: =IF(AND(21>=$D11,21<=$E11),$C11/$F11,0) -> 0 | AB11: =IF(AND(22>=$D11,22<=$E11),$C11/$F11,0) -> 0 | AC11: =IF(AND(23>=$D11,23<=$E11),$C11/$F11,0) -> 0 | AD11: =IF(AND(24>=$D11,24<=$E11),$C11/$F11,0) -> 0
A12: VIII | B12: PEKERJAAN FINISHING | C12: ='Rekap RAB'!D14 -> 0.038983394 | D12: 17 | E12: 21 | F12: =E12-D12+1 -> 5 | G12: =IF(AND(1>=$D12,1<=$E12),$C12/$F12,0) -> 0 | H12: =IF(AND(2>=$D12,2<=$E12),$C12/$F12,0) -> 0 | I12: =IF(AND(3>=$D12,3<=$E12),$C12/$F12,0) -> 0 | J12: =IF(AND(4>=$D12,4<=$E12),$C12/$F12,0) -> 0 | K12: =IF(AND(5>=$D12,5<=$E12),$C12/$F12,0) -> 0 | L12: =IF(AND(6>=$D12,6<=$E12),$C12/$F12,0) -> 0 | M12: =IF(AND(7>=$D12,7<=$E12),$C12/$F12,0) -> 0 | N12: =IF(AND(8>=$D12,8<=$E12),$C12/$F12,0) -> 0 | O12: =IF(AND(9>=$D12,9<=$E12),$C12/$F12,0) -> 0 | P12: =IF(AND(10>=$D12,10<=$E12),$C12/$F12,0) -> 0 | Q12: =IF(AND(11>=$D12,11<=$E12),$C12/$F12,0) -> 0 | R12: =IF(AND(12>=$D12,12<=$E12),$C12/$F12,0) -> 0 | S12: =IF(AND(13>=$D12,13<=$E12),$C12/$F12,0) -> 0 | T12: =IF(AND(14>=$D12,14<=$E12),$C12/$F12,0) -> 0 | U12: =IF(AND(15>=$D12,15<=$E12),$C12/$F12,0) -> 0 | V12: =IF(AND(16>=$D12,16<=$E12),$C12/$F12,0) -> 0 | W12: =IF(AND(17>=$D12,17<=$E12),$C12/$F12,0) -> 0.0077966788 | X12: =IF(AND(18>=$D12,18<=$E12),$C12/$F12,0) -> 0.0077966788 | Y12: =IF(AND(19>=$D12,19<=$E12),$C12/$F12,0) -> 0.0077966788 | Z12: =IF(AND(20>=$D12,20<=$E12),$C12/$F12,0) -> 0.0077966788 | AA12: =IF(AND(21>=$D12,21<=$E12),$C12/$F12,0) -> 0.0077966788 | AB12: =IF(AND(22>=$D12,22<=$E12),$C12/$F12,0) -> 0 | AC12: =IF(AND(23>=$D12,23<=$E12),$C12/$F12,0) -> 0 | AD12: =IF(AND(24>=$D12,24<=$E12),$C12/$F12,0) -> 0
A13: IX | B13: PEKERJAAN SANITASI & AIR | C13: ='Rekap RAB'!D15 -> 0.034780886 | D13: 14 | E13: 19 | F13: =E13-D13+1 -> 6 | G13: =IF(AND(1>=$D13,1<=$E13),$C13/$F13,0) -> 0 | H13: =IF(AND(2>=$D13,2<=$E13),$C13/$F13,0) -> 0 | I13: =IF(AND(3>=$D13,3<=$E13),$C13/$F13,0) -> 0 | J13: =IF(AND(4>=$D13,4<=$E13),$C13/$F13,0) -> 0 | K13: =IF(AND(5>=$D13,5<=$E13),$C13/$F13,0) -> 0 | L13: =IF(AND(6>=$D13,6<=$E13),$C13/$F13,0) -> 0 | M13: =IF(AND(7>=$D13,7<=$E13),$C13/$F13,0) -> 0 | N13: =IF(AND(8>=$D13,8<=$E13),$C13/$F13,0) -> 0 | O13: =IF(AND(9>=$D13,9<=$E13),$C13/$F13,0) -> 0 | P13: =IF(AND(10>=$D13,10<=$E13),$C13/$F13,0) -> 0 | Q13: =IF(AND(11>=$D13,11<=$E13),$C13/$F13,0) -> 0 | R13: =IF(AND(12>=$D13,12<=$E13),$C13/$F13,0) -> 0 | S13: =IF(AND(13>=$D13,13<=$E13),$C13/$F13,0) -> 0 | T13: =IF(AND(14>=$D13,14<=$E13),$C13/$F13,0) -> 0.0057968143 | U13: =IF(AND(15>=$D13,15<=$E13),$C13/$F13,0) -> 0.0057968143 | V13: =IF(AND(16>=$D13,16<=$E13),$C13/$F13,0) -> 0.0057968143 | W13: =IF(AND(17>=$D13,17<=$E13),$C13/$F13,0) -> 0.0057968143 | X13: =IF(AND(18>=$D13,18<=$E13),$C13/$F13,0) -> 0.0057968143 | Y13: =IF(AND(19>=$D13,19<=$E13),$C13/$F13,0) -> 0.0057968143 | Z13: =IF(AND(20>=$D13,20<=$E13),$C13/$F13,0) -> 0 | AA13: =IF(AND(21>=$D13,21<=$E13),$C13/$F13,0) -> 0 | AB13: =IF(AND(22>=$D13,22<=$E13),$C13/$F13,0) -> 0 | AC13: =IF(AND(23>=$D13,23<=$E13),$C13/$F13,0) -> 0 | AD13: =IF(AND(24>=$D13,24<=$E13),$C13/$F13,0) -> 0
A14: X | B14: PEKERJAAN INSTALASI LISTRIK | C14: ='Rekap RAB'!D16 -> 0.026925498 | D14: 15 | E14: 20 | F14: =E14-D14+1 -> 6 | G14: =IF(AND(1>=$D14,1<=$E14),$C14/$F14,0) -> 0 | H14: =IF(AND(2>=$D14,2<=$E14),$C14/$F14,0) -> 0 | I14: =IF(AND(3>=$D14,3<=$E14),$C14/$F14,0) -> 0 | J14: =IF(AND(4>=$D14,4<=$E14),$C14/$F14,0) -> 0 | K14: =IF(AND(5>=$D14,5<=$E14),$C14/$F14,0) -> 0 | L14: =IF(AND(6>=$D14,6<=$E14),$C14/$F14,0) -> 0 | M14: =IF(AND(7>=$D14,7<=$E14),$C14/$F14,0) -> 0 | N14: =IF(AND(8>=$D14,8<=$E14),$C14/$F14,0) -> 0 | O14: =IF(AND(9>=$D14,9<=$E14),$C14/$F14,0) -> 0 | P14: =IF(AND(10>=$D14,10<=$E14),$C14/$F14,0) -> 0 | Q14: =IF(AND(11>=$D14,11<=$E14),$C14/$F14,0) -> 0 | R14: =IF(AND(12>=$D14,12<=$E14),$C14/$F14,0) -> 0 | S14: =IF(AND(13>=$D14,13<=$E14),$C14/$F14,0) -> 0 | T14: =IF(AND(14>=$D14,14<=$E14),$C14/$F14,0) -> 0 | U14: =IF(AND(15>=$D14,15<=$E14),$C14/$F14,0) -> 0.0044875829 | V14: =IF(AND(16>=$D14,16<=$E14),$C14/$F14,0) -> 0.0044875829 | W14: =IF(AND(17>=$D14,17<=$E14),$C14/$F14,0) -> 0.0044875829 | X14: =IF(AND(18>=$D14,18<=$E14),$C14/$F14,0) -> 0.0044875829 | Y14: =IF(AND(19>=$D14,19<=$E14),$C14/$F14,0) -> 0.0044875829 | Z14: =IF(AND(20>=$D14,20<=$E14),$C14/$F14,0) -> 0.0044875829 | AA14: =IF(AND(21>=$D14,21<=$E14),$C14/$F14,0) -> 0 | AB14: =IF(AND(22>=$D14,22<=$E14),$C14/$F14,0) -> 0 | AC14: =IF(AND(23>=$D14,23<=$E14),$C14/$F14,0) -> 0 | AD14: =IF(AND(24>=$D14,24<=$E14),$C14/$F14,0) -> 0
A15: XI | B15: PEKERJAAN AKHIR | C15: ='Rekap RAB'!D17 -> 0.0021695263 | D15: 21 | E15: 22 | F15: =E15-D15+1 -> 2 | G15: =IF(AND(1>=$D15,1<=$E15),$C15/$F15,0) -> 0 | H15: =IF(AND(2>=$D15,2<=$E15),$C15/$F15,0) -> 0 | I15: =IF(AND(3>=$D15,3<=$E15),$C15/$F15,0) -> 0 | J15: =IF(AND(4>=$D15,4<=$E15),$C15/$F15,0) -> 0 | K15: =IF(AND(5>=$D15,5<=$E15),$C15/$F15,0) -> 0 | L15: =IF(AND(6>=$D15,6<=$E15),$C15/$F15,0) -> 0 | M15: =IF(AND(7>=$D15,7<=$E15),$C15/$F15,0) -> 0 | N15: =IF(AND(8>=$D15,8<=$E15),$C15/$F15,0) -> 0 | O15: =IF(AND(9>=$D15,9<=$E15),$C15/$F15,0) -> 0 | P15: =IF(AND(10>=$D15,10<=$E15),$C15/$F15,0) -> 0 | Q15: =IF(AND(11>=$D15,11<=$E15),$C15/$F15,0) -> 0 | R15: =IF(AND(12>=$D15,12<=$E15),$C15/$F15,0) -> 0 | S15: =IF(AND(13>=$D15,13<=$E15),$C15/$F15,0) -> 0 | T15: =IF(AND(14>=$D15,14<=$E15),$C15/$F15,0) -> 0 | U15: =IF(AND(15>=$D15,15<=$E15),$C15/$F15,0) -> 0 | V15: =IF(AND(16>=$D15,16<=$E15),$C15/$F15,0) -> 0 | W15: =IF(AND(17>=$D15,17<=$E15),$C15/$F15,0) -> 0 | X15: =IF(AND(18>=$D15,18<=$E15),$C15/$F15,0) -> 0 | Y15: =IF(AND(19>=$D15,19<=$E15),$C15/$F15,0) -> 0 | Z15: =IF(AND(20>=$D15,20<=$E15),$C15/$F15,0) -> 0 | AA15: =IF(AND(21>=$D15,21<=$E15),$C15/$F15,0) -> 0.0010847631 | AB15: =IF(AND(22>=$D15,22<=$E15),$C15/$F15,0) -> 0.0010847631 | AC15: =IF(AND(23>=$D15,23<=$E15),$C15/$F15,0) -> 0 | AD15: =IF(AND(24>=$D15,24<=$E15),$C15/$F15,0) -> 0
B16: RENCANA PROGRES MINGGUAN | C16: =SUM(C5:C15) -> 1 | G16: =SUM(G5:G15) -> 0.029545869 | H16: =SUM(H5:H15) -> 0.056452378 | I16: =SUM(I5:I15) -> 0.026906509 | J16: =SUM(J5:J15) -> 0.055526408 | K16: =SUM(K5:K15) -> 0.055526408 | L16: =SUM(L5:L15) -> 0.028619898 | M16: =SUM(M5:M15) -> 0.028619898 | N16: =SUM(N5:N15) -> 0.028619898 | ... AD16: =SUM(AD5:AD15) -> 0
B17: RENCANA PROGRES KUMULATIF (KURVA S) | G17: =G16 -> 0.029545869 | H17: =G17+H16 -> 0.085998247 | I17: =H17+I16 -> 0.11290476 | J17: =I17+J16 -> 0.16843116 | K17: =J17+K16 -> 0.22395757 | L17: =K17+L16 -> 0.25257747 | M17: =L17+M16 -> 0.28119737 | N17: =M17+N16 -> 0.30981727 | O17: =N17+O16 -> 0.3701722 | ... AD17: =AC17+AD16 -> 1
B18: Cek: kumulatif akhir harus 100% | C18: =AD17 -> 1 | D18: =IF(ROUND(AD17,6)=1,"OK","CEK") -> OK
B19: Tanggal akhir minggu (rencana) | G19: ='Informasi Project'!$B$20+1*7-1 -> 46033 | H19: ='Informasi Project'!$B$20+2*7-1 -> 46040 | I19: ='Informasi Project'!$B$20+3*7-1 -> 46047 | J19: ='Informasi Project'!$B$20+4*7-1 -> 46054 | K19: ='Informasi Project'!$B$20+5*7-1 -> 46061 | L19: ='Informasi Project'!$B$20+6*7-1 -> 46068 | M19: ='Informasi Project'!$B$20+7*7-1 -> 46075 | N19: ='Informasi Project'!$B$20+8*7-1 -> 46082 | O19: ='Informasi Project'!$B$20+9*7-1 -> 46089 | P19: ='Informasi Project'!$B$20+10*7-1 -> 46096 | Q19: ='Informasi Project'!$B$20+11*7-1 -> 46103 | R19: ='Informasi Project'!$B$20+12*7-1 -> 46110 | S19: ='Informasi Project'!$B$20+13*7-1 -> 46117 | T19: ='Informasi Project'!$B$20+14*7-1 -> 46124 | U19: ='Informasi Project'!$B$20+15*7-1 -> 46131 | V19: ='Informasi Project'!$B$20+16*7-1 -> 46138 | W19: ='Informasi Project'!$B$20+17*7-1 -> 46145 | X19: ='Informasi Project'!$B$20+18*7-1 -> 46152 | Y19: ='Informasi Project'!$B$20+19*7-1 -> 46159 | Z19: ='Informasi Project'!$B$20+20*7-1 -> 46166 | AA19: ='Informasi Project'!$B$20+21*7-1 -> 46173 | AB19: ='Informasi Project'!$B$20+22*7-1 -> 46180 | AC19: ='Informasi Project'!$B$20+23*7-1 -> 46187 | AD19: ='Informasi Project'!$B$20+24*7-1 -> 46194
