Workbook

Sheet Informasi Project
A1: RENCANA ANGGARAN BIAYA (RAB)
A2: Sheet ini adalah pusat input. Sel BIRU = diisi/diubah pengguna; sel hitam = rumus. Seluruh data di bawah adalah CONTOH — ganti sesuai proyek.
A4: Nama Proyek | B4: Pembangunan Rumah Tinggal Tipe 36
A5: Lokasi Proyek | B5: Jl. Contoh No. 1, Kota Contoh
A6: Pemilik / Owner | B6: Bapak/Ibu Contoh
A7: Project Manager | B7: (isi nama PM)
A8: Konsultan Perencana | B8: (isi nama konsultan)
A9: Kontraktor Pelaksana | B9: (isi nama kontraktor)
A10: Jenis Pekerjaan | B10: Gedung / Bangunan Rumah Tinggal 1 Lantai
A11: Tahun Anggaran | B11: 2026
A12: Tanggal Penyusunan | B12: 2026-10-15
A13: Luas Bangunan (m²) | B13: 36
A14: Durasi Pelaksanaan (hari kalender) | B14: 90
A15: Sumber Dana | B15: Pribadi / Swadana
A16: Overhead & Profit (%) | B16: 0.15
A17: PPN (%) | B17: 0.11
A18: Pembulatan ke kelipatan (Rp) | B18: 1000
A21: CATATAN & ASUMSI
A22: 1. Koefisien analisa (AHSP) bersifat indikatif mengacu pola SNI/Permen PUPR; verifikasi dengan standar & kondisi lapangan proyek.
A23: 2. Harga bahan & upah adalah asumsi contoh (Rp, estimasi 2026) — WAJIB diganti dengan harga survei/pasar lokasi proyek.
A24: 3. Overhead & Profit (kuning) ditambahkan di atas jumlah bahan + upah pada setiap analisa harga satuan.
A25: 4. Alur data: Harga Bahan & Harga Upah -> Analisa Harga Satuan -> Rekap RAB (volume diinput di Rekap RAB).
A26: 5. Volume pekerjaan pada Rekap RAB adalah contoh; ganti dengan hasil perhitungan quantity take-off dari gambar kerja.

Sheet Rekap RAB
A1: REKAPITULASI RENCANA ANGGARAN BIAYA
A2: ="Proyek: "&'Informasi Project'!B4 -> Proyek: Pembangunan Rumah Tinggal Tipe 36
A3: ="Lokasi: "&'Informasi Project'!B5 -> Lokasi: Jl. Contoh No. 1, Kota Contoh
A5: No | B5: Uraian Pekerjaan | C5: Kode AHSP | D5: Satuan | E5: Volume | F5: Harga Satuan (Rp) | G5: Jumlah Harga (Rp) | H5: Bobot (%)
A6: A | B6: PEKERJAAN PERSIAPAN & TANAH
A7: 1 | B7: =INDEX('Analisa Harga Satuan'!$B$5:$B$157,MATCH(C7,'Analisa Harga Satuan'!$A$5:$A$157,0)) -> Pembersihan lahan & perataan | C7: A.1 | D7: =INDEX('Analisa Harga Satuan'!$C$5:$C$157,MATCH(C7,'Analisa Harga Satuan'!$A$5:$A$157,0)) -> m² | E7: 54 | F7: =INDEX('Analisa Harga Satuan'!$F$5:$F$157,MATCH(C7,'Analisa Harga Satuan'!$A$5:$A$157,0)) -> 8021.25 | G7: =E7*F7 -> 433147.5 | H7: =IF($G$37=0,0,G7/$G$37) -> 0.003961551
A8: 2 | B8: =INDEX('Analisa Harga Satuan'!$B$5:$B$157,MATCH(C8,'Analisa Harga Satuan'!$A$5:$A$157,0)) -> Galian tanah pondasi | C8: A.2 | D8: =INDEX('Analisa Harga Satuan'!$C$5:$C$157,MATCH(C8,'Analisa Harga Satuan'!$A$5:$A$157,0)) -> m³ | E8: 14 | F8: =INDEX('Analisa Harga Satuan'!$F$5:$F$157,MATCH(C8,'Analisa Harga Satuan'!$A$5:$A$157,0)) -> 117587.5 | G8: =E8*F8 -> 1646225 | H8: =IF($G$37=0,0,G8/$G$37) -> 0.015056313
A9: 3 | B9: =INDEX('Analisa Harga Satuan'!$B$5:$B$157,MATCH(C9,'Analisa Harga Satuan'!$A$5:$A$157,0)) -> Urugan pasir bawah pondasi | C9: A.3 | D9: =INDEX('Analisa Harga Satuan'!$C$5:$C$157,MATCH(C9,'Analisa Harga Satuan'!$A$5:$A$157,0)) -> m³ | E9: 5 | F9: =INDEX('Analisa Harga Satuan'!$F$5:$F$157,MATCH(C9,'Analisa Harga Satuan'!$A$5:$A$157,0)) -> 405835 | G9: =E9*F9 -> 2029175 | H9: =IF($G$37=0,0,G9/$G$37) -> 0.018558759
B10: Sub Total A | G10: =SUM(G7:G9) -> 4108547.5 | H10: =IF($G$37=0,0,G10/$G$37) -> 0.037576623
A12: B | B12: PEKERJAAN STRUKTUR
A13: 1 | B13: =INDEX('Analisa Harga Satuan'!$B$5:$B$157,MATCH(C13,'Analisa Harga Satuan'!$A$5:$A$157,0)) -> Pondasi batu kali campuran 1 PC : 5 PS | C13: B.1 | D13: =INDEX('Analisa Harga Satuan'!$C$5:$C$157,MATCH(C13,'Analisa Harga Satuan'!$A$5:$A$157,0)) -> m³ | E13: 14 | F13: =INDEX('Analisa Harga Satuan'!$F$5:$F$157,MATCH(C13,'Analisa Harga Satuan'!$A$5:$A$157,0)) -> 1207413.8 | G13: =E13*F13 -> 16903792 | H13: =IF($G$37=0,0,G13/$G$37) -> 0.15460146
A14: 2 | B14: =INDEX('Analisa Harga Satuan'!$B$5:$B$157,MATCH(C14,'Analisa Harga Satuan'!$A$5:$A$157,0)) -> Beton K-175 (1:2:3) sloof/kolom/ring balk | C14: B.2 | D14: =INDEX('Analisa Harga Satuan'!$C$5:$C$157,MATCH(C14,'Analisa Harga Satuan'!$A$5:$A$157,0)) -> m³ | E14: 3.2 | F14: =INDEX('Analisa Harga Satuan'!$F$5:$F$157,MATCH(C14,'Analisa Harga Satuan'!$A$5:$A$157,0)) -> 1364383 | G14: =E14*F14 -> 4366025.6 | H14: =IF($G$37=0,0,G14/$G$37) -> 0.039931508
A15: 3 | B15: =INDEX('Analisa Harga Satuan'!$B$5:$B$157,MATCH(C15,'Analisa Harga Satuan'!$A$5:$A$157,0)) -> Pembesian dengan besi polos/ulir | C15: B.3 | D15: =INDEX('Analisa Harga Satuan'!$C$5:$C$157,MATCH(C15,'Analisa Harga Satuan'!$A$5:$A$157,0)) -> kg | E15: 320 | F15: =INDEX('Analisa Harga Satuan'!$F$5:$F$157,MATCH(C15,'Analisa Harga Satuan'!$A$5:$A$157,0)) -> 20416.525 | G15: =E15*F15 -> 6533288 | H15: =IF($G$37=0,0,G15/$G$37) -> 0.05975321
A16: 4 | B16: =INDEX('Analisa Harga Satuan'!$B$5:$B$157,MATCH(C16,'Analisa Harga Satuan'!$A$5:$A$157,0)) -> Bekisting kolom/sloof (kayu) | C16: B.4 | D16: =INDEX('Analisa Harga Satuan'!$C$5:$C$157,MATCH(C16,'Analisa Harga Satuan'!$A$5:$A$157,0)) -> m² | E16: 28 | F16: =INDEX('Analisa Harga Satuan'!$F$5:$F$157,MATCH(C16,'Analisa Harga Satuan'!$A$5:$A$157,0)) -> 321413.5 | G16: =E16*F16 -> 8999578 | H16: =IF($G$37=0,0,G16/$G$37) -> 0.082309806
B17: Sub Total B | G17: =SUM(G13:G16) -> 36802684 | H17: =IF($G$37=0,0,G17/$G$37) -> 0.33659598
A19: C | B19: PEKERJAAN DINDING
A20: 1 | B20: =INDEX('Analisa Harga Satuan'!$B$5:$B$157,MATCH(C20,'Analisa Harga Satuan'!$A$5:$A$157,0)) -> Pasangan dinding bata merah 1 PC : 4 PS | C20: C.1 | D20: =INDEX('Analisa Harga Satuan'!$C$5:$C$157,MATCH(C20,'Analisa Harga Satuan'!$A$5:$A$157,0)) -> m² | E20: 95 | F20: =INDEX('Analisa Harga Satuan'!$F$5:$F$157,MATCH(C20,'Analisa Harga Satuan'!$A$5:$A$157,0)) -> 173023.25 | G20: =E20*F20 -> 16437209 | H20: =IF($G$37=0,0,G20/$G$37) -> 0.1503341
A21: 2 | B21: =INDEX('Analisa Harga Satuan'!$B$5:$B$157,MATCH(C21,'Analisa Harga Satuan'!$A$5:$A$157,0)) -> Plesteran 1 PC : 4 PS tebal 15 mm | C21: C.2 | D21: =INDEX('Analisa Harga Satuan'!$C$5:$C$157,MATCH(C21,'Analisa Harga Satuan'!$A$5:$A$157,0)) -> m² | E21: 190 | F21: =INDEX('Analisa Harga Satuan'!$F$5:$F$157,MATCH(C21,'Analisa Harga Satuan'!$A$5:$A$157,0)) -> 96327.45 | G21: =E21*F21 -> 18302216 | H21: =IF($G$37=0,0,G21/$G$37) -> 0.16739138
B22: Sub Total C | G22: =SUM(G20:G21) -> 34739424 | H22: =IF($G$37=0,0,G22/$G$37) -> 0.31772549
A24: D | B24: PEKERJAAN ATAP
A25: 1 | B25: =INDEX('Analisa Harga Satuan'!$B$5:$B$157,MATCH(C25,'Analisa Harga Satuan'!$A$5:$A$157,0)) -> Rangka atap kayu & penutup genteng beton | C25: D.1 | D25: =INDEX('Analisa Harga Satuan'!$C$5:$C$157,MATCH(C25,'Analisa Harga Satuan'!$A$5:$A$157,0)) -> m² | E25: 45 | F25: =INDEX('Analisa Harga Satuan'!$F$5:$F$157,MATCH(C25,'Analisa Harga Satuan'!$A$5:$A$157,0)) -> 260245 | G25: =E25*F25 -> 11711025 | H25: =IF($G$37=0,0,G25/$G$37) -> 0.1071086
B26: Sub Total D | G26: =SUM(G25:G25) -> 11711025 | H26: =IF($G$37=0,0,G26/$G$37) -> 0.1071086
A28: E | B28: PEKERJAAN LANTAI & PLAFON
A29: 1 | B29: =INDEX('Analisa Harga Satuan'!$B$5:$B$157,MATCH(C29,'Analisa Harga Satuan'!$A$5:$A$157,0)) -> Pasang lantai keramik 40x40 | C29: E.1 | D29: =INDEX('Analisa Harga Satuan'!$C$5:$C$157,MATCH(C29,'Analisa Harga Satuan'!$A$5:$A$157,0)) -> m² | E29: 36 | F29: =INDEX('Analisa Harga Satuan'!$F$5:$F$157,MATCH(C29,'Analisa Harga Satuan'!$A$5:$A$157,0)) -> 316508.75 | G29: =E29*F29 -> 11394315 | H29: =IF($G$37=0,0,G29/$G$37) -> 0.10421198
A30: 2 | B30: =INDEX('Analisa Harga Satuan'!$B$5:$B$157,MATCH(C30,'Analisa Harga Satuan'!$A$5:$A$157,0)) -> Plafon gypsum rangka kayu | C30: E.2 | D30: =INDEX('Analisa Harga Satuan'!$C$5:$C$157,MATCH(C30,'Analisa Harga Satuan'!$A$5:$A$157,0)) -> m² | E30: 36 | F30: =INDEX('Analisa Harga Satuan'!$F$5:$F$157,MATCH(C30,'Analisa Harga Satuan'!$A$5:$A$157,0)) -> 129944.25 | G30: =E30*F30 -> 4677993 | H30: =IF($G$37=0,0,G30/$G$37) -> 0.04278475
B31: Sub Total E | G31: =SUM(G29:G30) -> 16072308 | H31: =IF($G$37=0,0,G31/$G$37) -> 0.14699673
A33: F | B33: PEKERJAAN FINISHING
A34: 1 | B34: =INDEX('Analisa Harga Satuan'!$B$5:$B$157,MATCH(C34,'Analisa Harga Satuan'!$A$5:$A$157,0)) -> Pengecatan dinding (plamir + cat 1 lapis) | C34: F.1 | D34: =INDEX('Analisa Harga Satuan'!$C$5:$C$157,MATCH(C34,'Analisa Harga Satuan'!$A$5:$A$157,0)) -> m² | E34: 190 | F34: =INDEX('Analisa Harga Satuan'!$F$5:$F$157,MATCH(C34,'Analisa Harga Satuan'!$A$5:$A$157,0)) -> 31073 | G34: =E34*F34 -> 5903870 | H34: =IF($G$37=0,0,G34/$G$37) -> 0.053996576
B35: Sub Total F | G35: =SUM(G34:G34) -> 5903870 | H35: =IF($G$37=0,0,G35/$G$37) -> 0.053996576
B37: JUMLAH TOTAL (A+B+C+D+E+F) | G37: =G10+G17+G22+G26+G31+G35 -> 1.0933786e+08
B38: PPN | G38: =G37*'Informasi Project'!$B$17 -> 12027164
B39: TOTAL SETELAH PPN | G39: =G37+G38 -> 1.2136502e+08
B40: TOTAL RAB (DIBULATKAN) | G40: =IF('Informasi Project'!$B$18>0,CEILING(G39,'Informasi Project'!$B$18),G39) -> 121366000
B41: Biaya per m² bangunan | G41: =IF('Informasi Project'!$B$13>0,G40/'Informasi Project'!$B$13,0) -> 3371277.8
A43: Catatan: Kode AHSP & Volume (biru) adalah input. Volume contoh — ganti dengan hasil quantity take-off. Harga satuan terhubung otomatis ke sheet Analisa Harga Satuan.
B45: Disusun oleh, | G45: Disetujui oleh,
B49: ( ............................ ) | G49: ( ............................ )
B50: Project Manager | G50: Pemilik Proyek

Sheet Analisa Harga Satuan
A1: ANALISA HARGA SATUAN PEKERJAAN (AHSP)
A2: Koefisien (biru) = input, indikatif mengacu pola SNI. Uraian, satuan & harga komponen diambil otomatis dari sheet Harga Bahan / Harga Upah berdasarkan kode.
A4: Kode | B4: Uraian | C4: Satuan | D4: Koefisien | E4: Harga Satuan (Rp) | F4: Jumlah Harga (Rp) | G4: Kategori
A5: A.1 | B5: Pembersihan lahan & perataan | C5: m² | E5: Harga satuan: | F5: =F11 -> 8021.25
A6: U-01 | B6: =IF(LEFT($A6,1)="B",INDEX('Harga Bahan'!$B$5:$B$200,MATCH($A6,'Harga Bahan'!$A$5:$A$200,0)),INDEX('Harga Upah'!$B$5:$B$200,MATCH($A6,'Harga Upah'!$A$5:$A$200,0))) -> Pekerja | C6: =IF(LEFT($A6,1)="B",INDEX('Harga Bahan'!$C$5:$C$200,MATCH($A6,'Harga Bahan'!$A$5:$A$200,0)),INDEX('Harga Upah'!$C$5:$C$200,MATCH($A6,'Harga Upah'!$A$5:$A$200,0))) -> OH | D6: 0.05 | E6: =IF(LEFT($A6,1)="B",INDEX('Harga Bahan'!$D$5:$D$200,MATCH($A6,'Harga Bahan'!$A$5:$A$200,0)),INDEX('Harga Upah'!$D$5:$D$200,MATCH($A6,'Harga Upah'!$A$5:$A$200,0))) -> 130000 | F6: =D6*E6 -> 6500 | G6: Upah
A7: U-07 | B7: =IF(LEFT($A7,1)="B",INDEX('Harga Bahan'!$B$5:$B$200,MATCH($A7,'Harga Bahan'!$A$5:$A$200,0)),INDEX('Harga Upah'!$B$5:$B$200,MATCH($A7,'Harga Upah'!$A$5:$A$200,0))) -> Mandor | C7: =IF(LEFT($A7,1)="B",INDEX('Harga Bahan'!$C$5:$C$200,MATCH($A7,'Harga Bahan'!$A$5:$A$200,0)),INDEX('Harga Upah'!$C$5:$C$200,MATCH($A7,'Harga Upah'!$A$5:$A$200,0))) -> OH | D7: 0.0025 | E7: =IF(LEFT($A7,1)="B",INDEX('Harga Bahan'!$D$5:$D$200,MATCH($A7,'Harga Bahan'!$A$5:$A$200,0)),INDEX('Harga Upah'!$D$5:$D$200,MATCH($A7,'Harga Upah'!$A$5:$A$200,0))) -> 190000 | F7: =D7*E7 -> 475 | G7: Upah
B8: Jumlah harga bahan | F8: =SUMIF(G6:G7,"Bahan",F6:F7) -> 0
B9: Jumlah harga upah | F9: =SUMIF(G6:G7,"Upah",F6:F7) -> 6975
B10: ="Overhead & profit ("&TEXT('Informasi Project'!$B$16,"0.0%")&")" -> Overhead & profit (15.0%) | F10: =(F8+F9)*'Informasi Project'!$B$16 -> 1046.25
B11: HARGA SATUAN PEKERJAAN | F11: =F8+F9+F10 -> 8021.25
A13: A.2 | B13: Galian tanah pondasi | C13: m³ | E13: Harga satuan: | F13: =F19 -> 117587.5
A14: U-01 | B14: =IF(LEFT($A14,1)="B",INDEX('Harga Bahan'!$B$5:$B$200,MATCH($A14,'Harga Bahan'!$A$5:$A$200,0)),INDEX('Harga Upah'!$B$5:$B$200,MATCH($A14,'Harga Upah'!$A$5:$A$200,0))) -> Pekerja | C14: =IF(LEFT($A14,1)="B",INDEX('Harga Bahan'!$C$5:$C$200,MATCH($A14,'Harga Bahan'!$A$5:$A$200,0)),INDEX('Harga Upah'!$C$5:$C$200,MATCH($A14,'Harga Upah'!$A$5:$A$200,0))) -> OH | D14: 0.75 | E14: =IF(LEFT($A14,1)="B",INDEX('Harga Bahan'!$D$5:$D$200,MATCH($A14,'Harga Bahan'!$A$5:$A$200,0)),INDEX('Harga Upah'!$D$5:$D$200,MATCH($A14,'Harga Upah'!$A$5:$A$200,0))) -> 130000 | F14: =D14*E14 -> 97500 | G14: Upah
A15: U-07 | B15: =IF(LEFT($A15,1)="B",INDEX('Harga Bahan'!$B$5:$B$200,MATCH($A15,'Harga Bahan'!$A$5:$A$200,0)),INDEX('Harga Upah'!$B$5:$B$200,MATCH($A15,'Harga Upah'!$A$5:$A$200,0))) -> Mandor | C15: =IF(LEFT($A15,1)="B",INDEX('Harga Bahan'!$C$5:$C$200,MATCH($A15,'Harga Bahan'!$A$5:$A$200,0)),INDEX('Harga Upah'!$C$5:$C$200,MATCH($A15,'Harga Upah'!$A$5:$A$200,0))) -> OH | D15: 0.025 | E15: =IF(LEFT($A15,1)="B",INDEX('Harga Bahan'!$D$5:$D$200,MATCH($A15,'Harga Bahan'!$A$5:$A$200,0)),INDEX('Harga Upah'!$D$5:$D$200,MATCH($A15,'Harga Upah'!$A$5:$A$200,0))) -> 190000 | F15: =D15*E15 -> 4750 | G15: Upah
B16: Jumlah harga bahan | F16: =SUMIF(G14:G15,"Bahan",F14:F15) -> 0
B17: Jumlah harga upah | F17: =SUMIF(G14:G15,"Upah",F14:F15) -> 102250
B18: ="Overhead & profit ("&TEXT('Informasi Project'!$B$16,"0.0%")&")" -> Overhead & profit (15.0%) | F18: =(F16+F17)*'Informasi Project'!$B$16 -> 15337.5
B19: HARGA SATUAN PEKERJAAN | F19: =F16+F17+F18 -> 117587.5
A21: A.3 | B21: Urugan pasir bawah pondasi | C21: m³ | E21: Harga satuan: | F21: =F28 -> 405835
A22: B-02 | B22: =IF(LEFT($A22,1)="B",INDEX('Harga Bahan'!$B$5:$B$200,MATCH($A22,'Harga Bahan'!$A$5:$A$200,0)),INDEX('Harga Upah'!$B$5:$B$200,MATCH($A22,'Harga Upah'!$A$5:$A$200,0))) -> Pasir pasang | C22: =IF(LEFT($A22,1)="B",INDEX('Harga Bahan'!$C$5:$C$200,MATCH($A22,'Harga Bahan'!$A$5:$A$200,0)),INDEX('Harga Upah'!$C$5:$C$200,MATCH($A22,'Harga Upah'!$A$5:$A$200,0))) -> m³ | D22: 1.2 | E22: =IF(LEFT($A22,1)="B",INDEX('Harga Bahan'!$D$5:$D$200,MATCH($A22,'Harga Bahan'!$A$5:$A$200,0)),INDEX('Harga Upah'!$D$5:$D$200,MATCH($A22,'Harga Upah'!$A$5:$A$200,0))) -> 260000 | F22: =D22*E22 -> 312000 | G22: Bahan
A23: U-01 | B23: =IF(LEFT($A23,1)="B",INDEX('Harga Bahan'!$B$5:$B$200,MATCH($A23,'Harga Bahan'!$A$5:$A$200,0)),INDEX('Harga Upah'!$B$5:$B$200,MATCH($A23,'Harga Upah'!$A$5:$A$200,0))) -> Pekerja | C23: =IF(LEFT($A23,1)="B",INDEX('Harga Bahan'!$C$5:$C$200,MATCH($A23,'Harga Bahan'!$A$5:$A$200,0)),INDEX('Harga Upah'!$C$5:$C$200,MATCH($A23,'Harga Upah'!$A$5:$A$200,0))) -> OH | D23: 0.3 | E23: =IF(LEFT($A23,1)="B",INDEX('Harga Bahan'!$D$5:$D$200,MATCH($A23,'Harga Bahan'!$A$5:$A$200,0)),INDEX('Harga Upah'!$D$5:$D$200,MATCH($A23,'Harga Upah'!$A$5:$A$200,0))) -> 130000 | F23: =D23*E23 -> 39000 | G23: Upah
A24: U-07 | B24: =IF(LEFT($A24,1)="B",INDEX('Harga Bahan'!$B$5:$B$200,MATCH($A24,'Harga Bahan'!$A$5:$A$200,0)),INDEX('Harga Upah'!$B$5:$B$200,MATCH($A24,'Harga Upah'!$A$5:$A$200,0))) -> Mandor | C24: =IF(LEFT($A24,1)="B",INDEX('Harga Bahan'!$C$5:$C$200,MATCH($A24,'Harga Bahan'!$A$5:$A$200,0)),INDEX('Harga Upah'!$C$5:$C$200,MATCH($A24,'Harga Upah'!$A$5:$A$200,0))) -> OH | D24: 0.01 | E24: =IF(LEFT($A24,1)="B",INDEX('Harga Bahan'!$D$5:$D$200,MATCH($A24,'Harga Bahan'!$A$5:$A$200,0)),INDEX('Harga Upah'!$D$5:$D$200,MATCH($A24,'Harga Upah'!$A$5:$A$200,0))) -> 190000 | F24: =D24*E24 -> 1900 | G24: Upah
B25: Jumlah harga bahan | F25: =SUMIF(G22:G24,"Bahan",F22:F24) -> 312000
B26: Jumlah harga upah | F26: =SUMIF(G22:G24,"Upah",F22:F24) -> 40900
B27: ="Overhead & profit ("&TEXT('Informasi Project'!$B$16,"0.0%")&")" -> Overhead & profit (15.0%) | F27: =(F25+F26)*'Informasi Project'!$B$16 -> 52935
B28: HARGA SATUAN PEKERJAAN | F28: =F25+F26+F27 -> 405835
A30: B.1 | B30: Pondasi batu kali campuran 1 PC : 5 PS | C30: m³ | E30: Harga satuan: | F30: =F41 -> 1207413.8
A31: B-05 | B31: =IF(LEFT($A31,1)="B",INDEX('Harga Bahan'!$B$5:$B$200,MATCH($A31,'Harga Bahan'!$A$5:$A$200,0)),INDEX('Harga Upah'!$B$5:$B$200,MATCH($A31,'Harga Upah'!$A$5:$A$200,0))) -> Batu kali belah | C31: =IF(LEFT($A31,1)="B",INDEX('Harga Bahan'!$C$5:$C$200,MATCH($A31,'Harga Bahan'!$A$5:$A$200,0)),INDEX('Harga Upah'!$C$5:$C$200,MATCH($A31,'Harga Upah'!$A$5:$A$200,0))) -> m³ | D31: 1.2 | E31: =IF(LEFT($A31,1)="B",INDEX('Harga Bahan'!$D$5:$D$200,MATCH($A31,'Harga Bahan'!$A$5:$A$200,0)),INDEX('Harga Upah'!$D$5:$D$200,MATCH($A31,'Harga Upah'!$A$5:$A$200,0))) -> 280000 | F31: =D31*E31 -> 336000 | G31: Bahan
A32: B-01 | B32: =IF(LEFT($A32,1)="B",INDEX('Harga Bahan'!$B$5:$B$200,MATCH($A32,'Harga Bahan'!$A$5:$A$200,0)),INDEX('Harga Upah'!$B$5:$B$200,MATCH($A32,'Harga Upah'!$A$5:$A$200,0))) -> Semen Portland (PC) | C32: =IF(LEFT($A32,1)="B",INDEX('Harga Bahan'!$C$5:$C$200,MATCH($A32,'Harga Bahan'!$A$5:$A$200,0)),INDEX('Harga Upah'!$C$5:$C$200,MATCH($A32,'Harga Upah'!$A$5:$A$200,0))) -> kg | D32: 163 | E32: =IF(LEFT($A32,1)="B",INDEX('Harga Bahan'!$D$5:$D$200,MATCH($A32,'Harga Bahan'!$A$5:$A$200,0)),INDEX('Harga Upah'!$D$5:$D$200,MATCH($A32,'Harga Upah'!$A$5:$A$200,0))) -> 1450 | F32: =D32*E32 -> 236350 | G32: Bahan
A33: B-02 | B33: =IF(LEFT($A33,1)="B",INDEX('Harga Bahan'!$B$5:$B$200,MATCH($A33,'Harga Bahan'!$A$5:$A$200,0)),INDEX('Harga Upah'!$B$5:$B$200,MATCH($A33,'Harga Upah'!$A$5:$A$200,0))) -> Pasir pasang | C33: =IF(LEFT($A33,1)="B",INDEX('Harga Bahan'!$C$5:$C$200,MATCH($A33,'Harga Bahan'!$A$5:$A$200,0)),INDEX('Harga Upah'!$C$5:$C$200,MATCH($A33,'Harga Upah'!$A$5:$A$200,0))) -> m³ | D33: 0.52 | E33: =IF(LEFT($A33,1)="B",INDEX('Harga Bahan'!$D$5:$D$200,MATCH($A33,'Harga Bahan'!$A$5:$A$200,0)),INDEX('Harga Upah'!$D$5:$D$200,MATCH($A33,'Harga Upah'!$A$5:$A$200,0))) -> 260000 | F33: =D33*E33 -> 135200 | G33: Bahan
A34: U-01 | B34: =IF(LEFT($A34,1)="B",INDEX('Harga Bahan'!$B$5:$B$200,MATCH($A34,'Harga Bahan'!$A$5:$A$200,0)),INDEX('Harga Upah'!$B$5:$B$200,MATCH($A34,'Harga Upah'!$A$5:$A$200,0))) -> Pekerja | C34: =IF(LEFT($A34,1)="B",INDEX('Harga Bahan'!$C$5:$C$200,MATCH($A34,'Harga Bahan'!$A$5:$A$200,0)),INDEX('Harga Upah'!$C$5:$C$200,MATCH($A34,'Harga Upah'!$A$5:$A$200,0))) -> OH | D34: 1.5 | E34: =IF(LEFT($A34,1)="B",INDEX('Harga Bahan'!$D$5:$D$200,MATCH($A34,'Harga Bahan'!$A$5:$A$200,0)),INDEX('Harga Upah'!$D$5:$D$200,MATCH($A34,'Harga Upah'!$A$5:$A$200,0))) -> 130000 | F34: =D34*E34 -> 195000 | G34: Upah
A35: U-02 | B35: =IF(LEFT($A35,1)="B",INDEX('Harga Bahan'!$B$5:$B$200,MATCH($A35,'Harga Bahan'!$A$5:$A$200,0)),INDEX('Harga Upah'!$B$5:$B$200,MATCH($A35,'Harga Upah'!$A$5:$A$200,0))) -> Tukang batu | C35: =IF(LEFT($A35,1)="B",INDEX('Harga Bahan'!$C$5:$C$200,MATCH($A35,'Harga Bahan'!$A$5:$A$200,0)),INDEX('Harga Upah'!$C$5:$C$200,MATCH($A35,'Harga Upah'!$A$5:$A$200,0))) -> OH | D35: 0.75 | E35: =IF(LEFT($A35,1)="B",INDEX('Harga Bahan'!$D$5:$D$200,MATCH($A35,'Harga Bahan'!$A$5:$A$200,0)),INDEX('Harga Upah'!$D$5:$D$200,MATCH($A35,'Harga Upah'!$A$5:$A$200,0))) -> 160000 | F35: =D35*E35 -> 120000 | G35: Upah
A36: U-06 | B36: =IF(LEFT($A36,1)="B",INDEX('Harga Bahan'!$B$5:$B$200,MATCH($A36,'Harga Bahan'!$A$5:$A$200,0)),INDEX('Harga Upah'!$B$5:$B$200,MATCH($A36,'Harga Upah'!$A$5:$A$200,0))) -> Kepala tukang | C36: =IF(LEFT($A36,1)="B",INDEX('Harga Bahan'!$C$5:$C$200,MATCH($A36,'Harga Bahan'!$A$5:$A$200,0)),INDEX('Harga Upah'!$C$5:$C$200,MATCH($A36,'Harga Upah'!$A$5:$A$200,0))) -> OH | D36: 0.075 | E36: =IF(LEFT($A36,1)="B",INDEX('Harga Bahan'!$D$5:$D$200,MATCH($A36,'Harga Bahan'!$A$5:$A$200,0)),INDEX('Harga Upah'!$D$5:$D$200,MATCH($A36,'Harga Upah'!$A$5:$A$200,0))) -> 175000 | F36: =D36*E36 -> 13125 | G36: Upah
A37: U-07 | B37: =IF(LEFT($A37,1)="B",INDEX('Harga Bahan'!$B$5:$B$200,MATCH($A37,'Harga Bahan'!$A$5:$A$200,0)),INDEX('Harga Upah'!$B$5:$B$200,MATCH($A37,'Harga Upah'!$A$5:$A$200,0))) -> Mandor | C37: =IF(LEFT($A37,1)="B",INDEX('Harga Bahan'!$C$5:$C$200,MATCH($A37,'Harga Bahan'!$A$5:$A$200,0)),INDEX('Harga Upah'!$C$5:$C$200,MATCH($A37,'Harga Upah'!$A$5:$A$200,0))) -> OH | D37: 0.075 | E37: =IF(LEFT($A37,1)="B",INDEX('Harga Bahan'!$D$5:$D$200,MATCH($A37,'Harga Bahan'!$A$5:$A$200,0)),INDEX('Harga Upah'!$D$5:$D$200,MATCH($A37,'Harga Upah'!$A$5:$A$200,0))) -> 190000 | F37: =D37*E37 -> 14250 | G37: Upah
B38: Jumlah harga bahan | F38: =SUMIF(G31:G37,"Bahan",F31:F37) -> 707550
B39: Jumlah harga upah | F39: =SUMIF(G31:G37,"Upah",F31:F37) -> 342375
B40: ="Overhead & profit ("&TEXT('Informasi Project'!$B$16,"0.0%")&")" -> Overhead & profit (15.0%) | F40: =(F38+F39)*'Informasi Project'!$B$16 -> 157488.75
B41: HARGA SATUAN PEKERJAAN | F41: =F38+F39+F40 -> 1207413.8
A43: B.2 | B43: Beton K-175 (1:2:3) sloof/kolom/ring balk | C43: m³ | E43: Harga satuan: | F43: =F55 -> 1364383
A44: B-01 | B44: =IF(LEFT($A44,1)="B",INDEX('Harga Bahan'!$B$5:$B$200,MATCH($A44,'Harga Bahan'!$A$5:$A$200,0)),INDEX('Harga Upah'!$B$5:$B$200,MATCH($A44,'Harga Upah'!$A$5:$A$200,0))) -> Semen Portland (PC) | C44: =IF(LEFT($A44,1)="B",INDEX('Harga Bahan'!$C$5:$C$200,MATCH($A44,'Harga Bahan'!$A$5:$A$200,0)),INDEX('Harga Upah'!$C$5:$C$200,MATCH($A44,'Harga Upah'!$A$5:$A$200,0))) -> kg | D44: 326 | E44: =IF(LEFT($A44,1)="B",INDEX('Harga Bahan'!$D$5:$D$200,MATCH($A44,'Harga Bahan'!$A$5:$A$200,0)),INDEX('Harga Upah'!$D$5:$D$200,MATCH($A44,'Harga Upah'!$A$5:$A$200,0))) -> 1450 | F44: =D44*E44 -> 472700 | G44: Bahan
A45: B-03 | B45: =IF(LEFT($A45,1)="B",INDEX('Harga Bahan'!$B$5:$B$200,MATCH($A45,'Harga Bahan'!$A$5:$A$200,0)),INDEX('Harga Upah'!$B$5:$B$200,MATCH($A45,'Harga Upah'!$A$5:$A$200,0))) -> Pasir beton | C45: =IF(LEFT($A45,1)="B",INDEX('Harga Bahan'!$C$5:$C$200,MATCH($A45,'Harga Bahan'!$A$5:$A$200,0)),INDEX('Harga Upah'!$C$5:$C$200,MATCH($A45,'Harga Upah'!$A$5:$A$200,0))) -> m³ | D45: 0.52 | E45: =IF(LEFT($A45,1)="B",INDEX('Harga Bahan'!$D$5:$D$200,MATCH($A45,'Harga Bahan'!$A$5:$A$200,0)),INDEX('Harga Upah'!$D$5:$D$200,MATCH($A45,'Harga Upah'!$A$5:$A$200,0))) -> 290000 | F45: =D45*E45 -> 150800 | G45: Bahan
...

Sheet Harga Bahan
A1: DAFTAR HARGA SATUAN BAHAN
A2: Sel biru = harga input (asumsi contoh, ganti dengan harga survei). Tambah baris baru di bawah bila perlu (rentang rumus lookup sampai baris 200).
A4: Kode | B4: Uraian | C4: Satuan | D4: Harga Satuan (Rp)
A5: B-01 | B5: Semen Portland (PC) | C5: kg | D5: 1450
A6: B-02 | B6: Pasir pasang | C6: m³ | D6: 260000
A7: B-03 | B7: Pasir beton | C7: m³ | D7: 290000
A8: B-04 | B8: Batu split / kerikil 2/3 | C8: m³ | D8: 350000
A9: B-05 | B9: Batu kali belah | C9: m³ | D9: 280000
A10: B-06 | B10: Batu bata merah | C10: bh | D10: 900
A11: B-07 | B11: Besi beton polos/ulir | C11: kg | D11: 14500
A12: B-08 | B12: Kawat beton (bendrat) | C12: kg | D12: 20000
A13: B-09 | B13: Kayu kelas II/III (balok, usuk, reng) | C13: m³ | D13: 3800000
A14: B-10 | B14: Paku campuran | C14: kg | D14: 22000
A15: B-11 | B15: Air kerja | C15: liter | D15: 50
A16: B-12 | B16: Genteng beton | C16: bh | D16: 7500
... A21: B-17 | B21: Tanah urug | C21: m³ | D21: 120000

Sheet Harga Upah
A1: DAFTAR HARGA SATUAN UPAH TENAGA KERJA
A2: Sel biru = harga input (asumsi contoh, ganti dengan harga survei). Tambah baris baru di bawah bila perlu (rentang rumus lookup sampai baris 200).
A4: Kode | B4: Uraian | C4: Satuan | D4: Harga Satuan (Rp)
A5: U-01 | B5: Pekerja | C5: OH | D5: 130000
A6: U-02 | B6: Tukang batu | C6: OH | D6: 160000
A7: U-03 | B7: Tukang kayu | C7: OH | D7: 160000
A8: U-04 | B8: Tukang besi | C8: OH | D8: 160000
A9: U-05 | B9: Tukang cat | C9: OH | D9: 160000
A10: U-06 | B10: Kepala tukang | C10: OH | D10: 175000
A11: U-07 | B11: Mandor | C11: OH | D11: 190000
