Workbook

Sheet Petunjuk
A1: RAB Kawasan Peternakan Ayam KUB Semi Umbaran 10.000 Ekor - Adeva Farm, Konawe Selatan
A2: Rencana Anggaran Biaya untuk gambar teknik GT-01 (kandang), GT-02 (kawasan, pagar), GT-03 (fasilitas). Oktober 2026.
A4: CARA MEMAKAI
A5: 1 | B5: Sel berwarna BIRU adalah input: harga dasar (sheet Harga Dasar), koefisien analisa (sheet AHSP), dan persentase di bawah.
A6: 2 | B6: Sel HIJAU mengambil angka dari sheet lain. Sel HITAM adalah rumus. Jangan menimpa rumus.
A7: 3 | B7: Ganti harga dasar dengan harga toko/penawaran setempat atau HSPK Kabupaten Konawe Selatan terbaru; seluruh RAB otomatis berubah.
A8: 4 | B8: Volume dihitung dari ukuran gambar (rumus di kolom Volume menunjukkan cara hitungnya).
A9: DASAR PERHITUNGAN
A10: • | B10: Koefisien analisa mengikuti pola AHSP Bidang Cipta Karya (Permen PUPR No. 8 Tahun 2023 dan SNI analisa harga satuan) untuk pekerjaan manual, disederhanakan untuk bangunan kandang. Item yang tidak ada di AHSP (baja ringan, kawat, tirai, perlengkapan kandang) memakai analisa pasar.
A11: • | B11: Harga dasar upah dan bahan adalah PERKIRAAN Konawe Selatan/Kendari 2026, karena HSPK resmi Konawe Selatan 2026 tidak dapat diakses saat penyusunan. Rujukan: Perbup Konawe Selatan No. 85/2024 (HSPK), UMK Sultra 2026 Rp 3.306.496, Indeks Kemahalan Konstruksi Konawe Selatan 2025 = 91,52.
A12: • | B12: Bekisting dihitung dengan kayu dipakai ulang sekitar 3 kali (koefisien kayu lebih kecil dari AHSP standar).
A13: • | B13: Belum termasuk: pembelian lahan, perizinan (PBG/SLF, izin usaha), PPN, pengawasan konsultan, dan pengangkutan khusus ke lokasi yang sulit.
A14: KOMPONEN TAMBAHAN
B15: Biaya umum dan keuntungan pemborong (isi 0% bila swakelola/upah harian) | C15: 0.1
B16: Biaya tak terduga (dihitung di Rekap) | C16: 0.05

Sheet Rekap
A1: REKAPITULASI RAB KAWASAN PETERNAKAN AYAM KUB SEMI UMBARAN 10.000 EKOR
A2: Adeva Farm, Kabupaten Konawe Selatan · Oktober 2026 · harga perkiraan, wajib dicek dengan harga setempat
A4: No | B4: Uraian | C4: Jumlah unit | D4: Harga per unit (Rp) | E4: Jumlah (Rp) | F4: Porsi
A5: 1 | B5: Kandang postal semi umbaran 10 x 40 m (5 layer + 1 starter) | C5: 6 | D5: ='RAB Kandang'!$F$63 | E5: =C5*D5 | F5: =E5/E$19
A6: 2 | B6: Pos jaga | C6: 1 | D6: ='RAB Fasilitas'!$F$41 | E6: =C6*D6 | F6: =E6/E$19
A7: 3 | B7: Kantor | C7: 1 | D7: ='RAB Fasilitas'!$F$81 | E7: =C7*D7 | F7: =E7/E$19
A8: 4 | B8: Mes anak kandang | C8: 1 | D8: ='RAB Fasilitas'!$F$121 | E8: =C8*D8 | F8: =E8/E$19
A9: 5 | B9: Rumah telur (sortir & simpan) | C9: 1 | D9: ='RAB Fasilitas'!$F$159 | E9: =C9*D9 | F9: =E9/E$19
A10: 6 | B10: Rumah pakan (olah & campur) | C10: 1 | D10: ='RAB Fasilitas'!$F$199 | E10: =C10*D10 | F10: =E10/E$19
A11: 7 | B11: Gudang pakan jadi | C11: 1 | D11: ='RAB Fasilitas'!$F$233 | E11: =C11*D11 | F11: =E11/E$19
A12: 8 | B12: Gudang jagung | C12: 1 | D12: ='RAB Fasilitas'!$F$267 | E12: =C12*D12 | F12: =E12/E$19
A13: 9 | B13: Ruang ganti + celup kaki | C13: 1 | D13: ='RAB Fasilitas'!$F$305 | E13: =C13*D13 | F13: =E13/E$19
A14: 10 | B14: Rumah kompos | C14: 1 | D14: ='RAB Fasilitas'!$F$339 | E14: =C14*D14 | F14: =E14/E$19
A15: 11 | B15: Rumah maggot BSF | C15: 1 | D15: ='RAB Fasilitas'!$F$375 | E15: =C15*D15 | F15: =E15/E$19
A16: 12 | B16: Kandang karantina | C16: 1 | D16: ='RAB Fasilitas'!$F$413 | E16: =C16*D16 | F16: =E16/E$19
A17: 13 | B17: Pagar harmonika, gerbang, bak celup, umbaran | C17: 1 | D17: ='RAB Pagar Umbaran'!$F$33 | E17: =C17*D17 | F17: =E17/E$19
A18: 14 | B18: Utilitas: lahan, jalan, lantai jemur, air, embung, listrik | C18: 1 | D18: ='RAB Utilitas Lahan'!$F$41 | E18: =C18*D18 | F18: =E18/E$19
B19: JUMLAH | E19: =SUM(E5:E18)
B20: Biaya tak terduga | C20: =Petunjuk!$C$16 | E20: =E19*C20
B21: TOTAL BIAYA PEMBANGUNAN | E21: =E19+E20
B22: Dibulatkan | E22: =ROUNDUP(E21,-6)
B23: Opsional, tidak termasuk total: jembatan titian kayu 20 m ke lahan seberang sungai | E23: =20*ROUND('Harga Dasar'!$D$73*(1+Petunjuk!$C$15),-2)
B24: Biaya bangunan per ekor (10.000 ekor) | E24: =E21/10000
B25: Kandang saja per ekor (6 unit / 12.000 kapasitas) | E25: =6*'RAB Kandang'!$F$63/12000
B27: PILIHAN PENGHEMATAN (bila dana terbatas)
B28: 1. Bangun bertahap: tahap 1 = 3 kandang + gudang pakan + ruang ganti + pagar zona; tahap 2 = 3 kandang + fasilitas lain.
B29: 2. Lantai kandang tanah dipadatkan + kapur + sekam tebal (tanpa rabat beton) menghemat ±Rp 45 juta per kandang, tetapi lebih sulit dibersihkan.
B30: 3. Overstek atap 60 cm (bukan 100 cm) memangkas bidang atap ±8%.
B31: 4. Tiang pagar sekat umbaran memakai kayu ulin bekas / bambu awetan (umur 3-5 tahun) bila dana belum cukup.
B32: 5. Biaya umum & keuntungan 10% dapat menjadi 0% bila dikerjakan swakelola dengan tukang harian dan pengawasan sendiri.

Sheet Harga Dasar
A1: Harga Satuan Dasar Upah, Bahan dan Alat - perkiraan Kab. Konawe Selatan 2026
A2: Kolom Harga (biru) WAJIB dicek ke toko bangunan Andoolo/Kendari, pemasok, atau HSPK Kabupaten terbaru sebelum dipakai.
A4: Kode | B4: Uraian | C4: Satuan | D4: Harga (Rp) | E4: Catatan
A5: A. UPAH TENAGA KERJA (per orang-hari)
A6: L01 | B6: Pekerja | C6: OH | D6: 130000 | E6: UMK Sultra 2026 Rp 3.306.496 / ±25 hari kerja
A7: L02 | B7: Tukang (batu/kayu/besi/las) | C7: OH | D7: 165000 | E7: perkiraan ±1,25 x pekerja
A8: L03 | B8: Kepala tukang | C8: OH | D8: 180000 | E8: perkiraan
A9: L04 | B9: Mandor | C9: OH | D9: 195000 | E9: perkiraan
A10: B. BAHAN BANGUNAN
A11: M01 | B11: Semen Portland (zak 40 kg = Rp 62.000) | C11: kg | D11: 1550 | E11: Tonasa/Bosowa, harga toko
A12: M02 | B12: Pasir pasang / pasir beton | C12: m³ | D12: 250000 | E12: franco lokasi
A13: M03 | B13: Pasir urug | C13: m³ | D13: 200000
A14: M04 | B14: Kerikil / batu pecah 2/3 | C14: m³ | D14: 400000
A15: M05 | B15: Sirtu (pasir batu) | C15: m³ | D15: 180000 | E15: untuk jalan dan lantai kerja
A16: M06 | B16: Tanah urug (termasuk angkut) | C16: m³ | D16: 80000 | E16: bisa memakai tanah galian embung
A17: M07 | B17: Batu bata merah | C17: bh | D17: 1000
A18: M08 | B18: Besi beton polos/ulir | C18: kg | D18: 14000
A19: M09 | B19: Kawat bendrat | C19: kg | D19: 22000
A20: M10 | B20: Kayu kelas III (bekisting, papan) | C20: m³ | D20: 3500000
A21: M11 | B21: Kayu kelas II (kusen, rangka pintu kecil) | C21: m³ | D21: 5500000
A22: M12 | B22: Paku campur | C22: kg | D22: 24000
A23: M13 | B23: Minyak bekisting | C23: liter | D23: 10000
A24: M14 | B24: Kawat harmonika galvanis 1" BWG 16 (dinding kandang) | C24: m² | D24: 35000 | E24: anti burung liar
A25: M15 | B25: Kawat harmonika galvanis 2" BWG 12 (pagar) | C25: m² | D25: 30000
A26: M16 | B26: Kawat seling / besi Ø3 mm | C26: m | D26: 4000
A27: M17 | B27: Terpal A5 tirai | C27: m² | D27: 12000
A28: M18 | B28: Tali nilon 6 mm | C28: m | D28: 2500
A29: M19 | B29: Katrol tirai | C29: bh | D29: 25000
A30: M20 | B30: Pipa PVC 3/4" (4 m) | C30: btg | D30: 25000
A31: M21 | B31: Hollow galvanis 40x40x1,2 (6 m) | C31: btg | D31: 140000
A32: M22 | B32: Hollow galvanis 50x50x1,6 (6 m) | C32: btg | D32: 230000 | E32: gerbang
A33: M23 | B33: Plat galvalum 0,4 mm | C33: m² | D33: 75000
A34: M24 | B34: Engsel 4" | C34: bh | D34: 35000
A35: M25 | B35: Grendel + kunci | C35: bh | D35: 30000
A36: M26 | B36: Cat besi / meni | C36: kg | D36: 70000
A37: M27 | B37: Cat dasar tembok | C37: kg | D37: 30000
A38: M28 | B38: Cat tembok eksterior | C38: kg | D38: 35000
A39: M29 | B39: Baja ringan C75.75 (6 m) | C39: btg | D39: 105000 | E39: G550 AZ100
A40: M30 | B40: Reng baja ringan U30.45 (6 m) | C40: btg | D40: 50000
A41: M31 | B41: Sekrup baja ringan / atap | C41: bh | D41: 300
...

Sheet AHSP
A1: Analisa Harga Satuan Pekerjaan (pola AHSP PUPR)
A2: Koefisien biru boleh disesuaikan. Harga satuan = (upah + bahan + alat) x (1 + biaya umum & keuntungan di sheet Petunjuk).
A4: A.1 | B4: Perataan lokasi bangunan dan peil | C4: m² | D4: Koefisien | E4: Harga dasar | F4: Jumlah (Rp)
A5: L01 | B5: Pekerja | C5: OH | D5: 0.05 | E5: ='Harga Dasar'!$D$6 | F5: =D5*E5
A6: L04 | B6: Mandor | C6: OH | D6: 0.005 | E6: ='Harga Dasar'!$D$9 | F6: =D6*E6
B7: Jumlah upah + bahan + alat | F7: =SUM(F5:F6)
B8: Biaya umum dan keuntungan | F8: =F7*Petunjuk!$C$15
B9: HARGA SATUAN PEKERJAAN per m² | F9: =ROUND(F7+F8,-2)
A11: A.2 | B11: Pengukuran dan pemasangan bouwplank | C11: m' | D11: Koefisien | E11: Harga dasar | F11: Jumlah (Rp)
A12: L01 | B12: Pekerja | C12: OH | D12: 0.1 | E12: ='Harga Dasar'!$D$6 | F12: =D12*E12
A13: L02 | B13: Tukang (batu/kayu/besi/las) | C13: OH | D13: 0.1 | E13: ='Harga Dasar'!$D$7 | F13: =D13*E13
A14: L03 | B14: Kepala tukang | C14: OH | D14: 0.01 | E14: ='Harga Dasar'!$D$8 | F14: =D14*E14
A15: L04 | B15: Mandor | C15: OH | D15: 0.005 | E15: ='Harga Dasar'!$D$9 | F15: =D15*E15
A16: M10 | B16: Kayu kelas III (bekisting, papan) | C16: m³ | D16: 0.012 | E16: ='Harga Dasar'!$D$20 | F16: =D16*E16
A17: M12 | B17: Paku campur | C17: kg | D17: 0.02 | E17: ='Harga Dasar'!$D$22 | F17: =D17*E17
B18: Jumlah upah + bahan + alat | F18: =SUM(F12:F17)
B19: Biaya umum dan keuntungan | F19: =F18*Petunjuk!$C$15
B20: HARGA SATUAN PEKERJAAN per m' | F20: =ROUND(F18+F19,-2)
A22: A.3 | B22: Galian tanah biasa sedalam s.d. 1 m | C22: m³ | D22: Koefisien | E22: Harga dasar | F22: Jumlah (Rp)
A23: L01 | B23: Pekerja | C23: OH | D23: 0.75 | E23: ='Harga Dasar'!$D$6 | F23: =D23*E23
A24: L04 | B24: Mandor | C24: OH | D24: 0.025 | E24: ='Harga Dasar'!$D$9 | F24: =D24*E24
B25: Jumlah upah + bahan + alat | F25: =SUM(F23:F24)
B26: Biaya umum dan keuntungan | F26: =F25*Petunjuk!$C$15
B27: HARGA SATUAN PEKERJAAN per m³ | F27: =ROUND(F25+F26,-2)
A29: A.4 | B29: Urugan kembali galian | C29: m³ | D29: Koefisien | E29: Harga dasar | F29: Jumlah (Rp)
A30: L01 | B30: Pekerja | C30: OH | D30: 0.25 | E30: ='Harga Dasar'!$D$6 | F30: =D30*E30
A31: L04 | B31: Mandor | C31: OH | D31: 0.008 | E31: ='Harga Dasar'!$D$9 | F31: =D31*E31
B32: Jumlah upah + bahan + alat | F32: =SUM(F30:F31)
B33: Biaya umum dan keuntungan | F33: =F32*Petunjuk!$C$15
B34: HARGA SATUAN PEKERJAAN per m³ | F34: =ROUND(F32+F33,-2)
A36: A.5 | B36: Urugan tanah peninggian dipadatkan | C36: m³ | D36: Koefisien | E36: Harga dasar | F36: Jumlah (Rp)
A37: M06 | B37: Tanah urug (termasuk angkut) | C37: m³ | D37: 1.2 | E37: ='Harga Dasar'!$D$16 | F37: =D37*E37
A38: L01 | B38: Pekerja | C38: OH | D38: 0.5 | E38: ='Harga Dasar'!$D$6 | F38: =D38*E38
A39: L04 | B39: Mandor | C39: OH | D39: 0.05 | E39: ='Harga Dasar'!$D$9 | F39: =D39*E39
B40: Jumlah upah + bahan + alat | F40: =SUM(F37:F39)
B41: Biaya umum dan keuntungan | F41: =F40*Petunjuk!$C$15
B42: HARGA SATUAN PEKERJAAN per m³ | F42: =ROUND(F40+F41,-2)
A44: A.6 | B44: Urugan pasir | C44: m³ | D44: Koefisien | E44: Harga dasar | F44: Jumlah (Rp)
A45: M03 | B45: Pasir urug | C45: m³ | D45: 1.2 | E45: ='Harga Dasar'!$D$13 | F45: =D45*E45
A46: L01 | B46: Pekerja | C46: OH | D46: 0.3 | E46: ='Harga Dasar'!$D$6 | F46: =D46*E46
...

Sheet RAB Kandang
A1: RAB 1 unit kandang postal semi umbaran 10 x 40 m (2.000 ekor)
A2: Gambar GT-01 lembar K-01 s/d K-09. Kawasan memerlukan 6 unit (5 layer + 1 starter).
A4: No | B4: Uraian pekerjaan | C4: Volume | D4: Sat | E4: Harga satuan (Rp) | F4: Jumlah (Rp) | G4: Dasar volume (dari gambar)
B5: I. PEKERJAAN PERSIAPAN
A6: 1 | B6: Perataan lokasi kandang + teras 3 m dan peil | C6: =(40+6)*(10+6) | D6: m² | E6: =AHSP!$F$9 | F6: =C6*E6 | G6: (panjang + 6) x (lebar + 6)
A7: 2 | B7: Pengukuran dan bouwplank | C7: =2*(44+14) | D7: m' | E7: =AHSP!$F$20 | F7: =C7*E7 | G7: keliling bouwplank 2 m di luar as
B8: Jumlah pekerjaan persiapan | F8: =SUM(F6:F7)
B10: II. PEKERJAAN TANAH
A11: 1 | B11: Galian tanah pondasi footplat 100x100x70 | C11: =24*1*1*0.7 | D11: m³ | E11: =AHSP!$F$27 | F11: =C11*E11 | G11: 24 titik x 1 x 1 x 0,7
A12: 2 | B12: Galian dasar sloof | C12: =100*0.35*0.10 | D12: m³ | E12: =AHSP!$F$27 | F12: =C12*E12 | G12: keliling x 0,35 x 0,10
A13: 3 | B13: Urugan kembali galian footplat | C13: =24*(0.7-0.1985) | D13: m³ | E13: =AHSP!$F$34 | F13: =C13*E13 | G13: galian - (footplat + pedestal + lantai kerja + pasir)
A14: 4 | B14: Urugan tanah peninggian lantai dipadatkan t=18 | C14: =392.522*0.18 | D14: m³ | E14: =AHSP!$F$42 | F14: =C14*E14 | G14: luas dalam 39,85 x 9,85 x 0,18
A15: 5 | B15: Urugan pasir bawah lantai, footplat, sloof t=5 | C15: =392.522*0.05+24*1*1*0.05+100*0.25*0.05 | D15: m³ | E15: =AHSP!$F$50 | F15: =C15*E15 | G15: lantai + footplat + sloof
B16: Jumlah pekerjaan tanah | F16: =SUM(F11:F15)
B18: III. PEKERJAAN STRUKTUR BETON
A19: 1 | B19: Lantai kerja beton K-100 t=5 bawah footplat | C19: =24*0.9*0.9*0.05 | D19: m³ | E19: =AHSP!$F$93 | F19: =C19*E19 | G19: 24 x 0,9 x 0,9 x 0,05
A20: 2 | B20: Beton K-225 footplat P1 70x70x20 | C20: =24*0.7*0.7*0.2 | D20: m³ | E20: =AHSP!$F$117 | F20: =C20*E20 | G20: 24 x 0,7 x 0,7 x 0,2
A21: 3 | B21: Beton K-225 kolom K1 15/15 (pedestal + kolom, tinggi 3,20) | C21: =24*0.15*0.15*3.2 | D21: m³ | E21: =AHSP!$F$117 | F21: =C21*E21 | G21: 24 x 0,15 x 0,15 x 3,20
A22: 4 | B22: Beton K-225 sloof S1 15/25 | C22: =(100-24*0.15)*0.15*0.25 | D22: m³ | E22: =AHSP!$F$117 | F22: =C22*E22 | G22: (keliling - kolom) x 0,15 x 0,25
A23: 5 | B23: Beton K-225 ring balk RB 15/20 | C23: =(100-24*0.15)*0.15*0.2 | D23: m³ | E23: =AHSP!$F$117 | F23: =C23*E23 | G23: (keliling - kolom) x 0,15 x 0,20
A24: 6 | B24: Pembesian D10 dan Ø8 (footplat, kolom, sloof, ring balk) | C24: =24*4.44+24*13.8+(4*100*1.1*0.617+100/0.15*0.7*0.395)+(4*100*1.1*0.617+100/0.15*0.6*0.395) | D24: kg | E24: =AHSP!$F$128 | F24: =C24*E24 | G24: footplat 4,44 kg/bh; kolom 13,8 kg/bh; sloof & ring balk 4D10 + Ø8-150
A25: 7 | B25: Bekisting footplat, kolom, sloof, ring balk | C25: =24*4*0.7*0.2+24*4*0.15*3.2+2*(100-24*0.15)*0.25+(100-24*0.15)*(2*0.2+0.15) | D25: m² | E25: =AHSP!$F$140 | F25: =C25*E25 | G25: luas permukaan cetakan
B26: Jumlah pekerjaan struktur beton | F26: =SUM(F19:F25)
B28: IV. PEKERJAAN DINDING DAN LANTAI
A29: 1 | B29: Pasangan bata 1/2 bata tinggi 50 | C29: =90.80*0.5 | D29: m² | E29: =AHSP!$F$152 | F29: =C29*E29 | G29: (keliling - pintu - pintu umbaran - kolom) x 0,5
A30: 2 | B30: Plesteran dua sisi + atas dinding | C30: =2*90.80*0.5+90.80*0.11 | D30: m² | E30: =AHSP!$F$163 | F30: =C30*E30 | G30: 2 sisi + bidang atas
A31: 3 | B31: Acian | C31: =2*90.80*0.5+90.80*0.11 | D31: m² | E31: =AHSP!$F$173 | F31: =C31*E31 | G31: sama dengan plesteran
A32: 4 | B32: Pengecatan dinding, kolom, ring balk | C32: =2*90.80*0.5+24*0.6*2.0+(100-24*0.15)*0.55 | D32: m² | E32: =AHSP!$F$184 | F32: =C32*E32 | G32: dinding 2 sisi + kolom terlihat + ring balk
A33: 5 | B33: Lantai rabat beton K-175 t=7 | C33: =392.522*0.07 | D33: m³ | E33: =AHSP!$F$105 | F33: =C33*E33 | G33: luas dalam x 0,07
A34: 6 | B34: Finishing lantai dipel kasar | C34: =392.522 | D34: m² | E34: =AHSP!$F$192 | F34: =C34*E34 | G34: luas dalam
A35: 7 | B35: Lapis kerikil garis tetesan atap 50 x 15 cm kiri-kanan | C35: =2*42*0.5*0.15 | D35: m³ | E35: =AHSP!$F$81 | F35: =C35*E35 | G35: 2 x 42 m x 0,5 x 0,15 (pengganti saluran bata)
B36: Jumlah pekerjaan dinding dan lantai | F36: =SUM(F29:F35)
B38: V. PEKERJAAN KAWAT, RANGKA DAN TIRAI
A39: 1 | B39: Rangka hollow 40x40 (rel atas-bawah + tiang antara) | C39: =2*97.6+24*2.0 | D39: m' | E39: =AHSP!$F$280 | F39: =C39*E39 | G39: rel 2 x keliling bersih + 24 tiang antara x 2 m
A40: 2 | B40: Kawat harmonika 1" dinding, gevel, celah monitor | C40: =188.00+23.32+2*0.4*41 | D40: m² | E40: =AHSP!$F$270 | F40: =C40*E40 | G40: dinding 2 m + 2 segitiga gevel + 2 celah monitor 40 cm
A41: 3 | B41: Tirai terpal sisi panjang dan sisi pendek | C41: =2*(40+10)*2.0-2*1.2*2.0 | D41: m² | E41: =AHSP!$F$291 | F41: =C41*E41 | G41: keliling x 2 m - pintu
B42: Jumlah pekerjaan kawat, rangka dan tirai | F42: =SUM(F39:F41)
B44: VI. PEKERJAAN ATAP
A45: 1 | B45: Rangka atap baja ringan (bidang atap utama + monitor) | C45: =470.48+108.57 | D45: m² | E45: =AHSP!$F$218 | F45: =C45*E45 | G45: 2 x 5.74 x 41 + 2 x 1.32 x 41
A46: 2 | B46: Penutup atap galvalum spandek 0,30 | C46: =470.48+108.57 | D46: m² | E46: =AHSP!$F$229 | F46: =C46*E46 | G46: sama dengan bidang atap
...

Sheet RAB Fasilitas
A1: RAB bangunan fasilitas (gambar GT-03 dan GT-04)
A2: Struktur tipikal: footplat, kolom 15/15, sloof, ring balk, dinding bata, atap baja ringan + galvalum.
A4: No | B4: Uraian pekerjaan | C4: Volume | D4: Sat | E4: Harga satuan (Rp) | F4: Jumlah (Rp) | G4: Dasar volume
B5: POS JAGA (4 x 3 m)
B6: I. PERSIAPAN DAN TANAH
A7: 1 | B7: Perataan lokasi dan peil | C7: =(4.0+4)*(3.0+4) | D7: m² | E7: =AHSP!$F$9 | F7: =C7*E7 | G7: (panjang + 4) x (lebar + 4)
A8: 2 | B8: Pengukuran dan bouwplank | C8: =2*(4.0+4+3.0+4) | D8: m' | E8: =AHSP!$F$20 | F8: =C8*E8 | G8: keliling + 2 m
A9: 3 | B9: Galian footplat 100x100x70 | C9: =4*0.7 | D9: m³ | E9: =AHSP!$F$27 | F9: =C9*E9 | G9: 4 titik
A10: 4 | B10: Urugan kembali | C10: =4*0.5015 | D10: m³ | E10: =AHSP!$F$34 | F10: =C10*E10 | G10: sisa galian
A11: 5 | B11: Urugan tanah peninggian dipadatkan | C11: =10.973*0.15 | D11: m³ | E11: =AHSP!$F$42 | F11: =C11*E11 | G11: luas dalam x 0.15
A12: 6 | B12: Urugan pasir bawah lantai, footplat, sloof | C12: =10.973*0.05+4*0.05+14.0*0.25*0.05 | D12: m³ | E12: =AHSP!$F$50 | F12: =C12*E12
B13: II. STRUKTUR BETON
A14: 7 | B14: Lantai kerja K-100 | C14: =4*0.0405 | D14: m³ | E14: =AHSP!$F$93 | F14: =C14*E14
A15: 8 | B15: Beton K-225 footplat 70x70x20 | C15: =4*0.098 | D15: m³ | E15: =AHSP!$F$117 | F15: =C15*E15
A16: 9 | B16: Beton K-225 kolom 15/15 tinggi 3,70 | C16: =4*0.0225*3.7 | D16: m³ | E16: =AHSP!$F$117 | F16: =C16*E16 | G16: pedestal + kolom sampai +300
A17: 10 | B17: Beton K-225 sloof 15/25 | C17: =16.40*0.0375 | D17: m³ | E17: =AHSP!$F$117 | F17: =C17*E17
A18: 11 | B18: Beton K-225 ring balk 15/20 | C18: =16.40*0.03 | D18: m³ | E18: =AHSP!$F$117 | F18: =C18*E18
A19: 12 | B19: Pembesian | C19: =4*4.44+4*15.65+16.40*4.558+16.40*4.295 | D19: kg | E19: =AHSP!$F$128 | F19: =C19*E19 | G19: footplat + kolom + sloof + ring balk
A20: 13 | B20: Bekisting | C20: =4*0.56+4*0.6*3.7+16.40*0.5+16.40*0.55 | D20: m² | E20: =AHSP!$F$140 | F20: =C20*E20
B21: III. DINDING, LANTAI, ATAP
A22: 14 | B22: Pasangan bata 1/2 bata | C22: =41.69 | D22: m² | E22: =AHSP!$F$152 | F22: =C22*E22 | G22: dinding luar h 3 m + dinding dalam 3.0 m, dikurangi bukaan
A23: 15 | B23: Plesteran dua sisi | C23: =2*41.69 | D23: m² | E23: =AHSP!$F$163 | F23: =C23*E23
A24: 16 | B24: Acian sisi luar | C24: =1*41.69 | D24: m² | E24: =AHSP!$F$173 | F24: =C24*E24
A25: 17 | B25: Pengecatan sisi luar | C25: =1*41.69 | D25: m² | E25: =AHSP!$F$184 | F25: =C25*E25
A26: 18 | B26: Lantai beton K-175 t=10 (dasar keramik) | C26: =10.973*0.1 | D26: m³ | E26: =AHSP!$F$105 | F26: =C26*E26
A27: 19 | B27: Rangka atap baja ringan | C27: =25.38 | D27: m² | E27: =AHSP!$F$218 | F27: =C27*E27 | G27: kemiringan sisi utara + selatan (termasuk teras) x (panjang + 1)
A28: 20 | B28: Penutup atap galvalum | C28: =25.38 | D28: m² | E28: =AHSP!$F$229 | F28: =C28*E28
A29: 21 | B29: Nok | C29: =4.0+1 | D29: m' | E29: =AHSP!$F$238 | F29: =C29*E29
A30: 22 | B30: Lisplang/flashing | C30: =2*(4.0+1)+4*2.54 | D30: m' | E30: =AHSP!$F$247 | F30: =C30*E30
A31: 23 | B31: Penutup gevel kawat harmonika | C31: =2.10 | D31: m² | E31: =AHSP!$F$270 | F31: =C31*E31 | G31: 2 segitiga di atas ring balk
B32: IV. PINTU, JENDELA DAN UTILITAS
A33: 24 | B33: Keramik 40x40 | C33: =10.973 | D33: m² | E33: =AHSP!$F$205 | F33: =C33*E33
A34: 25 | B34: Plafon GRC rangka hollow | C34: =10.973 | D34: m² | E34: =AHSP!$F$259 | F34: =C34*E34
A35: 26 | B35: Pintu panel kayu 90x210 | C35: =2 | D35: unit | E35: =ROUND('Harga Dasar'!$D$62*(1+Petunjuk!$C$15),-2) | F35: =C35*E35 | G35: sesuai denah GT-04
A36: 27 | B36: Jendela + boven aluminium kaca | C36: =4.36 | D36: m² | E36: =ROUND('Harga Dasar'!$D$63*(1+Petunjuk!$C$15),-2) | F36: =C36*E36 | G36: luas bukaan GT-04
A37: 28 | B37: Kloset + perlengkapan KM | C37: =1 | D37: unit | E37: =ROUND('Harga Dasar'!$D$64*(1+Petunjuk!$C$15),-2) | F37: =C37*E37
A38: 29 | B38: Septic tank biofil 1 m³ | C38: =1 | D38: unit | E38: =ROUND('Harga Dasar'!$D$65*(1+Petunjuk!$C$15),-2) | F38: =C38*E38
A39: 30 | B39: Titik lampu | C39: =3 | D39: titik | E39: =ROUND('Harga Dasar'!$D$60*(1+Petunjuk!$C$15),-2) | F39: =C39*E39
A40: 31 | B40: Stop kontak | C40: =1 | D40: titik | E40: =ROUND('Harga Dasar'!$D$61*(1+Petunjuk!$C$15),-2) | F40: =C40*E40
B41: Jumlah pos jaga | F41: =SUM(F6:F40)
...

Sheet RAB Pagar Umbaran
A1: RAB pagar harmonika, gerbang, dan umbaran (gambar GT-02)
A2: Panjang pagar sesuai rencana tapak 100 x 400 m.
A4: No | B4: Uraian pekerjaan | C4: Volume | D4: Sat | E4: Harga satuan (Rp) | F4: Jumlah (Rp) | G4: Dasar volume (dari gambar)
B5: I. PAGAR KELILING LAHAN
A6: 1 | B6: Pagar kawat harmonika 2" tinggi 210 | C6: =100-12+2*340 | D6: m' | E6: =AHSP!$F$302 | F6: =C6*E6 | G6: depan 100 - gerbang 12 + sisi 2 x 340 m (sampai sabuk hijau sungai)
A7: 2 | B7: Tiang beton pracetak + dudukan cor | C7: =ROUND((100-12+2*340)/2.5,0)+31 | D7: bh | E7: =AHSP!$F$314 | F7: =C7*E7 | G7: jarak 250 + skur sudut/25 m
A8: 3 | B8: Gerbang utama 600 x 220 (2 daun, hollow 50x50) | C8: =6*2.2 | D8: m² | E8: =AHSP!$F$342 | F8: =C8*E8
A9: 4 | B9: Gerbang kebun 400 x 220 | C9: =4*2.2 | D9: m² | E9: =AHSP!$F$342 | F9: =C9*E9
A10: 5 | B10: Tiang gerbang beton 20/20 + footplat 60x60 (beton) | C10: =4*(0.2*0.2*3.0+0.6*0.6*0.2) | D10: m³ | E10: =AHSP!$F$117 | F10: =C10*E10 | G10: 4 tiang
A11: 6 | B11: Pembesian tiang gerbang | C11: =4*(4*3.4*0.888+22*0.7*0.395) | D11: kg | E11: =AHSP!$F$128 | F11: =C11*E11 | G11: 4 D12 + Ø8-150
A12: 7 | B12: Bak celup kendaraan 8 x 4 m: galian | C12: =8*4*0.35 | D12: m³ | E12: =AHSP!$F$27 | F12: =C12*E12
A13: 8 | B13: Bak celup kendaraan: sirtu dipadatkan t=15 | C13: =8*4*0.15 | D13: m³ | E13: =AHSP!$F$58 | F13: =C13*E13
A14: 9 | B14: Bak celup kendaraan: pelat beton K-225 t=15 | C14: =8*4*0.15 | D14: m³ | E14: =AHSP!$F$117 | F14: =C14*E14
A15: 10 | B15: Bak celup kendaraan: wiremesh M8 | C15: =ROUNDUP(8*4/(2.1*5.4)*1.1,0) | D15: lbr | E15: =ROUND('Harga Dasar'!$D$50*(1+Petunjuk!$C$15),-2) | F15: =C15*E15 | G15: lembar 2,1 x 5,4
A16: 11 | B16: Penanaman pagar hidup lamtoro/gamal | C16: =100-12+2*340 | D16: m' | E16: =AHSP!$F$434 | F16: =C16*E16 | G16: di dalam pagar keliling
B17: Jumlah pagar keliling lahan | F17: =SUM(F6:F16)
B19: II. PAGAR ZONA KANDANG
A20: 1 | B20: Pagar kawat harmonika 2" tinggi 210 | C20: =2*(94+157.5)-4-4 | D20: m' | E20: =AHSP!$F$302 | F20: =C20*E20 | G20: keliling zona - gerbang gerobak - gerbang kotor
A21: 2 | B21: Tiang beton pracetak + dudukan cor | C21: =ROUND((2*(94+157.5))/2.5,0)+20 | D21: bh | E21: =AHSP!$F$314 | F21: =C21*E21
A22: 3 | B22: Gerbang gerobak 300 x 200 (2 buah: depan dan belakang) | C22: =2*3*2 | D22: m² | E22: =AHSP!$F$328 | F22: =C22*E22
B23: Jumlah pagar zona kandang | F23: =SUM(F20:F22)
B25: III. UMBARAN (6 PETAK 45 x 38 m)
A26: 1 | B26: Pagar sekat umbaran kawat harmonika 2" tinggi 210 | C26: =6*88 | D26: m' | E26: =AHSP!$F$302 | F26: =C26*E26 | G26: 88 m per petak (sisi luar memakai pagar zona)
A27: 2 | B27: Tiang beton pracetak + dudukan cor | C27: =ROUND(6*88/2.5,0)+12 | D27: bh | E27: =AHSP!$F$314 | F27: =C27*E27
A28: 3 | B28: Pintu umbaran 100 x 180 | C28: =6*1*1.8 | D28: m² | E28: =AHSP!$F$328 | F28: =C28*E28 | G28: 1 per petak
A29: 4 | B29: Pohon peneduh + pelindung bambu | C29: =6*18 | D29: bh | E29: =AHSP!$F$420 | F29: =C29*E29 | G29: 18 pohon per petak
A30: 5 | B30: Rumput / legum penutup tanah | C30: =6*45*38 | D30: m² | E30: =AHSP!$F$427 | F30: =C30*E30
B31: Jumlah umbaran (6 petak 45 x 38 m) | F31: =SUM(F26:F30)
B33: TOTAL | F33: =F17+F23+F31

Sheet RAB Utilitas Lahan
A1: RAB utilitas, jalan, lantai jemur, air, listrik (gambar GT-00, GT-02, GT-03 F-03 dan F-04)
A2: Jembatan titian bersifat opsional.
A4: No | B4: Uraian pekerjaan | C4: Volume | D4: Sat | E4: Harga satuan (Rp) | F4: Jumlah (Rp) | G4: Dasar volume (dari gambar)
B5: I. PENYIAPAN LAHAN DAN JALAN
A6: 1 | B6: Pembersihan dan perataan lahan zona servis, kandang, kotor (alat) | C6: =100*50+96*160+36*35 | D6: m² | E6: =AHSP!$F$65 | F6: =C6*E6
A7: 2 | B7: Jalan servis, jalan gerobak, jalan masuk: sirtu t=12 (jalur kerja cukup rumput) | C7: =(4*330+4*157.5+8*50)*0.12 | D7: m³ | E7: =AHSP!$F$58 | F7: =C7*E7 | G7: luas jalan x 0,12
B8: Jumlah penyiapan lahan dan jalan | F8: =SUM(F6:F7)
B10: II. LANTAI JEMUR 40 x 18 m
A11: 1 | B11: Perataan dan sirtu dipadatkan t=10 | C11: =40.0*18.0*0.10 | D11: m³ | E11: =AHSP!$F$58 | F11: =C11*E11
A12: 2 | B12: Beton K-175 t=8 | C12: =40.0*18.0*0.08 | D12: m³ | E12: =AHSP!$F$105 | F12: =C12*E12
A13: 3 | B13: Finishing permukaan dipel kasar | C13: =40.0*18.0 | D13: m² | E13: =AHSP!$F$192 | F13: =C13*E13
A14: 4 | B14: Parit kerikil keliling 30 x 30 | C14: =2*(40.0+18.0)*0.3*0.3 | D14: m³ | E14: =AHSP!$F$81 | F14: =C14*E14
B15: Jumlah lantai jemur 40 x 18 m | F15: =SUM(F11:F14)
B17: III. AIR BERSIH: SUMUR BOR DAN MENARA TANDON
A18: 1 | B18: Pengeboran sumur Ø4" kedalaman ±60 m | C18: =60 | D18: m | E18: =ROUND('Harga Dasar'!$D$67*(1+Petunjuk!$C$15),-2) | F18: =C18*E18
A19: 2 | B19: Pompa submersible 1 HP + panel | C19: =1 | D19: unit | E19: =ROUND('Harga Dasar'!$D$68*(1+Petunjuk!$C$15),-2) | F19: =C19*E19
A20: 3 | B20: Beton K-225 menara tandon (kolom, balok, plat, footplat) | C20: =4*0.2*0.2*6.5+8*1.8*0.2*0.2+2.4*2.4*0.15+4*0.6*0.6*0.2 | D20: m³ | E20: =AHSP!$F$117 | F20: =C20*E20 | G20: kolom 20/20 h 650 + balok + plat t 15
A21: 4 | B21: Pembesian menara tandon (±120 kg/m³) | C21: =120*(4*0.2*0.2*6.5+8*1.8*0.2*0.2+2.4*2.4*0.15+4*0.6*0.6*0.2) | D21: kg | E21: =AHSP!$F$128 | F21: =C21*E21
A22: 5 | B22: Bekisting menara tandon | C22: =4*0.8*6.5+8*1.8*0.6+2.4*2.4+4*0.48 | D22: m² | E22: =AHSP!$F$140 | F22: =C22*E22
A23: 6 | B23: Galian footplat menara | C23: =4*1*1*1 | D23: m³ | E23: =AHSP!$F$27 | F23: =C23*E23
A24: 7 | B24: Tandon air 2.200 liter | C24: =2 | D24: bh | E24: =ROUND('Harga Dasar'!$D$66*(1+Petunjuk!$C$15),-2) | F24: =C24*E24
A25: 8 | B25: Pipa distribusi PVC ke kandang dan bangunan | C25: =250 | D25: m' | E25: =AHSP!$F$399 | F25: =C25*E25 | G25: pipa induk
B26: Jumlah air bersih: sumur bor dan menara tandon | F26: =SUM(F18:F25)
B28: IV. AIR SUNGAI DAN EMBUNG
A29: 1 | B29: Rumah pompa 3 x 3 m | C29: =3*3 | D29: m² | E29: =ROUND('Harga Dasar'!$D$74*(1+Petunjuk!$C$15),-2) | F29: =C29*E29 | G29: bangunan sederhana
A30: 2 | B30: Pompa air sungai 3" | C30: =1 | D30: unit | E30: =ROUND('Harga Dasar'!$D$69*(1+Petunjuk!$C$15),-2) | F30: =C30*E30
A31: 3 | B31: Pipa PVC 3" sungai - embung - kebun | C31: =ROUNDUP(150/4,0) | D31: btg | E31: =ROUND('Harga Dasar'!$D$51*(1+Petunjuk!$C$15),-2) | F31: =C31*E31 | G31: 150 m
A32: 4 | B32: Galian embung 30 x 20 x 2,5 m talud 1:1,5 (excavator) | C32: =1076.7 | D32: m³ | E32: =AHSP!$F$73 | F32: =C32*E32 | G32: rumus limas terpancung
A33: 5 | B33: Perapian talud dan tanggul + rumput | C33: =85*4.51+3*112 | D33: m² | E33: =AHSP!$F$441 | F33: =C33*E33 | G33: luas talud + tanggul 3 m
B34: Jumlah air sungai dan embung | F34: =SUM(F29:F33)
B36: V. LISTRIK KAWASAN
A37: 1 | B37: Pasang baru PLN 3.500 VA + SLO + panel | C37: =1 | D37: ls | E37: =ROUND('Harga Dasar'!$D$70*(1+Petunjuk!$C$15),-2) | F37: =C37*E37
A38: 2 | B38: Kabel NYY 4x6 tanam ke zona kandang dan servis | C38: =250 | D38: m | E38: =ROUND('Harga Dasar'!$D$71*(1+Petunjuk!$C$15),-2) | F38: =C38*E38
B39: Jumlah listrik kawasan | F39: =SUM(F37:F38)
B41: TOTAL | F41: =F8+F15+F26+F34+F39
