Workbook

Sheet Ringkasan
A1: RAB HEMAT Kandang Ayam KUB 2.000 Ekor, Kab. Konawe Selatan
A2: Rekapitulasi Rencana Anggaran Biaya. Semua angka berupa rumus yang mengikuti sheet Asumsi, Harga Dasar, dan Analisa HSP.
A4: No | B4: Uraian | C4: Jumlah (Rp) | D4: Persen | E4: Keterangan
A5: A | B5: Kandang litter 10 x 20 m (semua unit) | C5: ='RAB Kandang'!$F$34 | D5: =IF($C$12=0,0,C5/$C$12) | E5: Sheet RAB Kandang
A6: B | B6: Bangunan dan fasilitas pendukung | C6: ='RAB Pendukung'!$F$16 | D6: =IF($C$12=0,0,C6/$C$12) | E6: Sheet RAB Pendukung
A7: C | B7: Peralatan kandang | C7: ='Peralatan'!$F$24 | D7: =IF($C$12=0,0,C7/$C$12) | E7: Sheet Peralatan
B8: Jumlah biaya langsung (A + B + C) | C8: =SUM(C5:C7) | D8: =IF($C$12=0,0,C8/$C$12)
B9: Jasa pelaksana / overhead dan keuntungan | C9: =ROUND(C8*Asumsi!$B$43,0) | D9: =IF($C$12=0,0,C9/$C$12) | E9: Persentase di sheet Asumsi (isi 0% bila swakelola)
B10: Cadangan tak terduga | C10: =ROUND(C8*Asumsi!$B$44,0) | D10: =IF($C$12=0,0,C10/$C$12)
B11: PPN | C11: =ROUND((C8+C9+C10)*Asumsi!$B$45,0) | D11: =IF($C$12=0,0,C11/$C$12) | E11: Default 0%
B12: TOTAL RAB | C12: =SUM(C8:C11) | D12: =IF($C$12=0,0,C12/$C$12)
B13: Terbilang bulat (jutaan rupiah) | C13: =ROUND(C12/1000000,1)
B15: Indikator
B16: Jumlah ayam (ekor) | C16: =Asumsi!$B$6
B17: Biaya per ekor (Rp/ekor) | C17: =C12/Asumsi!$B$6
B18: Luas lantai kandang (m²) | C18: =Asumsi!$B$10*Asumsi!$B$11*Asumsi!$B$8
B19: Biaya kandang per m² lantai (Rp/m²) | C19: =C5/(Asumsi!$B$10*Asumsi!$B$11*Asumsi!$B$8)
B20: Biaya per ekor, hanya kandang dan peralatan (Rp/ekor) | C20: =(C5+C7)/Asumsi!$B$6
B21: Luas atap per kandang (m²) | C21: =Asumsi!$B$53
B22: Zona produksi berpagar (m²) dari lahan 10.000 m² | C22: =Asumsi!$B$55
B24: Catatan penting
B25: • VERSI HEMAT. Harga satuan bahan dan upah adalah ESTIMASI untuk Konawe Selatan/Kendari, bukan kutipan resmi. Ganti sel biru di sheet Harga Dasar dengan penawaran toko bangunan setempat.
B26: • Dasar yang terverifikasi: UMK Konawe Selatan 2026 Rp 3.306.496 per bulan dan Indeks Kemahalan Konstruksi Konawe Selatan 2025 sebesar 91,52 (Surabaya = 100).
B27: • Konstruksi hemat: tiang kayu 10/10 di atas umpak beton, lantai tanah dipadatkan dengan lapisan pasir dan litter sekam, dinding bawah papan kayu 0,5 m, kawat harmonika dan tirai terpal, atap rangka kayu dengan seng gelombang landai 15°. Umur bangunan sekitar 5-8 tahun dan perlu perawatan rutin (cat/pengawet kayu, ganti tiang yang lapuk).
B28: • Hasil: sekitar Rp 355 juta untuk 2.000 ekor (dua kandang). Untuk target Rp 200-250 juta, bangun TAHAP 1: ubah Jumlah ayam menjadi 1.000 dan Jumlah unit menjadi 1 di sheet Asumsi (hasilnya sekitar Rp 232 juta), lalu tambah kandang kedua setelah kas berjalan.
B29: • Penghematan tambahan yang bisa dipilih: tunda kandang karantina, pakai sumber air yang sudah ada tanpa sumur bor baru, buat sarang bertelur dan tempat pakan sendiri, dan pagar hanya sisi depan lebih dulu.
B30: • Gambar di sheet Gambar menunjukkan konstruksi permanen (pondasi batu kali, lantai beton, atap baja ringan). Tata letak dan dimensi sama, tetapi detail struktur versi hemat berbeda seperti uraian di atas. Gambar detail versi hemat dapat dibuat bila diperlukan.
B31: • Biaya ini hanya investasi bangunan, fasilitas, dan peralatan. Belum termasuk DOC, pakan, tenaga kerja, dan modal kerja. Konsultasikan struktur final (terutama rangka atap bentang 10 m) dengan tukang atau tenaga ahli setempat sebelum membangun.

Sheet Asumsi
A1: Asumsi dan Parameter Desain
A2: Sel biru = input yang boleh diubah. Semua volume dan biaya di sheet lain mengikuti sel ini.
A4: Parameter | B4: Nilai | C4: Satuan | D4: Catatan
A5: Kapasitas
A6: Jumlah ayam total | B6: 2000 | C6: ekor | D6: Permintaan pengguna.
A7: Kepadatan kandang litter | B7: 5 | C7: ekor/m² | D7: Ayam KUB petelur sistem litter 5 ekor/m². Untuk pedaging boleh 8-10 ekor/m² (lihat sheet Ringkasan, catatan).
A8: Jumlah unit kandang | B8: 2 | C8: unit | D8: Dua unit identik agar bisa dikosongkan bergantian dan sistem all-in all-out per kandang.
A9: Dimensi bangunan per unit
A10: Panjang kandang | B10: 20 | C10: m | D10: Poros timur-barat.
A11: Lebar kandang | B11: 10 | C11: m | D11: Maksimal 10 m agar ventilasi alami efektif.
A12: Jarak antar kolom | B12: 2.5 | C12: m | D12: 8 bentang x 2,5 m = 20 m.
A13: Tinggi kolom/dinding efektif | B13: 3 | C13: m
A14: Tinggi dinding bata bagian bawah | B14: 0.5 | C14: m | D14: Menahan litter dan mencegah tikus.
A15: Tinggi kawat harmonika di atas bata | B15: 2.5 | C15: m | D15: Dari 0,5 m sampai 3,0 m.
A16: Tinggi tirai terpal | B16: 1.6 | C16: m | D16: Dapat digulung.
A17: Sudut atap | B17: 15 | C17: derajat | D17: Atap lebih landai untuk menghemat luas bidang atap.
A18: Overstek atap tiap sisi | B18: 0.6 | C18: m | D18: Cukup melindungi tirai pada atap landai.
A19: Lebar pintu | B19: 1.2 | C19: m
A20: Jumlah pintu per kandang | B20: 2 | C20: buah | D20: Depan dan belakang.
A21: Struktur dan lantai
A22: Tebal lantai beton | B22: 0.07 | C22: m | D22: K-125.
A23: Tebal urugan pasir di bawah lantai | B23: 0.05 | C23: m
A24: Tinggi urugan tanah peninggian lantai | B24: 0.3 | C24: m | D24: Lantai kandang lebih tinggi dari tanah sekitar agar kering.
A25: Pondasi batu kali, lebar atas | B25: 0.25 | C25: m
A26: Pondasi batu kali, lebar bawah | B26: 0.6 | C26: m
A27: Pondasi batu kali, tinggi | B27: 0.6 | C27: m
A28: Galian pondasi, lebar | B28: 0.7 | C28: m
A29: Galian pondasi, dalam | B29: 0.7 | C29: m
A30: Sloof, lebar | B30: 0.15 | C30: m
A31: Sloof, tinggi | B31: 0.2 | C31: m
A32: Kolom, sisi (persegi) | B32: 0.15 | C32: m | D32: 15 x 15 cm.
A33: Ring balk, lebar | B33: 0.12 | C33: m
A34: Ring balk, tinggi | B34: 0.15 | C34: m
A35: Kebutuhan besi per m³ beton | B35: 170 | C35: kg/m³ | D35: Rata-rata sloof, kolom, ring balk.
A36: Jenis rangka atap (1 = baja ringan, 2 = kayu) | B36: 2 | C36: pilihan | D36: Versi hemat memakai rangka kayu.
A37: Lahan dan fasilitas pendukung
A38: Luas lahan | B38: 10000 | C38: m² | D38: 1 ha.
A39: Panjang zona produksi berpagar | B39: 70 | C39: m
A40: Lebar zona produksi berpagar | B40: 60 | C40: m
A41: Biaya tidak langsung
...

Sheet Harga Dasar
A1: Harga Dasar Upah dan Bahan, estimasi Kab. Konawe Selatan
A2: Kolom Harga Acuan (biru) adalah estimasi dan WAJIB dikonfirmasi ke toko bangunan Andoolo/Kendari atau HSPK Kab. Konawe Selatan terbaru sebelum dipakai untuk penawaran.
A4: Kode | B4: Uraian | C4: Satuan | D4: Harga acuan (Rp) | E4: Harga dipakai (Rp) | F4: Dasar / catatan
A5: UPAH (Rp per orang-hari)
A6: pekerja | B6: Pekerja | C6: OH | D6: 130000 | E6: =D6 | F6: UMK Konawe Selatan 2026 Rp 3.306.496 per bulan, dibagi sekitar 25 hari kerja = Rp 132.000.
A7: tukang | B7: Tukang | C7: OH | D7: 165000 | E7: =D7 | F7: Estimasi, sekitar 1,25 x pekerja.
A8: kepala | B8: Kepala tukang | C8: OH | D8: 180000 | E8: =D8 | F8: Estimasi.
A9: mandor | B9: Mandor | C9: OH | D9: 195000 | E9: =D9 | F9: Estimasi.
A10: BAHAN
A11: semen | B11: Semen Portland (40 kg = Rp 62.000) | C11: kg | D11: 1550 | E11: =D11*Asumsi!$B$42 | F11: Kisaran nasional Rp 42.000-72.000 per 40 kg (Mei-Juni 2025). Wilayah timur umumnya di atas rata-rata.
A12: pasir | B12: Pasir pasang | C12: m³ | D12: 250000 | E12: =D12*Asumsi!$B$42 | F12: Estimasi franco lokasi.
A13: pasir_urug | B13: Pasir urug | C13: m³ | D13: 200000 | E13: =D13*Asumsi!$B$42 | F13: Estimasi.
A14: batu | B14: Batu kali / batu belah | C14: m³ | D14: 300000 | E14: =D14*Asumsi!$B$42 | F14: Estimasi.
A15: kerikil | B15: Kerikil / split | C15: m³ | D15: 400000 | E15: =D15*Asumsi!$B$42 | F15: Estimasi.
A16: tanah | B16: Tanah urug (termasuk angkut) | C16: m³ | D16: 80000 | E16: =D16*Asumsi!$B$42 | F16: Estimasi. Bila tanah galian dipakai ulang, harga turun.
A17: bata | B17: Batu bata merah | C17: bh | D17: 1000 | E17: =D17*Asumsi!$B$42 | F17: Estimasi.
A18: besi | B18: Besi beton (ulir/polos) | C18: kg | D18: 14000 | E18: =D18*Asumsi!$B$42 | F18: Estimasi.
A19: bendrat | B19: Kawat bendrat | C19: kg | D19: 22000 | E19: =D19*Asumsi!$B$42 | F19: Estimasi.
A20: kayu | B20: Kayu kelas III (balok/papan bekisting) | C20: m³ | D20: 3500000 | E20: =D20*Asumsi!$B$42 | F20: Estimasi.
A21: paku | B21: Paku campur | C21: kg | D21: 24000 | E21: =D21*Asumsi!$B$42 | F21: Estimasi.
A22: kawat | B22: Kawat harmonika / kawat ayam galvanis | C22: m² | D22: 11000 | E22: =D22*Asumsi!$B$42 | F22: Estimasi.
... A25: sekrup | B25: Sekrup atap + ring | C25: bh | D25: 700 | E25: =D25*Asumsi!$B$42 | F25: Estimasi.
A26: PEKERJAAN BORONGAN (bahan + upah)
A27: baja | B27: Rangka atap baja ringan C75 + reng, terpasang | C27: m² | D27: 235000 | E27: =D27*Asumsi!$B$42 | F27: Estimasi borongan tukang baja ringan.
A28: kayu_rangka | B28: Rangka atap kayu + reng, terpasang | C28: m² | D28: 100000 | E28: =D28*Asumsi!$B$42 | F28: Estimasi borongan tukang kayu lokal.
A29: ridge | B29: Ventilasi nok (ridge vent) + bubungan, terpasang | C29: m | D29: 150000 | E29: =D29*Asumsi!$B$42 | F29: Estimasi, rangka kayu dan seng sederhana.
A30: talang | B30: Talang air PVC + penyangga, terpasang | C30: m | D30: 125000 | E30: =D30*Asumsi!$B$42 | F30: Estimasi.
A31: pintu | B31: Pintu rangka kayu + kawat 1,2 x 2,1 m | C31: unit | D31: 1000000 | E31: =D31*Asumsi!$B$42 | F31: Estimasi.
A32: cat | B32: Pengapuran / cat dinding bata (2 lapis), terpasang | C32: m² | D32: 20000 | E32: =D32*Asumsi!$B$42 | F32: Estimasi.
A33: siap | B33: Pembersihan lahan, pengukuran, bowplank | C33: m² | D33: 4000 | E33: =D33*Asumsi!$B$42 | F33: Estimasi.
B35: Rujukan resmi yang perlu dibuka sebelum finalisasi
B36: • Peraturan Bupati Konawe Selatan No. 85 Tahun 2024 (harga satuan / HSPK), tersedia di JDIH Konawe Selatan dan peraturan.bpk.go.id.
B37: • Indeks Kemahalan Konstruksi Konawe Selatan 2025: 91,52 (Surabaya = 100), sumber databoks.katadata.co.id.
B38: • UMK / UMP Sulawesi Tenggara 2026: Rp 3.306.496, berlaku untuk Konawe Selatan.
B39: • Harga bahan dalam tabel ini estimasi saya karena daftar harga resmi per material tidak dapat diakses saat penyusunan.

Sheet Analisa HSP
A1: Analisa Harga Satuan Pekerjaan (HSP)
A2: Koefisien mengacu pola SNI/AHSP yang disederhanakan untuk bangunan kandang. Koefisien (biru) boleh disesuaikan. Harga komponen ditarik dari sheet Harga Dasar.
A4: galian | B4: Galian tanah pondasi | C4: Satuan | D4: Koefisien | E4: Harga satuan | F4: Jumlah (Rp)
B5: Pekerja | C5: OH | D5: 0.75 | E5: ='Harga Dasar'!$E$6 | F5: =D5*E5
B6: Mandor | C6: OH | D6: 0.025 | E6: ='Harga Dasar'!$E$9 | F6: =D6*E6
B7: Harga satuan galian tanah pondasi per m³ | F7: =SUM(F5:F6)
A9: urug_tanah | B9: Urugan tanah dipadatkan | C9: Satuan | D9: Koefisien | E9: Harga satuan | F9: Jumlah (Rp)
B10: Tanah urug (termasuk angkut) | C10: m³ | D10: 1.2 | E10: ='Harga Dasar'!$E$16 | F10: =D10*E10
B11: Pekerja | C11: OH | D11: 0.3 | E11: ='Harga Dasar'!$E$6 | F11: =D11*E11
B12: Mandor | C12: OH | D12: 0.015 | E12: ='Harga Dasar'!$E$9 | F12: =D12*E12
B13: Harga satuan urugan tanah dipadatkan per m³ | F13: =SUM(F10:F12)
A15: urug_pasir | B15: Urugan pasir | C15: Satuan | D15: Koefisien | E15: Harga satuan | F15: Jumlah (Rp)
B16: Pasir urug | C16: m³ | D16: 1.2 | E16: ='Harga Dasar'!$E$13 | F16: =D16*E16
B17: Pekerja | C17: OH | D17: 0.3 | E17: ='Harga Dasar'!$E$6 | F17: =D17*E17
B18: Mandor | C18: OH | D18: 0.015 | E18: ='Harga Dasar'!$E$9 | F18: =D18*E18
B19: Harga satuan urugan pasir per m³ | F19: =SUM(F16:F18)
A21: batu_kali | B21: Pasangan batu kali 1:4 | C21: Satuan | D21: Koefisien | E21: Harga satuan | F21: Jumlah (Rp)
B22: Batu kali / batu belah | C22: m³ | D22: 1.2 | E22: ='Harga Dasar'!$E$14 | F22: =D22*E22
B23: Semen Portland (40 kg = Rp 62.000) | C23: kg | D23: 163 | E23: ='Harga Dasar'!$E$11 | F23: =D23*E23
B24: Pasir pasang | C24: m³ | D24: 0.52 | E24: ='Harga Dasar'!$E$12 | F24: =D24*E24
B25: Pekerja | C25: OH | D25: 1.5 | E25: ='Harga Dasar'!$E$6 | F25: =D25*E25
B26: Tukang | C26: OH | D26: 0.75 | E26: ='Harga Dasar'!$E$7 | F26: =D26*E26
B27: Kepala tukang | C27: OH | D27: 0.075 | E27: ='Harga Dasar'!$E$8 | F27: =D27*E27
B28: Mandor | C28: OH | D28: 0.075 | E28: ='Harga Dasar'!$E$9 | F28: =D28*E28
B29: Harga satuan pasangan batu kali 1:4 per m³ | F29: =SUM(F22:F28)
A31: beton175 | B31: Beton K-175 (sloof, kolom, ring balk) | C31: Satuan | D31: Koefisien | E31: Harga satuan | F31: Jumlah (Rp)
B32: Semen Portland (40 kg = Rp 62.000) | C32: kg | D32: 336 | E32: ='Harga Dasar'!$E$11 | F32: =D32*E32
B33: Pasir pasang | C33: m³ | D33: 0.54 | E33: ='Harga Dasar'!$E$12 | F33: =D33*E33
B34: Kerikil / split | C34: m³ | D34: 0.81 | E34: ='Harga Dasar'!$E$15 | F34: =D34*E34
B35: Pekerja | C35: OH | D35: 1.65 | E35: ='Harga Dasar'!$E$6 | F35: =D35*E35
B36: Tukang | C36: OH | D36: 0.275 | E36: ='Harga Dasar'!$E$7 | F36: =D36*E36
B37: Kepala tukang | C37: OH | D37: 0.028 | E37: ='Harga Dasar'!$E$8 | F37: =D37*E37
B38: Mandor | C38: OH | D38: 0.083 | E38: ='Harga Dasar'!$E$9 | F38: =D38*E38
B39: Harga satuan beton k-175 (sloof, kolom, ring balk) per m³ | F39: =SUM(F32:F38)
A41: beton125 | B41: Beton K-125 (lantai) | C41: Satuan | D41: Koefisien | E41: Harga satuan | F41: Jumlah (Rp)
B42: Semen Portland (40 kg = Rp 62.000) | C42: kg | D42: 276 | E42: ='Harga Dasar'!$E$11 | F42: =D42*E42
B43: Pasir pasang | C43: m³ | D43: 0.54 | E43: ='Harga Dasar'!$E$12 | F43: =D43*E43
B44: Kerikil / split | C44: m³ | D44: 0.81 | E44: ='Harga Dasar'!$E$15 | F44: =D44*E44
B45: Pekerja | C45: OH | D45: 1.65 | E45: ='Harga Dasar'!$E$6 | F45: =D45*E45
B46: Tukang | C46: OH | D46: 0.275 | E46: ='Harga Dasar'!$E$7 | F46: =D46*E46
...

Sheet RAB Kandang
A1: RAB Kandang Ayam KUB, per 1 unit (10 m x 20 m, 1.000 ekor)
A2: Volume dihitung dengan rumus dari sheet Asumsi. Harga satuan dari Analisa HSP dan Harga Dasar.
A4: No | B4: Uraian pekerjaan | C4: Volume | D4: Sat | E4: Harga satuan (Rp) | F4: Jumlah (Rp) | G4: Dasar perhitungan volume
A5: I | B5: PEKERJAAN PERSIAPAN
A6: 1 | B6: Pembersihan lahan, pengukuran, bowplank | C6: =(Asumsi!$B$10+4)*(Asumsi!$B$11+4) | D6: m² | E6: ='Harga Dasar'!$E$33 | F6: =ROUND(C6*E6,0) | G6: (panjang + 4 m) x (lebar + 4 m)
A7: II | B7: PEKERJAAN TANAH DAN PONDASI SETEMPAT
A8: 2 | B8: Galian lubang umpak 50 x 50 x 50 cm | C8: =Asumsi!$B$52*0.5*0.5*0.5 | D8: m³ | E8: ='Analisa HSP'!$F$7 | F8: =ROUND(C8*E8,0) | G8: jumlah tiang x 0,5 x 0,5 x 0,5
A9: 3 | B9: Umpak beton K-175 30 x 30 x 40 cm | C9: =Asumsi!$B$52*0.3*0.3*0.4 | D9: m³ | E9: ='Analisa HSP'!$F$39 | F9: =ROUND(C9*E9,0) | G9: jumlah tiang x volume umpak
A10: 4 | B10: Urugan tanah peninggian lantai, dipadatkan | C10: =Asumsi!$B$10*Asumsi!$B$11*Asumsi!$B$24 | D10: m³ | E10: ='Analisa HSP'!$F$13 | F10: =ROUND(C10*E10,0) | G10: panjang x lebar x tinggi urugan
A11: 5 | B11: Lapisan pasir lantai t = 5 cm | C11: =Asumsi!$B$10*Asumsi!$B$11*Asumsi!$B$23 | D11: m³ | E11: ='Analisa HSP'!$F$19 | F11: =ROUND(C11*E11,0) | G11: panjang x lebar x tebal pasir
A12: 6 | B12: Pemadatan dan perataan lantai tanah | C12: =Asumsi!$B$10*Asumsi!$B$11 | D12: m² | E12: ='Analisa HSP'!$F$101 | F12: =ROUND(C12*E12,0) | G12: luas lantai
A13: III | B13: PEKERJAAN STRUKTUR KAYU
A14: 7 | B14: Tiang kayu 10/10 (termasuk bagian yang tertanam di umpak) | C14: =Asumsi!$B$52*0.1*0.1*(Asumsi!$B$13+0.3) | D14: m³ | E14: ='Analisa HSP'!$F$127 | F14: =ROUND(C14*E14,0) | G14: jumlah tiang x 0,1 x 0,1 x (tinggi + 0,3)
A15: 8 | B15: Balok pengikat / ring balk kayu 6/12 | C15: =(2*Asumsi!$B$10+2*Asumsi!$B$11)*0.06*0.12 | D15: m³ | E15: ='Analisa HSP'!$F$127 | F15: =ROUND(C15*E15,0) | G15: keliling x 0,06 x 0,12
A16: IV | B16: PEKERJAAN DINDING DAN BUKAAN
A17: 9 | B17: Dinding papan kayu, tinggi 0,5 m | C17: =(Asumsi!$B$51-Asumsi!$B$19*Asumsi!$B$20)*Asumsi!$B$14 | D17: m² | E17: ='Analisa HSP'!$F$136 | F17: =ROUND(C17*E17,0) | G17: (perimeter - lebar pintu) x tinggi
A18: 10 | B18: Kawat harmonika galvanis + rangka, tinggi 2,5 m | C18: =(Asumsi!$B$51-Asumsi!$B$19*Asumsi!$B$20)*Asumsi!$B$15 | D18: m² | E18: ='Analisa HSP'!$F$111 | F18: =ROUND(C18*E18,0) | G18: (perimeter - lebar pintu) x tinggi kawat
A19: 11 | B19: Tirai terpal, tinggi 1,6 m | C19: =(Asumsi!$B$51-Asumsi!$B$19*Asumsi!$B$20)*Asumsi!$B$16 | D19: m² | E19: ='Analisa HSP'!$F$118 | F19: =ROUND(C19*E19,0) | G19: (perimeter - lebar pintu) x tinggi tirai
A20: 12 | B20: Pintu rangka kayu + kawat 1,2 x 2,1 m | C20: =Asumsi!$B$20 | D20: unit | E20: ='Harga Dasar'!$E$31 | F20: =ROUND(C20*E20,0) | G20: jumlah pintu
A21: V | B21: PEKERJAAN ATAP
A22: 13 | B22: Rangka atap kayu | C22: =Asumsi!$B$53 | D22: m² | E22: ='Harga Dasar'!$E$28 | F22: =ROUND(C22*E22,0) | G22: luas bidang atap miring
A23: 14 | B23: Penutup atap seng gelombang | C23: =Asumsi!$B$53 | D23: m² | E23: ='Analisa HSP'!$F$145 | F23: =ROUND(C23*E23,0) | G23: luas bidang atap miring
A24: 15 | B24: Ventilasi nok (ridge vent) + bubungan | C24: =Asumsi!$B$10+2*Asumsi!$B$18 | D24: m | E24: ='Harga Dasar'!$E$29 | F24: =ROUND(C24*E24,0) | G24: panjang atap termasuk overstek
B26: REKAPITULASI PER BAGIAN (1 unit kandang)
A27: I | B27: PEKERJAAN PERSIAPAN | F27: =SUM(F6:F6)
A28: II | B28: PEKERJAAN TANAH DAN PONDASI SETEMPAT | F28: =SUM(F8:F12)
A29: III | B29: PEKERJAAN STRUKTUR KAYU | F29: =SUM(F14:F15)
A30: IV | B30: PEKERJAAN DINDING DAN BUKAAN | F30: =SUM(F17:F20)
A31: V | B31: PEKERJAAN ATAP | F31: =SUM(F22:F24)
B32: TOTAL PER 1 UNIT KANDANG | F32: =SUM(F27:F31)
B33: Jumlah unit kandang | F33: =Asumsi!$B$8
B34: TOTAL KANDANG (SEMUA UNIT) | F34: =F32*F33

Sheet RAB Pendukung
A1: RAB Bangunan dan Fasilitas Pendukung
A2: Harga satuan borongan (biru) adalah estimasi; ubah sesuai penawaran tukang lokal.
A4: No | B4: Uraian | C4: Volume | D4: Sat | E4: Harga satuan (Rp) | F4: Jumlah (Rp) | G4: Catatan
A5: 1 | B5: Pembersihan lahan zona produksi | C5: =Asumsi!$B$55 | D5: m² | E5: 1500 | F5: =ROUND(C5*E5,0) | G5: Pembukaan semak dan perataan.
A6: 2 | B6: Gudang pakan + ruang telur semi-permanen 6 x 5 m | C6: 30 | D6: m² | E6: 1000000 | F6: =ROUND(C6*E6,0) | G6: Dinding papan/batako setengah, atap seng, lantai semen tipis. Telur dan pakan disekat.
A7: 3 | B7: Pos jaga + ruang ganti 3 x 4 m | C7: 12 | D7: m² | E7: 1200000 | F7: =ROUND(C7*E7,0) | G7: Sederhana, sebagai pintu biosekuriti orang.
A8: 4 | B8: Kandang karantina / isolasi 4 x 6 m | C8: 24 | D8: m² | E8: 400000 | F8: =ROUND(C8*E8,0) | G8: Opsional, bisa ditunda sampai ada ayam baru yang masuk.
A9: 5 | B9: Pagar keliling zona produksi, tinggi 1,8 m | C9: =Asumsi!$B$54 | D9: m | E9: 55000 | F9: =ROUND(C9*E9,0) | G9: Kawat harmonika + tiang kayu/bambu tiap 3 m.
A10: 6 | B10: Sumur bor + pompa + tangki air 1 m³ | C10: 1 | D10: ls | E10: 12000000 | F10: =ROUND(C10*E10,0) | G10: Tergantung kedalaman air tanah. Hemat bila memakai sumber air yang sudah ada.
A11: 7 | B11: Instalasi listrik tiap kandang (lampu, kabel, panel) | C11: =Asumsi!$B$8 | D11: unit | E11: 2500000 | F11: =ROUND(C11*E11,0) | G11: Belum termasuk penambahan daya PLN.
A12: 8 | B12: Bak celup kaki / roda kendaraan | C12: 2 | D12: unit | E12: 500000 | F12: =ROUND(C12*E12,0) | G12: Gerbang dan pintu zona kandang.
A13: 9 | B13: Pengerasan jalan sirtu t = 10 cm, lebar 3 m | C13: 20 | D13: m³ | E13: 150000 | F13: =ROUND(C13*E13,0) | G13: Hanya jalan masuk utama.
A14: 10 | B14: Bak kompos / penampung kotoran | C14: 1 | D14: ls | E14: 1500000 | F14: =ROUND(C14*E14,0) | G14: Sederhana, atap seng dan lantai tanah padat.
A15: 11 | B15: Mobilisasi, papan nama, K3 | C15: 1 | D15: ls | E15: 2000000 | F15: =ROUND(C15*E15,0)
B16: TOTAL PENDUKUNG | F16: =SUM(F5:F15)

Sheet Peralatan
A1: Peralatan Kandang untuk 2.000 Ekor
A2: Jumlah dihitung dari jumlah ayam di sheet Asumsi (rumus). Harga satuan estimasi (biru).
A4: No | B4: Uraian | C4: Jumlah | D4: Sat | E4: Harga satuan (Rp) | F4: Jumlah (Rp) | G4: Dasar jumlah
A5: 1 | B5: Tempat pakan tubular (feeder) | C5: =ROUNDUP(Asumsi!$B$6/25,0) | D5: buah | E5: 60000 | F5: =ROUND(C5*E5,0) | G5: 1 per 25 ekor. Tempat pakan lokal dari pipa/ember.
A6: 2 | B6: Tempat minum otomatis (bell drinker) | C6: =ROUNDUP(Asumsi!$B$6/60,0) | D6: buah | E6: 55000 | F6: =ROUND(C6*E6,0) | G6: 1 per 60 ekor.
A7: 3 | B7: Sarang bertelur (kotak 6 lubang) | C7: =ROUNDUP(Asumsi!$B$6/5/6,0) | D7: unit | E7: 250000 | F7: =ROUND(C7*E7,0) | G7: 1 lubang per 5 ekor. Dibuat sendiri dari kayu/multipleks.
A8: 4 | B8: Tempat bertengger bambu | C8: =ROUNDUP(Asumsi!$B$6/5,0) | D8: m | E8: 6000 | F8: =ROUND(C8*E8,0) | G8: 1 m per 5 ekor.
A9: 5 | B9: Brooder gas (kapasitas 200 DOC) | C9: =ROUNDUP(Asumsi!$B$6/200,0) | D9: unit | E9: 600000 | F9: =ROUND(C9*E9,0) | G9: Dipakai di area brooding.
A10: 6 | B10: Tabung gas 3 kg + regulator | C10: =ROUNDUP(Asumsi!$B$6/200,0) | D10: unit | E10: 200000 | F10: =ROUND(C10*E10,0)
A11: 7 | B11: Pembatas brooding (kawat + terpal) | C11: 60 | D11: m | E11: 35000 | F11: =ROUND(C11*E11,0) | G11: Disesuaikan dengan sekat area brooding.
A12: 8 | B12: Lampu LED 15 W | C12: =ROUNDUP(Asumsi!$B$6/35,0) | D12: buah | E12: 35000 | F12: =ROUND(C12*E12,0)
A13: 9 | B13: Timer lampu | C13: 2 | D13: buah | E13: 150000 | F13: =ROUND(C13*E13,0) | G13: Pencahayaan 16 jam untuk petelur.
A14: 10 | B14: Termometer dan higrometer | C14: 4 | D14: buah | E14: 75000 | F14: =ROUND(C14*E14,0)
A15: 11 | B15: Timbangan gantung 50 kg | C15: 1 | D15: buah | E15: 350000 | F15: =ROUND(C15*E15,0)
A16: 12 | B16: Timbangan digital 5 kg | C16: 1 | D16: buah | E16: 250000 | F16: =ROUND(C16*E16,0)
A17: 13 | B17: Egg tray 30 butir | C17: 300 | D17: buah | E17: 2500 | F17: =ROUND(C17*E17,0)
A18: 14 | B18: Kereta dorong | C18: 2 | D18: buah | E18: 500000 | F18: =ROUND(C18*E18,0)
A19: 15 | B19: Sprayer 16 L | C19: 2 | D19: buah | E19: 450000 | F19: =ROUND(C19*E19,0)
A20: 16 | B20: Tong penyimpan pakan 100 L | C20: 4 | D20: buah | E20: 250000 | F20: =ROUND(C20*E20,0)
A21: 17 | B21: Sekam padi untuk litter, tebal 8 cm | C21: =Asumsi!$B$10*Asumsi!$B$11*Asumsi!$B$8*0.08 | D21: m³ | E21: 100000 | F21: =ROUND(C21*E21,0) | G21: Luas lantai total x 0,08.
A22: 18 | B22: Alat kebersihan dan APD | C22: 1 | D22: ls | E22: 1500000 | F22: =ROUND(C22*E22,0) | G22: Sepatu bot, masker, sarung tangan, sapu, sikat.
A23: 19 | B23: Perlengkapan kesehatan awal (vaksin, vitamin, desinfektan) | C23: 1 | D23: ls | E23: 2000000 | F23: =ROUND(C23*E23,0) | G23: Stok awal, belum termasuk vaksin batch berikutnya.
B24: TOTAL PERALATAN | F24: =SUM(F5:F23)

Sheet Gambar
A1: Gambar Desain
A2: G-01 Rencana tapak · G-02 Denah · G-03 Potongan A-A · G-04 Tampak · G-05 Detail pondasi
